Workbook
Name AnnualCostOfTime_BuyCar: #REF!
Name AnnualCostOfTime_Ridesharing: #REF!
Name AnnualFareCost: #REF!
Name AnnualFuelCost: #REF!
Name AnnualPurchaseCost: #REF!
Name AnnualUsageCost: #REF!
Name AveDistancePerTrip: Summary!$D$24
Name AveParkingTime: #REF!
Name AverageTripsPerDay: Summary!$D$19
Name AveSurgeMultiplier: #REF!
Name AveTimePerTrip: Summary!$D$20
Name AveWaitTime: #REF!
Name BaseFare: #REF!
Name DistanceFare: #REF!
Name DownPayment: #REF!
Name FuelCost: #REF!
Name FuelEfficiency: #REF!
Name GarageExpenses: #REF!
Name GaragePropertyTax: #REF!
Name Insurance: #REF!
Name InterestRate: #REF!
Name LoanTerm: #REF!
Name MaintenanceAndRepairs: #REF!
Name Parking: #REF!
Name PercentRideDuringSurge: #REF!
Name PriceOfCar: #REF!
Name ProductivePercent: #REF!
Name PurchaseFees: #REF!
Name RatePerHour: Summary!$D$64
Name RegistrationAndTaxes: #REF!
Name SalesTax: #REF!
Name TimeFare: #REF!
Name TotalMileage: Summary!#REF!

Sheet Summary
B2: CSR QA Report-new_version
C4: Report ID | D4: CSR_08/04/2026 | G4: Generated doc
C5: AW version | D5: Sandbox | G5: Clean Ver
C6: Generated By | D6: Paras | G6: Date | J6: 46120
G7: No. of Pages
C8: Remarks | G8: Generation Time
C11: Destination Template | E11: .docx - 2 pages
C12: Source Documents | D12: Mock_CSR Key messages_with_heading.docx | E12: Mock_CSR_Protocol.docx | G12: Mock_CSR _Tables_30Oct25.rtf
C13: Doc Type | D13: .docx | E13: .docx | G13: .rtf
C14: No. of Pages
B16: Placeholder Analysis | G16: Accuracy Analysis
B17: Column1 | C17: Column2 | D17: Column3 | E17: Column4
D18: Count | E18: Replaced
C19: Total Placeholders Identified | D19: =COUNTA(QA!A3:'QA'!A149) -> 108 | E19: =COUNTA(QA!G3:'QA'!G148) -> 89
C20: Unique Placeholders | D20: =COUNTA(_xlfn.UNIQUE(QA!A3:'QA'!A149)) -> 101 | E20: =COUNTA(_xlfn.UNIQUE(QA!G3:'QA'!G149)) -> 81
C21: Paragraph Placeholders | D21: =COUNTIF(QA!C3:'QA'!C149, "=Paragraph") -> 55 | E21: =COUNTA(Paragraph!M3:M57) -> 47
C22: Inline Placeholders | D22: =COUNTIF(QA!C3:'QA'!C149, "=Inline") -> 15 | E22: =COUNTA(Inline!G3:G17) -> 15
C23: List Placeholders | D23: =COUNTIF(QA!C3:'QA'!C149, "=List") -> 2 | E23: =COUNTA(Lists!G3:G4) -> 2
C24: Table Placeholders | D24: =COUNTIF(QA!C3:'QA'!C149, "=Table") -> 16 | E24: =COUNTA(Table!G3:G18) -> 16
C25: KeyValue Placeholders | D25: =COUNTA(KeyValue!A3:A21) -> 19 | E25: =COUNTA(KeyValue!M3:M21) -> 11
B27: Inline placeholders
B28: Column1 | C28: Column2 | D28: Column3 | E28: Column4
C29: Total Inline placeholders | D29: =COUNTA(Inline!A3:'Inline'!A500) -> 15 | E29: QA/Debugging ↓ | G29: Remarks
C30: Inline Replaced | D30: =COUNTA(Inline!G3:'Inline'!G500) -> 15 | E30: =D30/D29 -> 1
C31: Inline Replaced correctly | D31: =COUNTIF(QA!AK3:AK82, "Full match") -> 0 | E31: =D31*100%/D30 -> 0
C32: Inline Formatted correctly | D32: =D31 -> 0 | E32: =D32*100%/D31 -> #DIV/0!
B34: Paragraph placeholders
B35: Column1 | C35: Column2 | D35: Column3 | E35: Column4
C36: Total paragraph placeholders | D36: =COUNTA(Paragraph!A3:'Paragraph'!A500) -> 55 | E36: QA/Debugging ↓ | G36: Remarks
C37: Paragraphs Replaced | D37: =COUNTA(Paragraph!G3:'Paragraph'!G500) -> 55 | E37: =Table685[[#This Row],[Column3]]/D36 -> 1
C38: Paragraphs Replaced correctly | D38: =COUNTIF(QA!AI17:AI110, "Full Match") + COUNTIF(QA!AI17:AI110, "Partial Match") -> 0 | E38: =Table685[[#This Row],[Column3]]/D37 -> 0
C39: Paragraphs Formatted correctly | D39: =D38 -> 0 | E39: =Table685[[#This Row],[Column3]]/D38 -> #DIV/0!
B41: KeyValue placeholders
B42: Column1 | C42: Column2 | D42: Column3 | E42: Column4
C43: Total paragraph placeholders | D43: =COUNTA(KeyValue!A3:'KeyValue'!A500) -> 19 | E43: QA/Debugging ↓ | G43: Remarks
C44: KeyValues Replaced | D44: =COUNTA(KeyValue!G3:'KeyValue'!G500) -> 19 | E44: =Table687[[#This Row],[Column3]]/D43 -> 1
C45: KeyValues Replaced correctly | D45: =COUNTIF(QA!K5:K50, "Full match") -> 0 | E45: =Table687[[#This Row],[Column3]]/D44 -> 0
C46: keyValues Formatted correctly | D46: =D45 -> 0 | E46: =Table687[[#This Row],[Column3]]/D45 -> #DIV/0!
B48: Table placeholders
B49: Column1 | C49: Column2 | D49: Column3 | E49: Column4
...

Sheet QA
J1: KeyVaule | Q1: Table | Z1: List | AE1: Paragraph | AK1: Inline
A2: Placeholder | B2: Column1 | C2: Placeholder Type | D2: Expected Value | E2: Source Document | F2: Writing instruction | G2: AI Replaced Text | H2: Ai detected Source | I2: Matching Accuracy | J2: Similarity Score | K2: Source Match | Q2: Expected Rows | R2: Expected Colunms | S2: Expected Footnote | T2: AI replaced Rows | U2: AI replaced Colunms | V2: AI replaced Footnotes | W2: Alignment(yes/no) | X2: Status | Z2: Number of point | AA2: AI Number of point | AB2: Point matching(yes/no) | AC2: Status(with formula) | AE2: Header Availablity | AF2: AI Header Availablity | AG2: Status(True/false) | AH2: Similarity Score | AI2: Status | AK2: Status
A3: <Sponsor's Name> | C3: Inline | D3: Stendarr, Inc | E3: Mock_CSR_Protocol.docx | G3: Sponsor | I3: {=_xldudf_BOARDFLARE_FMATCH(G3,D3)} -> #NAME? | J3: =IF(M3>O3, M3,O3) -> #VALUE! | M3: {=_FV(L3,"Similarity",TRUE)} -> #VALUE! | N3: {=_xldudf_BOARDFLARE_FMATCH(D3,G3)} -> #NAME? | O3: {=_FV(N3,"Similarity",TRUE)} -> #VALUE! | AK3: {=IF( SUMPRODUCT(--ISNUMBER(SEARCH(_xlfn.TEXTSPLIT(D3," "), G3))) / COUNTA(_xlfn.TEXTSPLIT(D3," ")) = 1, "Full Match", IF( SUMPRODUCT(--ISNUMBER(SEARCH(_xlfn.TEXTSPLIT(D3," "), G3))) / COUNTA(_xlfn.TEXTSPLIT(D3," ")) > 0.5, "Partial Match", "No Match" ) )} -> No Match
A4: <Study Title> | C4: Inline | D4: A First-In-Human, Phase 1, Randomized, Double-Blind, Placebo-Controlled Study to Evaluate the Safety, Tolerability, and Pharmacokinetics of ABC-123 as a Single Dose in Healthy Participants and as Multiple Doses in Participants with Grade 2 Boneitis | E4: Mock_CSR_Protocol.docx | F4: Insert the full official study title as a formatted paragraph. | I4: {=_xldudf_BOARDFLARE_FMATCH(G4,D4)} -> #NAME? | J4: =IF(M4>O4, M4,O4) -> #VALUE! | L4: {=_xldudf_BOARDFLARE_FMATCH(G4,D4)} -> #NAME? | M4: {=_FV(L4,"Similarity",TRUE)} -> #VALUE! | N4: {=_xldudf_BOARDFLARE_FMATCH(D4,G4)} -> #NAME? | O4: {=_FV(N4,"Similarity",TRUE)} -> #VALUE! | AK4: {=IF( SUMPRODUCT(--ISNUMBER(SEARCH(_xlfn.TEXTSPLIT(D4," "), G4))) / COUNTA(_xlfn.TEXTSPLIT(D4," ")) = 1, "Full Match", IF( SUMPRODUCT(--ISNUMBER(SEARCH(_xlfn.TEXTSPLIT(D4," "), G4))) / COUNTA(_xlfn.TEXTSPLIT(D4," ")) > 0.5, "Partial Match", "No Match" ) )} -> No Match
A5: <Investigational Drug Name> | C5: KeyValue | D5: ABC-123 | E5: Mock_CSR_Protocol.docx | F5: Provide the investigational drug name in concise format. | G5: ABC-123 | I5: {=_xldudf_BOARDFLARE_FMATCH(G5,D5)} -> #NAME? | J5: =IF(M5>O5, M5,O5) -> #VALUE! | K5: {=IF( SUMPRODUCT(--ISNUMBER(SEARCH(_xlfn.TEXTSPLIT(D5," "), G5))) / COUNTA(_xlfn.TEXTSPLIT(D5," ")) = 1, "Full Match", IF( SUMPRODUCT(--ISNUMBER(SEARCH(_xlfn.TEXTSPLIT(D5," "), G5))) / COUNTA(_xlfn.TEXTSPLIT(D5," ")) > 0.5, "Partial Match", "No Match" ) )} -> No Match | L5: {=_xldudf_BOARDFLARE_FMATCH(G5,D5)} -> #NAME? | M5: {=_FV(L5,"Similarity",TRUE)} -> #VALUE! | N5: {=_xldudf_BOARDFLARE_FMATCH(D5,G5)} -> #NAME? | O5: {=_FV(N5,"Similarity",TRUE)} -> #VALUE!
A6: <Insert Disease Name> | C6: KeyValue | D6: Boneitis | E6: Mock_CSR_Protocol.docx | F6: Insert the disease name as referenced in the protocol. | G6: Boneitis | I6: {=_xldudf_BOARDFLARE_FMATCH(G6,D6)} -> #NAME? | J6: =IF(M6>O6, M6,O6) -> #VALUE! | K6: {=IF( SUMPRODUCT(--ISNUMBER(SEARCH(_xlfn.TEXTSPLIT(D6," "), G6))) / COUNTA(_xlfn.TEXTSPLIT(D6," ")) = 1, "Full Match", IF( SUMPRODUCT(--ISNUMBER(SEARCH(_xlfn.TEXTSPLIT(D6," "), G6))) / COUNTA(_xlfn.TEXTSPLIT(D6," ")) > 0.5, "Partial Match", "No Match" ) )} -> No Match | L6: {=_xldudf_BOARDFLARE_FMATCH(G6,D6)} -> #NAME? | M6: {=_FV(L6,"Similarity",TRUE)} -> #VALUE! | N6: {=_xldudf_BOARDFLARE_FMATCH(D6,G6)} -> #NAME? | O6: {=_FV(N6,"Similarity",TRUE)} -> #VALUE!
A7: <Protocol Identification (Code or Number)> | C7: KeyValue | D7: SKY-2000-101 | E7: Mock_CSR_Protocol.docx | F7: Provide the protocol identification code or number in the precise format as found in the context. | G7: SKY-2000-101 | I7: {=_xldudf_BOARDFLARE_FMATCH(G7,D7)} -> #NAME? | J7: =IF(M7>O7, M7,O7) -> #VALUE! | K7: {=IF( SUMPRODUCT(--ISNUMBER(SEARCH(_xlfn.TEXTSPLIT(D7," "), G7))) / COUNTA(_xlfn.TEXTSPLIT(D7," ")) = 1, "Full Match", IF( SUMPRODUCT(--ISNUMBER(SEARCH(_xlfn.TEXTSPLIT(D7," "), G7))) / COUNTA(_xlfn.TEXTSPLIT(D7," ")) > 0.5, "Partial Match", "No Match" ) )} -> No Match | L7: {=_xldudf_BOARDFLARE_FMATCH(G7,D7)} -> #NAME? | M7: {=_FV(L7,"Similarity",TRUE)} -> #VALUE! | N7: {=_xldudf_BOARDFLARE_FMATCH(D7,G7)} -> #NAME? | O7: {=_FV(N7,"Similarity",TRUE)} -> #VALUE!
A8: <Investigational Drug Name> | C8: KeyValue | D8: ABC-123 | E8: Mock_CSR_Protocol.docx | G8: ABC-123 | I8: {=_xldudf_BOARDFLARE_FMATCH(G8,D8)} -> #NAME? | J8: =IF(M8>O8, M8,O8) -> #VALUE! | K8: {=IF( SUMPRODUCT(--ISNUMBER(SEARCH(_xlfn.TEXTSPLIT(D8," "), G8))) / COUNTA(_xlfn.TEXTSPLIT(D8," ")) = 1, "Full Match", IF( SUMPRODUCT(--ISNUMBER(SEARCH(_xlfn.TEXTSPLIT(D8," "), G8))) / COUNTA(_xlfn.TEXTSPLIT(D8," ")) > 0.5, "Partial Match", "No Match" ) )} -> No Match | L8: {=_xldudf_BOARDFLARE_FMATCH(G8,D8)} -> #NAME? | M8: {=_FV(L8,"Similarity",TRUE)} -> #VALUE! | N8: {=_xldudf_BOARDFLARE_FMATCH(D8,G8)} -> #NAME? | O8: {=_FV(N8,"Similarity",TRUE)} -> #VALUE!
A9: <Protocol Identification (Code or Number)> | C9: KeyValue | D9: SKY-2000-101 | E9: Mock_CSR_Protocol.docx | G9: SKY-2000-101 | I9: {=_xldudf_BOARDFLARE_FMATCH(G9,D9)} -> #NAME? | J9: =IF(M9>O9, M9,O9) -> #VALUE! | K9: {=IF( SUMPRODUCT(--ISNUMBER(SEARCH(_xlfn.TEXTSPLIT(D9," "), G9))) / COUNTA(_xlfn.TEXTSPLIT(D9," ")) = 1, "Full Match", IF( SUMPRODUCT(--ISNUMBER(SEARCH(_xlfn.TEXTSPLIT(D9," "), G9))) / COUNTA(_xlfn.TEXTSPLIT(D9," ")) > 0.5, "Partial Match", "No Match" ) )} -> No Match | L9: {=_xldudf_BOARDFLARE_FMATCH(G9,D9)} -> #NAME? | M9: {=_FV(L9,"Similarity",TRUE)} -> #VALUE! | N9: {=_xldudf_BOARDFLARE_FMATCH(D9,G9)} -> #NAME? | O9: {=_FV(N9,"Similarity",TRUE)} -> #VALUE!
A10: <Investigational Drug Name> | C10: KeyValue | D10: ABC-123 | E10: Mock_CSR_Protocol.docx | F10: Provide the investigational drug name in concise form. | G10: ABC-123 | I10: {=_xldudf_BOARDFLARE_FMATCH(G10,D10)} -> #NAME? | J10: =IF(M10>O10, M10,O10) -> #VALUE! | K10: {=IF( SUMPRODUCT(--ISNUMBER(SEARCH(_xlfn.TEXTSPLIT(D10," "), G10))) / COUNTA(_xlfn.TEXTSPLIT(D10," ")) = 1, "Full Match", IF( SUMPRODUCT(--ISNUMBER(SEARCH(_xlfn.TEXTSPLIT(D10," "), G10))) / COUNTA(_xlfn.TEXTSPLIT(D10," ")) > 0.5, "Partial Match", "No Match" ) )} -> No Match | L10: {=_xldudf_BOARDFLARE_FMATCH(G10,D10)} -> #NAME? | M10: {=_FV(L10,"Similarity",TRUE)} -> #VALUE! | N10: {=_xldudf_BOARDFLARE_FMATCH(D10,G10)} -> #NAME? | O10: {=_FV(N10,"Similarity",TRUE)} -> #VALUE!
A11: <IND Number> | C11: KeyValue | D11: 123456 | E11: Mock_CSR_Protocol.docx | F11: Provide the IND number in numeric format. | G11: 123456 | I11: {=_xldudf_BOARDFLARE_FMATCH(G11,D11)} -> #NAME? | J11: =IF(M11>O11, M11,O11) -> #VALUE! | K11: {=IF( SUMPRODUCT(--ISNUMBER(SEARCH(_xlfn.TEXTSPLIT(D11," "), G11))) / COUNTA(_xlfn.TEXTSPLIT(D11," ")) = 1, "Full Match", IF( SUMPRODUCT(--ISNUMBER(SEARCH(_xlfn.TEXTSPLIT(D11," "), G11))) / COUNTA(_xlfn.TEXTSPLIT(D11," ")) > 0.5, "Partial Match", "No Match" ) )} -> No Match | L11: {=_xldudf_BOARDFLARE_FMATCH(G11,D11)} -> #NAME? | M11: {=_FV(L11,"Similarity",TRUE)} -> #VALUE! | N11: {=_xldudf_BOARDFLARE_FMATCH(D11,G11)} -> #NAME? | O11: {=_FV(N11,"Similarity",TRUE)} -> #VALUE!
A12: <PHASE X> | C12: KeyValue | D12: Phase 1 | E12: Mock_CSR_Protocol.docx | F12: Return the study phase in the format 'Phase X', matching the placeholder format. | G12: Phase 1 | I12: {=_xldudf_BOARDFLARE_FMATCH(G12,D12)} -> #NAME? | J12: =IF(M12>O12, M12,O12) -> #VALUE! | K12: {=IF( SUMPRODUCT(--ISNUMBER(SEARCH(_xlfn.TEXTSPLIT(D12," "), G12))) / COUNTA(_xlfn.TEXTSPLIT(D12," ")) = 1, "Full Match", IF( SUMPRODUCT(--ISNUMBER(SEARCH(_xlfn.TEXTSPLIT(D12," "), G12))) / COUNTA(_xlfn.TEXTSPLIT(D12," ")) > 0.5, "Partial Match", "No Match" ) )} -> No Match | L12: {=_xldudf_BOARDFLARE_FMATCH(G12,D12)} -> #NAME? | M12: {=_FV(L12,"Similarity",TRUE)} -> #VALUE! | N12: {=_xldudf_BOARDFLARE_FMATCH(D12,G12)} -> #NAME? | O12: {=_FV(N12,"Similarity",TRUE)} -> #VALUE!
A13: <Sponsor's Name> | C13: Inline | D13: Stendarr, Inc | E13: Mock_CSR_Protocol.docx | G13: Sponsor | I13: {=_xldudf_BOARDFLARE_FMATCH(G13,D13)} -> #NAME? | J13: =IF(M13>O13, M13,O13) -> #VALUE! | L13: {=_xldudf_BOARDFLARE_FMATCH(G13,D13)} -> #NAME? | M13: {=_FV(L13,"Similarity",TRUE)} -> #VALUE! | N13: {=_xldudf_BOARDFLARE_FMATCH(D13,G13)} -> #NAME? | O13: {=_FV(N13,"Similarity",TRUE)} -> #VALUE! | AK13: {=IF( SUMPRODUCT(--ISNUMBER(SEARCH(_xlfn.TEXTSPLIT(D13," "), G13))) / COUNTA(_xlfn.TEXTSPLIT(D13," ")) = 1, "Full Match", IF( SUMPRODUCT(--ISNUMBER(SEARCH(_xlfn.TEXTSPLIT(D13," "), G13))) / COUNTA(_xlfn.TEXTSPLIT(D13," ")) > 0.5, "Partial Match", "No Match" ) )} -> No Match
A14: <Sponsor's Address> | C14: KeyValue | D14: 123 Fake Street Anytown, CO USA 80002 | E14: Mock_CSR_Protocol.docx | I14: {=_xldudf_BOARDFLARE_FMATCH(G14,D14)} -> #NAME? | J14: =IF(M14>O14, M14,O14) -> #VALUE! | K14: {=IF( SUMPRODUCT(--ISNUMBER(SEARCH(_xlfn.TEXTSPLIT(D14," "), G14))) / COUNTA(_xlfn.TEXTSPLIT(D14," ")) = 1, "Full Match", IF( SUMPRODUCT(--ISNUMBER(SEARCH(_xlfn.TEXTSPLIT(D14," "), G14))) / COUNTA(_xlfn.TEXTSPLIT(D14," ")) > 0.5, "Partial Match", "No Match" ) )} -> No Match | L14: {=_xldudf_BOARDFLARE_FMATCH(G14,D14)} -> #NAME? | M14: {=_FV(L14,"Similarity",TRUE)} -> #VALUE! | N14: {=_xldudf_BOARDFLARE_FMATCH(D14,G14)} -> #NAME? | O14: {=_FV(N14,"Similarity",TRUE)} -> #VALUE!
A15: <Sponsor's Name> | C15: Inline | D15: Stendarr, Inc | E15: Mock_CSR_Protocol.docx | F15: Provide the Sponsor's name exactly as stated in the authoritative context. | G15: Sponsor | I15: {=_xldudf_BOARDFLARE_FMATCH(G15,D15)} -> #NAME? | J15: =IF(M15>O15, M15,O15) -> #VALUE! | L15: {=_xldudf_BOARDFLARE_FMATCH(G15,D15)} -> #NAME? | M15: {=_FV(L15,"Similarity",TRUE)} -> #VALUE! | N15: {=_xldudf_BOARDFLARE_FMATCH(D15,G15)} -> #NAME? | O15: {=_FV(N15,"Similarity",TRUE)} -> #VALUE! | AK15: {=IF( SUMPRODUCT(--ISNUMBER(SEARCH(_xlfn.TEXTSPLIT(D15," "), G15))) / COUNTA(_xlfn.TEXTSPLIT(D15," ")) = 1, "Full Match", IF( SUMPRODUCT(--ISNUMBER(SEARCH(_xlfn.TEXTSPLIT(D15," "), G15))) / COUNTA(_xlfn.TEXTSPLIT(D15," ")) > 0.5, "Partial Match", "No Match" ) )} -> No Match
A16: <Sponsor> | C16: Inline | D16: Stendarr, Inc | E16: Mock_CSR_Protocol.docx | F16: Insert the Sponsor name inline, matching the format and continuity of the surrounding text. | G16: Stendarr, Inc. | I16: {=_xldudf_BOARDFLARE_FMATCH(G16,D16)} -> #NAME? | J16: =IF(M16>O16, M16,O16) -> #VALUE! | L16: {=_xldudf_BOARDFLARE_FMATCH(G16,D16)} -> #NAME? | M16: {=_FV(L16,"Similarity",TRUE)} -> #VALUE! | N16: {=_xldudf_BOARDFLARE_FMATCH(D16,G16)} -> #NAME? | O16: {=_FV(N16,"Similarity",TRUE)} -> #VALUE! | AK16: {=IF( SUMPRODUCT(--ISNUMBER(SEARCH(_xlfn.TEXTSPLIT(D16," "), G16))) / COUNTA(_xlfn.TEXTSPLIT(D16," ")) = 1, "Full Match", IF( SUMPRODUCT(--ISNUMBER(SEARCH(_xlfn.TEXTSPLIT(D16," "), G16))) / COUNTA(_xlfn.TEXTSPLIT(D16," ")) > 0.5, "Partial Match", "No Match" ) )} -> No Match
A17: <Synopsis> | C17: Paragraph | D17: A First-In-Human, Phase 1, Randomized, Double-Blind, Placebo-Controlled Study to Evaluate the Safety, Tolerability, and Pharmacokinetics of ABC-123 as a Single Dose in Healthy Participants and as Multiple Doses in Participants with Grade 2 Boneitis.Short Title: Phase 1 RCT of ABC-123 in healthy participants (SAD) and participants with boneitis (repeat-dose) | E17: Mock_CSR_Protocol.docx | F17: Provide a brief synopsis summarizing the protocol title and short title for the study. | G17: A First-In-Human, Phase 1, Randomized, Double-Blind, Placebo-Controlled Study to Evaluate the Safety, Tolerability, and Pharmacokinetics of ABC-123 as a Single Dose in Healthy Participants and as Multiple Doses in Participants with Grade 2 Boneitis.Short Title: Phase 1 RCT of ABC-123 in healthy participants (SAD) and participants with boneitis (repeat-dose) | I17: {=_xldudf_BOARDFLARE_FMATCH(G17,D17)} -> #NAME? | J17: =IF(M17>O17, M17,O17) -> #VALUE! | K17: {=IF( SUMPRODUCT(--ISNUMBER(SEARCH(_xlfn.TEXTSPLIT(D17," "), G17))) / COUNTA(_xlfn.TEXTSPLIT(D17," ")) = 1, "Full Match", IF( SUMPRODUCT(--ISNUMBER(SEARCH(_xlfn.TEXTSPLIT(D17," "), G17))) / COUNTA(_xlfn.TEXTSPLIT(D17," ")) > 0.5, "Partial Match", "No Match" ) )} -> No Match | L17: {=_xldudf_BOARDFLARE_FMATCH(G17,D17)} -> #NAME? | M17: {=_FV(L17,"Similarity",TRUE)} -> #VALUE! | N17: {=_xldudf_BOARDFLARE_FMATCH(D17,G17)} -> #NAME? | O17: {=_FV(N17,"Similarity",TRUE)} -> #VALUE! | AE17: yes | AF17: no | AG17: =AE17=AF17 -> FALSE | AH17: {=SUMPRODUCT(--ISNUMBER(SEARCH(_xlfn.TEXTSPLIT(D17," "), G17))) / COUNTA(_xlfn.TEXTSPLIT(D17," "))} -> 0 | AI17: {=IF( SUMPRODUCT(--ISNUMBER(SEARCH(_xlfn.TEXTSPLIT(D17," "), G17))) / COUNTA(_xlfn.TEXTSPLIT(D17," ")) = 1, "Full Match", IF( SUMPRODUCT(--ISNUMBER(SEARCH(_xlfn.TEXTSPLIT(D17," "), G17))) / COUNTA(_xlfn.TEXTSPLIT(D17," ")) > 0.5, "Partial Match", "No Match" ) )} -> No Match
A18: <xx study centers by xx investigators> | C18: Inline | E18: Mock_CSR_Protocol.docx | F18: Replace the placeholder with the number of study centers and investigators if available. | G18: in cooperation with a number of support organizations (Table 1). A list of investigators and other important participants in the study is provided in Appendix 16.1.4. Signatures of the Coordinating Investigator and the Sponsor's responsible medical officer are included in Appendix 16.1.5. | I18: {=_xldudf_BOARDFLARE_FMATCH(G18,D18)} -> #NAME? | J18: =IF(M18>O18, M18,O18) -> #VALUE! | L18: {=_xldudf_BOARDFLARE_FMATCH(G18,D18)} -> #NAME? | M18: {=_FV(L18,"Similarity",TRUE)} -> #VALUE! | N18: {=_xldudf_BOARDFLARE_FMATCH(D18,G18)} -> #NAME? | O18: {=_FV(N18,"Similarity",TRUE)} -> #VALUE! | AK18: {=IF( SUMPRODUCT(--ISNUMBER(SEARCH(_xlfn.TEXTSPLIT(D18," "), G18))) / COUNTA(_xlfn.TEXTSPLIT(D18," ")) = 1, "Full Match", IF( SUMPRODUCT(--ISNUMBER(SEARCH(_xlfn.TEXTSPLIT(D18," "), G18))) / COUNTA(_xlfn.TEXTSPLIT(D18," ")) > 0.5, "Partial Match", "No Match" ) )} -> No Match
A19: <Company Name> | C19: Paragraph | D19: Stendarr, Inc | E19: Mock_CSR_Protocol.docx | F19: Insert the company name associated with the study, matching the format of the placeholder. | G19: Clinovance Solutions, Inc | I19: {=_xldudf_BOARDFLARE_FMATCH(G19,D19)} -> #NAME? | J19: =IF(M19>O19, M19,O19) -> #VALUE! | K19: {=IF( SUMPRODUCT(--ISNUMBER(SEARCH(_xlfn.TEXTSPLIT(D19," "), G19))) / COUNTA(_xlfn.TEXTSPLIT(D19," ")) = 1, "Full Match", IF( SUMPRODUCT(--ISNUMBER(SEARCH(_xlfn.TEXTSPLIT(D19," "), G19))) / COUNTA(_xlfn.TEXTSPLIT(D19," ")) > 0.5, "Partial Match", "No Match" ) )} -> No Match | L19: {=_xldudf_BOARDFLARE_FMATCH(G19,D19)} -> #NAME? | M19: {=_FV(L19,"Similarity",TRUE)} -> #VALUE! | N19: {=_xldudf_BOARDFLARE_FMATCH(D19,G19)} -> #NAME? | O19: {=_FV(N19,"Similarity",TRUE)} -> #VALUE! | AE19: yes | AF19: yes | AG19: =AE19=AF19 -> TRUE | AH19: {=SUMPRODUCT(--ISNUMBER(SEARCH(_xlfn.TEXTSPLIT(D19," "), G19))) / COUNTA(_xlfn.TEXTSPLIT(D19," "))} -> 0 | AI19: {=IF( SUMPRODUCT(--ISNUMBER(SEARCH(_xlfn.TEXTSPLIT(D19," "), G19))) / COUNTA(_xlfn.TEXTSPLIT(D19," ")) = 1, "Full Match", IF( SUMPRODUCT(--ISNUMBER(SEARCH(_xlfn.TEXTSPLIT(D19," "), G19))) / COUNTA(_xlfn.TEXTSPLIT(D19," ")) > 0.5, "Partial Match", "No Match" ) )} -> No Match
A20: <Company Address> | C20: KeyValue | D20: 123 Fake Street Anytown, CO USA 80002 | E20: Mock_CSR_Protocol.docx | F20: Insert the official company address in standard format. | G20: Clinovance Solutions, Inc. 582 Clinical Trail Blvd San Mate, CO 944 USA | I20: {=_xldudf_BOARDFLARE_FMATCH(G20,D20)} -> #NAME? | J20: =IF(M20>O20, M20,O20) -> #VALUE! | K20: {=IF( SUMPRODUCT(--ISNUMBER(SEARCH(_xlfn.TEXTSPLIT(D20," "), G20))) / COUNTA(_xlfn.TEXTSPLIT(D20," ")) = 1, "Full Match", IF( SUMPRODUCT(--ISNUMBER(SEARCH(_xlfn.TEXTSPLIT(D20," "), G20))) / COUNTA(_xlfn.TEXTSPLIT(D20," ")) > 0.5, "Partial Match", "No Match" ) )} -> No Match | L20: {=_xldudf_BOARDFLARE_FMATCH(G20,D20)} -> #NAME? | M20: {=_FV(L20,"Similarity",TRUE)} -> #VALUE! | N20: {=_xldudf_BOARDFLARE_FMATCH(D20,G20)} -> #NAME? | O20: {=_FV(N20,"Similarity",TRUE)} -> #VALUE!
A21: <Medical Monitor Name> | C21: KeyValue | D21: Karliah N. Gale, MD | E21: Mock_CSR_Protocol.docx | F21: Provide the full name of the Medical Monitor if available; otherwise, leave blank. | G21: Michael Yu | I21: {=_xldudf_BOARDFLARE_FMATCH(G21,D21)} -> #NAME? | J21: =IF(M21>O21, M21,O21) -> #VALUE! | K21: {=IF( SUMPRODUCT(--ISNUMBER(SEARCH(_xlfn.TEXTSPLIT(D21," "), G21))) / COUNTA(_xlfn.TEXTSPLIT(D21," ")) = 1, "Full Match", IF( SUMPRODUCT(--ISNUMBER(SEARCH(_xlfn.TEXTSPLIT(D21," "), G21))) / COUNTA(_xlfn.TEXTSPLIT(D21," ")) > 0.5, "Partial Match", "No Match" ) )} -> No Match | L21: {=_xldudf_BOARDFLARE_FMATCH(G21,D21)} -> #NAME? | M21: {=_FV(L21,"Similarity",TRUE)} -> #VALUE! | N21: {=_xldudf_BOARDFLARE_FMATCH(D21,G21)} -> #NAME? | O21: {=_FV(N21,"Similarity",TRUE)} -> #VALUE!
A22: <Introduction> | C22: Paragraph | D22: Lurgi is the leading cause of boneitis, eventually leading to the need for surgical intervention in the form of either a partial or complete brainectomy (Biagini et al. 2008). Zammoxin has been the standard of care for many years, and myrnestristoate has recently been approved in the European Union and United States (US) as an additional treatment. Even with treatment, patients with lurgi continue to be at risk for the morbidity, mortality, and impaired quality of life associated with boneitis. Thus, a high unmet medical need remains. The cadmium quantum shift flipper is a G protein-coupled receptor (GPCR), which is characterized by high levels of whomp and activated by promethium. Promethium activation has also been shown to lead to the phosphorylation and activation of mitogen-activated protein kinases. Compelling evidence from nonclinical studies suggests that the mekkalekka is enfrazzled on the snoot in up to 80% of cases. Whomp is predominantly upregulated in the grudgeon cells in murine models of boneitis. Pharmacological inhibition by blorp induction ameliorates whomp, inhibits spasms in the superior noidal zone, and prevents hyperfractal embarkation. | E22: Mock_CSR_Protocol.docx | F22: Write a concise introductory paragraph summarizing the investigational product, indication, study objectives, and population. | G22: ABC-123, a triolic gluon fragmentator, is being investigated for the treatment of lurgi, a condition that leads to boneitis and may require surgical interventions such as partial or complete brainectomy. The study aims to evaluate the safety, tolerability, and potentially the pharmacodynamics of ABC-123 by targeting the cadmium quantum shift flipper, which may reduce the risk of boneitis. The study includes patients with lurgi, a population with high unmet medical need, and utilizes a design that allows for meaningful exposure over 2 to 4 weeks, even with a single high-end dose. | I22: {=_xldudf_BOARDFLARE_FMATCH(G22,D22)} -> #NAME? | J22: =IF(M22>O22, M22,O22) -> #VALUE! | K22: {=IF( SUMPRODUCT(--ISNUMBER(SEARCH(_xlfn.TEXTSPLIT(D22," "), G22))) / COUNTA(_xlfn.TEXTSPLIT(D22," ")) = 1, "Full Match", IF( SUMPRODUCT(--ISNUMBER(SEARCH(_xlfn.TEXTSPLIT(D22," "), G22))) / COUNTA(_xlfn.TEXTSPLIT(D22," ")) > 0.5, "Partial Match", "No Match" ) )} -> No Match | L22: {=_xldudf_BOARDFLARE_FMATCH(G22,D22)} -> #NAME? | M22: {=_FV(L22,"Similarity",TRUE)} -> #VALUE! | N22: {=_xldudf_BOARDFLARE_FMATCH(D22,G22)} -> #NAME? | O22: {=_FV(N22,"Similarity",TRUE)} -> #VALUE! | AE22: yes | AF22: yes | AG22: =AE22=AF22 -> TRUE | AH22: {=SUMPRODUCT(--ISNUMBER(SEARCH(_xlfn.TEXTSPLIT(D22," "), G22))) / COUNTA(_xlfn.TEXTSPLIT(D22," "))} -> 0 | AI22: {=IF( SUMPRODUCT(--ISNUMBER(SEARCH(_xlfn.TEXTSPLIT(D22," "), G22))) / COUNTA(_xlfn.TEXTSPLIT(D22," ")) = 1, "Full Match", IF( SUMPRODUCT(--ISNUMBER(SEARCH(_xlfn.TEXTSPLIT(D22," "), G22))) / COUNTA(_xlfn.TEXTSPLIT(D22," ")) > 0.5, "Partial Match", "No Match" ) )} -> No Match
A23: <Background Information> | C23: Paragraph | D23: ABC-123 is a triolic gluon fragmentator, a type of blorp inductor made with binkles and naturally occurring fram. Blorp inductors typically have a long half-life, which facilitates weekly or monthly dosing, and are generally found to be poorly penetrant to the CNS. By targeting only peripheral receptors, ABC-123 potentially reduces the risk for boneitis previously described in patients with lurgi. This is a first-in-human study. It is intended to provide the initial safety, PK, and pharmacology data for ABC-123 in humans | E23: Mock_CSR_Protocol.docx | F23: Write a concise background paragraph summarizing the investigational product, its mechanism, class, preclinical evidence, and first-in-human study context. | G23: ABC-123 is a triolic gluon fragmentator, classified as a blorp inductor composed of binkles and fram. Blorp inductors are characterized by a long half-life, enabling weekly or monthly dosing, and are generally poorly penetrant to the CNS, which may reduce the risk of boneitis seen in patients with lurgi. This first-in-human study aims to establish the initial safety, pharmacokinetics, and pharmacology of ABC-123. Preclinical studies have demonstrated that ABC-123 is a potent, selective monoclonal antibody antagonist and inverse agonist of human and monkey grudgeon cells, protecting these cells in vitro and showing pharmacological activity in peripheral tissues without brain involvement. The safety profile of related blorp inductors has been favorable outside CNS effects, with gastrointestinal adverse events being most common. The current study is designed to address the unmet need for a safe and effective peripheral blorp inductor, given the limitations of previous agents. More details on the benefits, risks, and adverse events are available in the Investigator’s Brochure | I23: {=_xldudf_BOARDFLARE_FMATCH(G23,D23)} -> #NAME? | J23: =IF(M23>O23, M23,O23) -> #VALUE! | K23: {=IF( SUMPRODUCT(--ISNUMBER(SEARCH(_xlfn.TEXTSPLIT(D23," "), G23))) / COUNTA(_xlfn.TEXTSPLIT(D23," ")) = 1, "Full Match", IF( SUMPRODUCT(--ISNUMBER(SEARCH(_xlfn.TEXTSPLIT(D23," "), G23))) / COUNTA(_xlfn.TEXTSPLIT(D23," ")) > 0.5, "Partial Match", "No Match" ) )} -> No Match | L23: {=_xldudf_BOARDFLARE_FMATCH(G23,D23)} -> #NAME? | M23: {=_FV(L23,"Similarity",TRUE)} -> #VALUE! | N23: {=_xldudf_BOARDFLARE_FMATCH(D23,G23)} -> #NAME? | O23: {=_FV(N23,"Similarity",TRUE)} -> #VALUE! | AE23: yes | AF23: yes | AG23: =AE23=AF23 -> TRUE | AH23: {=SUMPRODUCT(--ISNUMBER(SEARCH(_xlfn.TEXTSPLIT(D23," "), G23))) / COUNTA(_xlfn.TEXTSPLIT(D23," "))} -> 0 | AI23: {=IF( SUMPRODUCT(--ISNUMBER(SEARCH(_xlfn.TEXTSPLIT(D23," "), G23))) / COUNTA(_xlfn.TEXTSPLIT(D23," ")) = 1, "Full Match", IF( SUMPRODUCT(--ISNUMBER(SEARCH(_xlfn.TEXTSPLIT(D23," "), G23))) / COUNTA(_xlfn.TEXTSPLIT(D23," ")) > 0.5, "Partial Match", "No Match" ) )} -> No Match
A24: <Rationale for the study> | C24: Paragraph | D24: The SAD portion of this study is a standard design for first-in-human testing with a monoclonal antibody. In addition, a 4-week repeated dose cohort will allow confirmation of the safety, tolerability, and repeat-dose PK and immunogenicity in the target population prior to proceeding to subsequent repeat-dose studies in a patient population | E24: Mock_CSR_Protocol.docx | F24: Summarize why the study was conducted, how the design addresses early development goals (safety, tolerability, PK, PD), and justify population, dosing, and exploratory objectives. | G24: This first-in-human, Phase 1 study of ABC-123 was conducted to establish the safety, tolerability, and pharmacokinetics (PK) of the drug in healthy volunteers and in participants with Grade 2 boneitis. The study design includes a single ascending dose (SAD) phase in healthy subjects, supporting the evaluation of safety and PK over up to 28 days, followed by a repeat-dose exploratory efficacy phase in patients with boneitis. The selected study populations and dosing strategies are intended to provide initial human safety and PK data, support dose selection, and inform subsequent studies. Additionally, the study explores phenotypic, genotypic, and biochemical biomarkers to identify patients most likely to respond to ABC-123. The rationale for this approach is supported by nonclinical pharmacology and safety data, which demonstrate the compound's selectivity and tolerability, and by the need to characterize ABC-123's effects prior to advancing to larger clinical studies | I24: {=_xldudf_BOARDFLARE_FMATCH(G24,D24)} -> #NAME? | J24: =IF(M24>O24, M24,O24) -> #VALUE! | K24: {=IF( SUMPRODUCT(--ISNUMBER(SEARCH(_xlfn.TEXTSPLIT(D24," "), G24))) / COUNTA(_xlfn.TEXTSPLIT(D24," ")) = 1, "Full Match", IF( SUMPRODUCT(--ISNUMBER(SEARCH(_xlfn.TEXTSPLIT(D24," "), G24))) / COUNTA(_xlfn.TEXTSPLIT(D24," ")) > 0.5, "Partial Match", "No Match" ) )} -> No Match | L24: {=_xldudf_BOARDFLARE_FMATCH(G24,D24)} -> #NAME? | M24: {=_FV(L24,"Similarity",TRUE)} -> #VALUE! | N24: {=_xldudf_BOARDFLARE_FMATCH(D24,G24)} -> #NAME? | O24: {=_FV(N24,"Similarity",TRUE)} -> #VALUE! | AE24: yes | AF24: yes | AG24: =AE24=AF24 -> TRUE | AH24: {=SUMPRODUCT(--ISNUMBER(SEARCH(_xlfn.TEXTSPLIT(D24," "), G24))) / COUNTA(_xlfn.TEXTSPLIT(D24," "))} -> 0 | AI24: {=IF( SUMPRODUCT(--ISNUMBER(SEARCH(_xlfn.TEXTSPLIT(D24," "), G24))) / COUNTA(_xlfn.TEXTSPLIT(D24," ")) = 1, "Full Match", IF( SUMPRODUCT(--ISNUMBER(SEARCH(_xlfn.TEXTSPLIT(D24," "), G24))) / COUNTA(_xlfn.TEXTSPLIT(D24," ")) > 0.5, "Partial Match", "No Match" ) )} -> No Match
A25: <Benefit and Risk assessment> | C25: Paragraph | D25: ABC-123 has not been studied in humans; therefore, the risk-benefit analysis considerations are based on nonclinical data and reports in the literature on similar therapies. The benefits to participants in the ABC-123 clinical program may include contributing to the process of developing new therapies in an area of unmet need and medical evaluations/assessments associated with study procedures (eg, physical examination); participants with boneitis due to lurgi may or may not experience an impact on progression of the disease. The risks of participation are primarily those associated with adverse reactions to the investigational medicinal product, although there may also be some discomfort associated with subcutaneous (SC) injections or study procedures (eg, blood collection). | E25: Mock_CSR_Protocol.docx | F25: Summarize the risks, potential benefits, and overall benefit–risk conclusion for ABC-123 based on study data in a structured paragraph. | G25: ABC-123 has not been studied in humans; risk assessment is based on nonclinical data and analogous therapies. No known risks, including CNS-associated risks, have been observed in nonclinical pharmacology and safety studies. However, potential risks include adverse reactions to the investigational product, discomfort from subcutaneous injections or study procedures, and CNS-associated effects seen with similar therapies (such as amphibious jocularity, levitation, and the crunge). Additional risks observed with blorp inductors include gastrointestinal events (nausea, diarrhea, vomiting), asthenia/fatigue, hot flushes, and dizziness. Participants will be closely monitored for adverse effects.Potential Benefits: As this is a non-therapeutic study in healthy volunteers and participants with boneitis, direct clinical benefit is not assured. Potential benefits include contributing to the development of new therapies in an area of unmet need and receiving medical evaluations associated with study procedures. There may or may not be an impact on disease progression for participants with boneitis.Overall Benefit–Risk Conclusion: The prior safety experience with similar therapies, lack of brain penetration in nonclinical studies, and absence of significant adverse findings in animal studies support the conduct of this study. The anticipated benefits to medical and scientific knowledge justify the potential risks, which are minimized through appropriate monitoring and dose escalation. Overall, the benefit–risk assessment is considered favorable for participation in this study. | I25: {=_xldudf_BOARDFLARE_FMATCH(G25,D25)} -> #NAME? | J25: =IF(M25>O25, M25,O25) -> #VALUE! | K25: {=IF( SUMPRODUCT(--ISNUMBER(SEARCH(_xlfn.TEXTSPLIT(D25," "), G25))) / COUNTA(_xlfn.TEXTSPLIT(D25," ")) = 1, "Full Match", IF( SUMPRODUCT(--ISNUMBER(SEARCH(_xlfn.TEXTSPLIT(D25," "), G25))) / COUNTA(_xlfn.TEXTSPLIT(D25," ")) > 0.5, "Partial Match", "No Match" ) )} -> No Match | L25: {=_xldudf_BOARDFLARE_FMATCH(G25,D25)} -> #NAME? | M25: {=_FV(L25,"Similarity",TRUE)} -> #VALUE! | N25: {=_xldudf_BOARDFLARE_FMATCH(D25,G25)} -> #NAME? | O25: {=_FV(N25,"Similarity",TRUE)} -> #VALUE! | AE25: yes | AF25: yes | AG25: =AE25=AF25 -> TRUE | AH25: {=SUMPRODUCT(--ISNUMBER(SEARCH(_xlfn.TEXTSPLIT(D25," "), G25))) / COUNTA(_xlfn.TEXTSPLIT(D25," "))} -> 0 | AI25: {=IF( SUMPRODUCT(--ISNUMBER(SEARCH(_xlfn.TEXTSPLIT(D25," "), G25))) / COUNTA(_xlfn.TEXTSPLIT(D25," ")) = 1, "Full Match", IF( SUMPRODUCT(--ISNUMBER(SEARCH(_xlfn.TEXTSPLIT(D25," "), G25))) / COUNTA(_xlfn.TEXTSPLIT(D25," ")) > 0.5, "Partial Match", "No Match" ) )} -> No Match
A26: <Risk assessment> | C26: Paragraph | D26: There are no known risks, including CNS-associated risks, that have been observed in nonclinical pharmacology and safety studies of ABC-123. ABC-123 targets peripheral receptors, potentially reducing the risk for the CNS-associated adverse effects observed in blorp inductors (ie, amphibious jocularity, levitation, and the crunge). Participants in the ABC-123 clinical program will be closely monitored for these CNS-associated risks until sufficient data in the ABC-123 clinical program are available to discharge these risks. Additional risks observed in clinical studies with blorp inductors include gastrointestinal adverse events (primarily nausea, diarrhea, and vomiting), asthenia/fatigue, hot flushes, and dizziness. Participants will be monitored closely for the development of adverse effects that may result from study drug administration | E26: Mock_CSR_Protocol.docx | F26: Summarize the risks identified for ABC-123, referencing TEAEs, SAEs, discontinuations, theoretical risks, and risk mitigation measures; conclude with a high-level safety profile overview. | G26: ABC-123 has not been studied in humans; therefore, risk assessment is based on nonclinical data and literature on similar therapies. No known risks, including CNS-associated risks, were observed in nonclinical pharmacology and safety studies of ABC-123. Theoretical risks, based on the drug’s mechanism and experience with similar blorp inductors, include CNS-associated adverse effects (such as amphibious jocularity, levitation, and the crunge), as well as gastrointestinal events (nausea, diarrhea, vomiting), asthenia/fatigue, hot flushes, and dizziness. There were no observed treatment-emergent adverse events (TEAEs), serious adverse events (SAEs), or discontinuations due to adverse events in the nonclinical studies. Risk mitigation measures include close monitoring of participants for CNS and other adverse effects, with ongoing assessment until sufficient clinical data are available to discharge these risks. Overall, the safety profile of ABC-123 is considered favorable based on available nonclinical data, with a low risk of CNS or other significant adverse events anticipated. | I26: {=_xldudf_BOARDFLARE_FMATCH(G26,D26)} -> #NAME? | J26: =IF(M26>O26, M26,O26) -> #VALUE! | K26: {=IF( SUMPRODUCT(--ISNUMBER(SEARCH(_xlfn.TEXTSPLIT(D26," "), G26))) / COUNTA(_xlfn.TEXTSPLIT(D26," ")) = 1, "Full Match", IF( SUMPRODUCT(--ISNUMBER(SEARCH(_xlfn.TEXTSPLIT(D26," "), G26))) / COUNTA(_xlfn.TEXTSPLIT(D26," ")) > 0.5, "Partial Match", "No Match" ) )} -> No Match | L26: {=_xldudf_BOARDFLARE_FMATCH(G26,D26)} -> #NAME? | M26: {=_FV(L26,"Similarity",TRUE)} -> #VALUE! | N26: {=_xldudf_BOARDFLARE_FMATCH(D26,G26)} -> #NAME? | O26: {=_FV(N26,"Similarity",TRUE)} -> #VALUE! | AE26: yes | AF26: yes | AG26: =AE26=AF26 -> TRUE | AH26: {=SUMPRODUCT(--ISNUMBER(SEARCH(_xlfn.TEXTSPLIT(D26," "), G26))) / COUNTA(_xlfn.TEXTSPLIT(D26," "))} -> 0 | AI26: {=IF( SUMPRODUCT(--ISNUMBER(SEARCH(_xlfn.TEXTSPLIT(D26," "), G26))) / COUNTA(_xlfn.TEXTSPLIT(D26," ")) = 1, "Full Match", IF( SUMPRODUCT(--ISNUMBER(SEARCH(_xlfn.TEXTSPLIT(D26," "), G26))) / COUNTA(_xlfn.TEXTSPLIT(D26," ")) > 0.5, "Partial Match", "No Match" ) )} -> No Match
A27: <Benefit assessment> | C27: Paragraph | D27: This is a non-therapeutic study in healthy volunteers (SAD component) and participants with boneitis (repeat-dose component). Potential benefits for participants in the study may include: ● Contributing to the process of developing new therapies in an area of unmet need ● Medical evaluations/assessments associated with study procedures (eg, physical examination, electrocardiogram [ECG], laboratory assessments). | E27: Mock_CSR_Protocol.docx | F27: Summarize the benefit assessment for ABC-123, emphasizing nonclinical evidence, participant contributions, and the clinical need for new therapies for boneitis due to lurgi. | I27: {=_xldudf_BOARDFLARE_FMATCH(G27,D27)} -> #NAME? | J27: =IF(M27>O27, M27,O27) -> #VALUE! | K27: {=IF( SUMPRODUCT(--ISNUMBER(SEARCH(_xlfn.TEXTSPLIT(D27," "), G27))) / COUNTA(_xlfn.TEXTSPLIT(D27," ")) = 1, "Full Match", IF( SUMPRODUCT(--ISNUMBER(SEARCH(_xlfn.TEXTSPLIT(D27," "), G27))) / COUNTA(_xlfn.TEXTSPLIT(D27," ")) > 0.5, "Partial Match", "No Match" ) )} -> No Match | L27: {=_xldudf_BOARDFLARE_FMATCH(G27,D27)} -> #NAME? | M27: {=_FV(L27,"Similarity",TRUE)} -> #VALUE! | N27: {=_xldudf_BOARDFLARE_FMATCH(D27,G27)} -> #NAME? | O27: {=_FV(N27,"Similarity",TRUE)} -> #VALUE! | AE27: yes | AF27: NA | AG27: =AE27=AF27 -> FALSE | AH27: {=SUMPRODUCT(--ISNUMBER(SEARCH(_xlfn.TEXTSPLIT(D27," "), G27))) / COUNTA(_xlfn.TEXTSPLIT(D27," "))} -> 0 | AI27: {=IF( SUMPRODUCT(--ISNUMBER(SEARCH(_xlfn.TEXTSPLIT(D27," "), G27))) / COUNTA(_xlfn.TEXTSPLIT(D27," ")) = 1, "Full Match", IF( SUMPRODUCT(--ISNUMBER(SEARCH(_xlfn.TEXTSPLIT(D27," "), G27))) / COUNTA(_xlfn.TEXTSPLIT(D27," ")) > 0.5, "Partial Match", "No Match" ) )} -> No Match
A28: <Overall Benefit: Risk Conclusion> | C28: Paragraph | D28: The pharmacodynamic analysis demonstrated that ABC-123 induces notable biomarker changes in both healthy volunteers following single ascending doses and in Boneitis patients receiving repeated doses. In healthy participants, modest improvements were observed in glucose metabolism and insulin sensitivity, as evidenced by reductions in fasting glucose, insulin, and leptin, alongside increased adiponectin levels. These changes were more pronounced in Boneitis participants, where repeated dosing resulted in significant reductions in fasting glucose, insulin, C-peptide, and leptin, coupled with a substantial rise in adiponectin. Placebo groups in both populations showed minimal biomarker changes, supporting the treatment-related effects observed. Overall, these findings suggest that ABC-123 exerts stronger pharmacodynamic effects in the diseased state, highlighting its potential as a therapeutic agent for Boneitis by improving metabolic dysfunction associated with the condition | E28: Mock_CSR Key messages_with_heading.docx | F28: Write a neutral, data-driven paragraph summarizing the overall benefit-risk conclusion, referencing safety findings and justification for continued development of ABC-123. | G28: The overall benefit-risk assessment for ABC-123 is favorable for participation in this study. The prior safety experience with blorp inductors, the lack of brain penetration demonstrated in nonclinical studies, and the absence of significant adverse findings in the 13-week monkey toxicology study support the conduct of this study. The potential risks identified are justified in light of the anticipated benefits to medical and scientific knowledge, and can be minimized through appropriate monitoring and dose escalation. Based on the available data and the participant population to be studied, the benefit-risk profile supports continued development of ABC-123 at this stage. | I28: {=_xldudf_BOARDFLARE_FMATCH(G28,D28)} -> #NAME? | J28: =IF(M28>O28, M28,O28) -> #VALUE! | K28: {=IF( SUMPRODUCT(--ISNUMBER(SEARCH(_xlfn.TEXTSPLIT(D28," "), G28))) / COUNTA(_xlfn.TEXTSPLIT(D28," ")) = 1, "Full Match", IF( SUMPRODUCT(--ISNUMBER(SEARCH(_xlfn.TEXTSPLIT(D28," "), G28))) / COUNTA(_xlfn.TEXTSPLIT(D28," ")) > 0.5, "Partial Match", "No Match" ) )} -> No Match | L28: {=_xldudf_BOARDFLARE_FMATCH(G28,D28)} -> #NAME? | M28: {=_FV(L28,"Similarity",TRUE)} -> #VALUE! | N28: {=_xldudf_BOARDFLARE_FMATCH(D28,G28)} -> #NAME? | O28: {=_FV(N28,"Similarity",TRUE)} -> #VALUE! | AE28: yes | AF28: yes | AG28: =AE28=AF28 -> TRUE | AH28: {=SUMPRODUCT(--ISNUMBER(SEARCH(_xlfn.TEXTSPLIT(D28," "), G28))) / COUNTA(_xlfn.TEXTSPLIT(D28," "))} -> 0 | AI28: {=IF( SUMPRODUCT(--ISNUMBER(SEARCH(_xlfn.TEXTSPLIT(D28," "), G28))) / COUNTA(_xlfn.TEXTSPLIT(D28," ")) = 1, "Full Match", IF( SUMPRODUCT(--ISNUMBER(SEARCH(_xlfn.TEXTSPLIT(D28," "), G28))) / COUNTA(_xlfn.TEXTSPLIT(D28," ")) > 0.5, "Partial Match", "No Match" ) )} -> No Match
A29: <Table Objectives and Endpoints> | C29: Table | D29: ● To assess the safety and tolerability after 4 weeks of exposure following single ascending doses of ABC-123 ● Number of participants with serious and other nonserious AEs Secondary ● To assess the safety and tolerability following repeated doses over 4 weeks of ABC-123 ● Number of participants with serious and other nonserious AEs ● To characterize PK of ABC-123 following single ascending doses ● Cmax and AUClast ● To characterize the PK of ABC-123 following repeated doses ● Cmax and AUClast Exploratory ● To explore additional PK characteristics of ABC-123 following single ascending doses ● Tmax, Clast, Tlast, AUCinf, CL, V, and t1/2 ● To explore additional PK characteristics of ABC-123 following repeated doses ● Tmax, Clast, Tlast, AUCinf, CL, V, and t1/2 ● To explore effects of ABC-123 on clinical laboratory assessments, 12-lead ECG, and vital signs following single ascending doses ● Incidence of clinically significant changes in laboratory parameters, 12-lead ECG parameters, and vital signs measurements ● To explore effects of ABC-123 on clinical laboratory assessments, 12-lead ECG, and vital signs following repeated doses ● Incidence of clinically significant changes in laboratory parameters, 12-lead ECG parameters, and vital signs measurements ● To explore the impact of ADA on the PK profile of ABC-123 following single ascending doses ● Impact of ADA on AUC or impact on overall exposure of ABC-123 ● To explore the impact of ADA on the PK profile of ABC-123 following repeated doses ● Impact of ADA on AUC or impact on overall exposure of ABC-123 ● To explore the effects on eating behavior in participants following single ascending doses of ABC-123 ● Hunger, satiety, and appetite VAS scores Abbreviations: ADA = antidrug antibodies; AE = adverse event. | E29: Mock_CSR_Protocol.docx | F29: Insert the table(s) listing study objectives and endpoints by matching semantic caption text. | G29: Objectives/Endpoints: The following objectives and endpoints will be evaluated in healthy participants during the SAD component of the study and in participants with boneitis in the repeat-dose component of the study. Objectives Endpoints Primary To assess the safety and tolerability after 4 weeks of exposure following single ascending doses of ABC-123 Number of participants with serious and other nonserious AEs Secondary To assess the safety and tolerability following repeated doses over 4 weeks of ABC-123 Number of participants with serious and other nonserious AEs To characterize PK of ABC-123 following single ascending doses Cmax and AUClast To characterize the PK of ABC-123 following repeated doses Cmax and AUClast Exploratory To explore additional PK characteristics of ABC-123 following single ascending doses Tmax, Clast, Tlast, AUCinf, CL, V, and t1/2 To explore additional PK characteristics of ABC-123 following repeated doses Tmax, Clast, Tlast, AUCinf, CL, V, and t1/2 To explore effects of ABC-123 on clinical laboratory assessments, 12-lead ECG, and vital signs following single ascending doses Incidence of clinically significant changes in laboratory parameters, 12-lead ECG parameters, and vital signs measurements To explore effects of ABC-123 on clinical laboratory assessments, 12-lead ECG, and vital signs following repeated doses Incidence of clinically significant changes in laboratory parameters, 12-lead ECG parameters, and vital signs measurements To explore the impact of ADA on the PK profile of ABC-123 following single ascending doses Impact of ADA on AUC or impact on overall exposure of ABC-123 To explore the impact of ADA on the PK profile of ABC-123 following repeated doses Impact of ADA on AUC or impact on overall exposure of ABC-123 To explore the effects on eating behavior in participants following single ascending doses of ABC-123 Hunger, satiety, and appetite VAS scores Abbreviations: ADA = antidrug antibodies; AE = adverse event. | I29: {=_xldudf_BOARDFLARE_FMATCH(G29,D29)} -> #NAME? | J29: =IF(M29>O29, M29,O29) -> #VALUE! | K29: {=IF( SUMPRODUCT(--ISNUMBER(SEARCH(_xlfn.TEXTSPLIT(D29," "), G29))) / COUNTA(_xlfn.TEXTSPLIT(D29," ")) = 1, "Full Match", IF( SUMPRODUCT(--ISNUMBER(SEARCH(_xlfn.TEXTSPLIT(D29," "), G29))) / COUNTA(_xlfn.TEXTSPLIT(D29," ")) > 0.5, "Partial Match", "No Match" ) )} -> No Match | L29: {=_xldudf_BOARDFLARE_FMATCH(G29,D29)} -> #NAME? | M29: {=_FV(L29,"Similarity",TRUE)} -> #VALUE! | N29: {=_xldudf_BOARDFLARE_FMATCH(D29,G29)} -> #NAME? | O29: {=_FV(N29,"Similarity",TRUE)} -> #VALUE! | Q29: 16 | R29: 2 | S29: Abbreviations: ADA = antidrug antibodies; AE = adverse event. | T29: 16 | U29: 2 | V29: Abbreviations: ADA = antidrug antibodies; AE = adverse event | W29: yes | X29: {=IF( SUMPRODUCT(--ISNUMBER(SEARCH(_xlfn.TEXTSPLIT(D29," "), G29))) / COUNTA(_xlfn.TEXTSPLIT(D29," ")) = 1, "Full Match", IF( SUMPRODUCT(--ISNUMBER(SEARCH(_xlfn.TEXTSPLIT(D29," "), G29))) / COUNTA(_xlfn.TEXTSPLIT(D29," ")) > 0.5, "Partial Match", "No Match" ) )} -> No Match
A30: <Insert Study Parts> | C30: Paragraph | D30: A First-In-Human, Phase 1, Randomized, Double-Blind, Placebo-Controlled Study to Evaluate the Safety, Tolerability, and Pharmacokinetics of ABC-123 as a Single Dose in Healthy Participants and as Multiple Doses in Participants with Grade 2 Boneitis | E30: Mock_CSR_Protocol.docx | F30: Provide a concise inline summary of the study parts as specified in the protocol. | G30: the single-dose and multiple-dose parts of the study are presented in Table 3. | I30: {=_xldudf_BOARDFLARE_FMATCH(G30,D30)} -> #NAME? | J30: =IF(M30>O30, M30,O30) -> #VALUE! | K30: {=IF( SUMPRODUCT(--ISNUMBER(SEARCH(_xlfn.TEXTSPLIT(D30," "), G30))) / COUNTA(_xlfn.TEXTSPLIT(D30," ")) = 1, "Full Match", IF( SUMPRODUCT(--ISNUMBER(SEARCH(_xlfn.TEXTSPLIT(D30," "), G30))) / COUNTA(_xlfn.TEXTSPLIT(D30," ")) > 0.5, "Partial Match", "No Match" ) )} -> No Match | L30: {=_xldudf_BOARDFLARE_FMATCH(G30,D30)} -> #NAME? | M30: {=_FV(L30,"Similarity",TRUE)} -> #VALUE! | N30: {=_xldudf_BOARDFLARE_FMATCH(D30,G30)} -> #NAME? | O30: {=_FV(N30,"Similarity",TRUE)} -> #VALUE! | AE30: yes | AF30: yes | AG30: =AE30=AF30 -> TRUE | AH30: {=SUMPRODUCT(--ISNUMBER(SEARCH(_xlfn.TEXTSPLIT(D30," "), G30))) / COUNTA(_xlfn.TEXTSPLIT(D30," "))} -> 0 | AI30: {=IF( SUMPRODUCT(--ISNUMBER(SEARCH(_xlfn.TEXTSPLIT(D30," "), G30))) / COUNTA(_xlfn.TEXTSPLIT(D30," ")) = 1, "Full Match", IF( SUMPRODUCT(--ISNUMBER(SEARCH(_xlfn.TEXTSPLIT(D30," "), G30))) / COUNTA(_xlfn.TEXTSPLIT(D30," ")) > 0.5, "Partial Match", "No Match" ) )} -> No Match
A31: <Figure X> | C31: Inline | I31: {=_xldudf_BOARDFLARE_FMATCH(G31,D31)} -> #NAME? | J31: =IF(M31>O31, M31,O31) -> #VALUE! | L31: {=_xldudf_BOARDFLARE_FMATCH(G31,D31)} -> #NAME? | M31: {=_FV(L31,"Similarity",TRUE)} -> #VALUE! | N31: {=_xldudf_BOARDFLARE_FMATCH(D31,G31)} -> #NAME? | O31: {=_FV(N31,"Similarity",TRUE)} -> #VALUE! | AK31: {=IF( SUMPRODUCT(--ISNUMBER(SEARCH(_xlfn.TEXTSPLIT(D31," "), G31))) / COUNTA(_xlfn.TEXTSPLIT(D31," ")) = 1, "Full Match", IF( SUMPRODUCT(--ISNUMBER(SEARCH(_xlfn.TEXTSPLIT(D31," "), G31))) / COUNTA(_xlfn.TEXTSPLIT(D31," ")) > 0.5, "Partial Match", "No Match" ) )} -> No Match
A32: <Date of Report> | C32: Inline | D32: 46082 | F32: Insert the report date in the format DD Month YYYY for inline continuity after 'Page 1 of'. | I32: {=_xldudf_BOARDFLARE_FMATCH(G32,D32)} -> #NAME? | J32: =IF(M32>O32, M32,O32) -> #VALUE! | L32: {=_xldudf_BOARDFLARE_FMATCH(G32,D32)} -> #NAME? | M32: {=_FV(L32,"Similarity",TRUE)} -> #VALUE! | N32: {=_xldudf_BOARDFLARE_FMATCH(D32,G32)} -> #NAME? | O32: {=_FV(N32,"Similarity",TRUE)} -> #VALUE! | AK32: {=IF( SUMPRODUCT(--ISNUMBER(SEARCH(_xlfn.TEXTSPLIT(D32," "), G32))) / COUNTA(_xlfn.TEXTSPLIT(D32," ")) = 1, "Full Match", IF( SUMPRODUCT(--ISNUMBER(SEARCH(_xlfn.TEXTSPLIT(D32," "), G32))) / COUNTA(_xlfn.TEXTSPLIT(D32," ")) > 0.5, "Partial Match", "No Match" ) )} -> No Match
A33: <Table: Insert SOA Table (s): Schedule of Activities> | C33: Table | F33: Insert the Schedule of Activities tables (both Single Ascending Dose and Repeat-Dose) by referencing their existing captions. | G33: Study Procedures (Day) In-Residence Period Follow-up Period Cohorts 4+ Follow-up Period Cohorts 1-3 Screening Day 1 Day 2 Day 3 Day 4 Day 5 Day 6 Day 7 Day 8 Day 9 Day 10 Day 11 Day 15 Day 22 Day 29 Day 43 Day 57 Follow-up / ED 71 Safety and tolerability: Immunogenicity assessment (ADA) X X X X X X X X X X X X X Clinical laboratory evaluations(chemistry, hematology, and urinalysis) X X X X X X X X X X X X X X X Adverse event inquiry X X X X X X X X X X X X X X X X X X Prior/concomitant medication monitoring X X X X X X X X X X X X X X X X X X Blood pressure, pulse rate, pulseoximetry/oxygen saturation, respiratory rate X X X X X X X X X X X X X X Body temperature X X X X X X X X X X X X X X Single safety 12-lead ECG X X Triplicate 12-lead ECG X X X X X X X X X Physical examination X X X X X X X X X X X X X | I33: {=_xldudf_BOARDFLARE_FMATCH(G33,D33)} -> #NAME? | J33: =IF(M33>O33, M33,O33) -> #VALUE! | K33: {=IF( SUMPRODUCT(--ISNUMBER(SEARCH(_xlfn.TEXTSPLIT(D33," "), G33))) / COUNTA(_xlfn.TEXTSPLIT(D33," ")) = 1, "Full Match", IF( SUMPRODUCT(--ISNUMBER(SEARCH(_xlfn.TEXTSPLIT(D33," "), G33))) / COUNTA(_xlfn.TEXTSPLIT(D33," ")) > 0.5, "Partial Match", "No Match" ) )} -> No Match | L33: {=_xldudf_BOARDFLARE_FMATCH(G33,D33)} -> #NAME? | M33: {=_FV(L33,"Similarity",TRUE)} -> #VALUE! | N33: {=_xldudf_BOARDFLARE_FMATCH(D33,G33)} -> #NAME? | O33: {=_FV(N33,"Similarity",TRUE)} -> #VALUE! | Q33: NA | R33: NA | S33: NA | T33: 13 | U33: 31 | V33: NA | W33: no | X33: {=IF( SUMPRODUCT(--ISNUMBER(SEARCH(_xlfn.TEXTSPLIT(D33," "), G33))) / COUNTA(_xlfn.TEXTSPLIT(D33," ")) = 1, "Full Match", IF( SUMPRODUCT(--ISNUMBER(SEARCH(_xlfn.TEXTSPLIT(D33," "), G33))) / COUNTA(_xlfn.TEXTSPLIT(D33," ")) > 0.5, "Partial Match", "No Match" ) )} -> No Match
A34: <Study Design Justification> | C34: Paragraph | D34: This study will comprise a SAD escalation component in healthy volunteer participants and a repeat-dose component to confirm repeat-dose safety, tolerability, PK, and immunogenicity in participants with boneitis. It will also explore potential blorp activity, participant selection, PD, and differential response biomarkers. This study will be conducted in a single Phase 1 unit. | E34: Mock_CSR Key messages_with_heading.docx | F34: Summarize the justification for the study design, including its methodological rationale and objectives. | I34: {=_xldudf_BOARDFLARE_FMATCH(G34,D34)} -> #NAME? | J34: =IF(M34>O34, M34,O34) -> #VALUE! | K34: {=IF( SUMPRODUCT(--ISNUMBER(SEARCH(_xlfn.TEXTSPLIT(D34," "), G34))) / COUNTA(_xlfn.TEXTSPLIT(D34," ")) = 1, "Full Match", IF( SUMPRODUCT(--ISNUMBER(SEARCH(_xlfn.TEXTSPLIT(D34," "), G34))) / COUNTA(_xlfn.TEXTSPLIT(D34," ")) > 0.5, "Partial Match", "No Match" ) )} -> No Match | L34: {=_xldudf_BOARDFLARE_FMATCH(G34,D34)} -> #NAME? | M34: {=_FV(L34,"Similarity",TRUE)} -> #VALUE! | N34: {=_xldudf_BOARDFLARE_FMATCH(D34,G34)} -> #NAME? | O34: {=_FV(N34,"Similarity",TRUE)} -> #VALUE! | AE34: yes | AF34: NA | AG34: =AE34=AF34 -> FALSE | AH34: {=SUMPRODUCT(--ISNUMBER(SEARCH(_xlfn.TEXTSPLIT(D34," "), G34))) / COUNTA(_xlfn.TEXTSPLIT(D34," "))} -> 0 | AI34: {=IF( SUMPRODUCT(--ISNUMBER(SEARCH(_xlfn.TEXTSPLIT(D34," "), G34))) / COUNTA(_xlfn.TEXTSPLIT(D34," ")) = 1, "Full Match", IF( SUMPRODUCT(--ISNUMBER(SEARCH(_xlfn.TEXTSPLIT(D34," "), G34))) / COUNTA(_xlfn.TEXTSPLIT(D34," ")) > 0.5, "Partial Match", "No Match" ) )} -> No Match
A35: <Dose Justification> | C35: Paragraph | D35: The planned clinical starting dose in healthy volunteers (HVs) is a single dose of 5 mg of ABC-123 administered as an SC injection. The planned maximum dose is 600 mg. The clinical starting dose is based on an integrated approach supported by the Good Laboratory Practice (GLP) toxicology study approach, the minimal cytokine change, expected 10% receptor occupancy (RO) attained at maximum observed serum concentration (Cmax), and utilizing the minimal anticipated biological effect level (MABEL) based on the half-maximal inhibitory concentration (IC50) of ABC-123 on binding and inhibition of blorp induction. The 13-week GLP toxicology study was conducted in cynomolgus monkey, as this is the most relevant species for evaluation based on in vitro cross-reactivity (study SKY-123_Nonclin_456). The no observed adverse effect level (NOAEL) in this study was 300 mg/kg. In addition, there is a 1.13-fold difference in binding of ABC-123 in monkey to human blorp; therefore, the human equivalent dose of the NOAEL is 265.5 mg/kg. Based on the maximum recommended starting dose (MRSD) guidance, a factor of 10 can be used to determine the maximum allowable starting dose, with an estimated maximum starting dose of 26.5 mg/kg of ABC-123. The planned starting dose of 5 mg given as a single SC injection in HVs is expected to be 318-fold lower than the dose supported by the GLP toxicology study. Starting at the dose of 5 mg will ensure full characterization of safety, PK, and PD of ABC-123. | E35: Mock_CSR_Protocol.docx | F35: Summarize the rationale and supporting data for the clinical starting dose of ABC-123, including toxicology study results, safety factors, and dosing calculations. | G35: The clinical starting dose of ABC-123 in healthy volunteers is 5 mg administered as a single subcutaneous injection, with a planned maximum dose of 600 mg. This starting dose was determined using an integrated approach, including GLP toxicology studies, minimal cytokine changes, and anticipated biological effect levels. The 13-week GLP toxicology study in cynomolgus monkeys identified a NOAEL of 300 mg/kg, and after accounting for species differences, the human equivalent dose is 265.5 mg/kg. Applying a safety factor of 10, the estimated maximum recommended starting dose is 26.5 mg/kg. The selected 5 mg dose is 318-fold lower than the dose supported by toxicology data, ensuring a conservative approach for safety, pharmacokinetic, and pharmacodynamic assessment | I35: {=_xldudf_BOARDFLARE_FMATCH(G35,D35)} -> #NAME? | J35: =IF(M35>O35, M35,O35) -> #VALUE! | K35: {=IF( SUMPRODUCT(--ISNUMBER(SEARCH(_xlfn.TEXTSPLIT(D35," "), G35))) / COUNTA(_xlfn.TEXTSPLIT(D35," ")) = 1, "Full Match", IF( SUMPRODUCT(--ISNUMBER(SEARCH(_xlfn.TEXTSPLIT(D35," "), G35))) / COUNTA(_xlfn.TEXTSPLIT(D35," ")) > 0.5, "Partial Match", "No Match" ) )} -> No Match | L35: {=_xldudf_BOARDFLARE_FMATCH(G35,D35)} -> #NAME? | M35: {=_FV(L35,"Similarity",TRUE)} -> #VALUE! | N35: {=_xldudf_BOARDFLARE_FMATCH(D35,G35)} -> #NAME? | O35: {=_FV(N35,"Similarity",TRUE)} -> #VALUE! | AE35: yes | AF35: yes | AG35: =AE35=AF35 -> TRUE | AH35: {=SUMPRODUCT(--ISNUMBER(SEARCH(_xlfn.TEXTSPLIT(D35," "), G35))) / COUNTA(_xlfn.TEXTSPLIT(D35," "))} -> 0 | AI35: {=IF( SUMPRODUCT(--ISNUMBER(SEARCH(_xlfn.TEXTSPLIT(D35," "), G35))) / COUNTA(_xlfn.TEXTSPLIT(D35," ")) = 1, "Full Match", IF( SUMPRODUCT(--ISNUMBER(SEARCH(_xlfn.TEXTSPLIT(D35," "), G35))) / COUNTA(_xlfn.TEXTSPLIT(D35," ")) > 0.5, "Partial Match", "No Match" ) )} -> No Match
A36: <Number list of inclusion criteria> | C36: List | D36: 1. Understands study procedures and voluntarily provides written informed consent. 2. Willing and able to abide by the study restrictions, including the lifestyle considerations in Section 5.3. 3. Willing and able to complete all study visits, in-residence requirements, and procedures. 4. 18 to 65 years of age at the time of signing informed consent. 5. Body mass index (BMI) between 18.0 and 35.0 kg/m2, inclusive, at Screening. 6. Female participants will be of non-childbearing potential (refer to Section 10.5 [Appendix 5] for definition of non-childbearing potential). 7. Male participants will agree to use contraception while on study intervention and for at least 6 months after the last dose of study intervention. 8. SAD cohorts only: Participants must be in good health, determined by no clinically significant findings from medical history, physical examination, 12-lead ECG, vital signs measurements, and clinical laboratory evaluations (see exclusion criteria for criteria for specific labs) at Screening as assessed by the Investigator. Clinical laboratory assessments may be repeated once at the Investigator’s discretion if laboratory error is suspected. 9. Repeat-dose cohort only: boneitis treated with Zammoxin or myrnestristoate and in otherwise good health except for well-controlled common conditions associated with boneitis, such as acid sweat or tonsillar invisibility. Clinical laboratory assessments may be repeated once at the Investigator’s discretion if laboratory error is suspected | F36: Write a numbered list of inclusion criteria for study participant eligibility, using protocol language. | G36: Understands study procedures and voluntarily provides written informed consent. Willing and able to abide by the study restrictions, including the lifestyle considerations in the protocol. Willing and able to complete all study visits, in-residence requirements, and procedures. 18 to 65 years of age at the time of signing informed consent. Body mass index (BMI) between 18.0 and 35.0 kg/m2, inclusive, at Screening. Female participants will be of non-childbearing potential (refer to protocol for definition). Male participants will agree to use contraception while on study intervention and for at least 6 months after the last dose of study intervention. SAD cohorts only: Participants must be in good health, determined by no clinically significant findings from medical history, physical examination, 12-lead ECG, vital signs measurements, and clinical laboratory evaluations at Screening as assessed by the Investigator. Clinical laboratory assessments may be repeated once at the Investigator’s discretion if laboratory error is suspected. Repeat-dose cohort only: boneitis treated with Zammoxin or myrnestristoate and in otherwise good health except for well-controlled conditions as specified in the protocol. | I36: {=_xldudf_BOARDFLARE_FMATCH(G36,D36)} -> #NAME? | J36: =IF(M36>O36, M36,O36) -> #VALUE! | K36: {=IF( SUMPRODUCT(--ISNUMBER(SEARCH(_xlfn.TEXTSPLIT(D36," "), G36))) / COUNTA(_xlfn.TEXTSPLIT(D36," ")) = 1, "Full Match", IF( SUMPRODUCT(--ISNUMBER(SEARCH(_xlfn.TEXTSPLIT(D36," "), G36))) / COUNTA(_xlfn.TEXTSPLIT(D36," ")) > 0.5, "Partial Match", "No Match" ) )} -> No Match | L36: {=_xldudf_BOARDFLARE_FMATCH(G36,D36)} -> #NAME? | M36: {=_FV(L36,"Similarity",TRUE)} -> #VALUE! | N36: {=_xldudf_BOARDFLARE_FMATCH(D36,G36)} -> #NAME? | O36: {=_FV(N36,"Similarity",TRUE)} -> #VALUE! | Z36: 9 | AA36: 9 | AB36: Yes | AC36: =IF(EXACT(Table11[[#This Row],[Expected Value]],Table11[[#This Row],[AI Replaced Text]]),"Match","Not Match") -> Not Match
