Workbook
Name AnnualCostOfTime_BuyCar: #REF!
Name AnnualCostOfTime_Ridesharing: #REF!
Name AnnualFareCost: #REF!
Name AnnualFuelCost: #REF!
Name AnnualPurchaseCost: #REF!
Name AnnualUsageCost: #REF!
Name AveDistancePerTrip: Summary!$D$24
Name AveParkingTime: #REF!
Name AverageTripsPerDay: Summary!$D$19
Name AveSurgeMultiplier: #REF!
Name AveTimePerTrip: Summary!$D$20
Name AveWaitTime: #REF!
Name BaseFare: #REF!
Name DistanceFare: #REF!
Name DownPayment: #REF!
Name FuelCost: #REF!
Name FuelEfficiency: #REF!
Name GarageExpenses: #REF!
Name GaragePropertyTax: #REF!
Name Insurance: #REF!
Name InterestRate: #REF!
Name LoanTerm: #REF!
Name MaintenanceAndRepairs: #REF!
Name Parking: #REF!
Name PercentRideDuringSurge: #REF!
Name PriceOfCar: #REF!
Name ProductivePercent: #REF!
Name PurchaseFees: #REF!
Name RatePerHour: Summary!$D$65
Name RegistrationAndTaxes: #REF!
Name SalesTax: #REF!
Name TimeFare: #REF!
Name TotalMileage: Summary!#REF!

Sheet Summary
B2: ICF FULL Report version2
C4: Report ID | D4: ICF_Full_16/04/2026 | G4: Generated doc
C5: AW version | D5: Sandbox | G5: Clean Ver
C6: Generated By | D6: Paras | G6: Date | J6: 46120
G7: No. of Pages
C8: Remarks | G8: Generation Time
C11: Destination Template | E11: .docx - 2 pages
C12: Source Documents | D12: Protocol Example (28Sep2023) 1
C13: Doc Type | D13: .docx | E13: .docx | G13: .rtf
C14: No. of Pages
B16: Placeholder Analysis | G16: Accuracy Analysis
B17: Column1 | C17: Column2 | D17: Column3 | E17: Column4
D18: Count | E18: Replaced
C19: Total Placeholders Identified | D19: =COUNTA(QA!A3:'QA'!A150) -> 124 | E19: =COUNTA(QA!G3:'QA'!G148) -> 83
C20: Unique Placeholders | D20: =COUNTA(_xlfn.UNIQUE(QA!A3:'QA'!A149)) -> 70 | E20: =COUNTA(_xlfn.UNIQUE(QA!G3:'QA'!G149)) -> 58
C21: Paragraph Placeholders | D21: =COUNTIF(QA!C3:'QA'!C149, "=Paragraph") -> 45 | E21: =COUNTA(QA!G83:G124) -> 28
C22: KeyValue Placeholders | D22: =COUNTA(KeyValue!A3:A48) -> 46 | E22: =COUNTA(KeyValue!M3:M48) -> 24
C23: List Placeholders | D23: =COUNTIF(QA!C3:'QA'!C149, "=List") -> 20 | E23: =COUNTA(Lists!G3:G22) -> 15
C24: Table Placeholders | D24: =COUNTIF(QA!C3:'QA'!C149, "=Table") -> 6 | E24: =COUNTA(Table!G3:G8) -> 6
C25: Multi Tables Placeholders | D25: =COUNTIF(QA!C3:'QA'!C49, "=MultiTable") -> 0 | E25: 0
C26: Figure Placeholders | D26: =COUNTIF(QA!C3:'QA'!C49, "=Figure") -> 0 | E26: 0
B28: List placeholders
B29: Column1 | C29: Column2 | D29: Column3 | E29: Column4
C30: Total List placeholders | D30: =COUNTA(Lists!A3:A39) -> 17 | E30: QA/Debugging ↓ | G30: Remarks
C31: List Replaced | D31: =COUNTA(Lists!G9:G22) -> 10 | E31: =D31/D30 -> 0.58823529
C32: List Replaced correctly | D32: =COUNTIF(QA!AH56:AH123, "Partial Match") -> 4 | E32: =D32*100%/D31 -> 0.4
C33: List Formatted correctly | D33: =D32 -> 4 | E33: =D33*100%/D32 -> 1
B35: Paragraph placeholders
B36: Column1 | C36: Column2 | D36: Column3 | E36: Column4
C37: Total paragraph placeholders | D37: =COUNTA(Paragraph!A3:'Paragraph'!A500) -> 45 | E37: QA/Debugging ↓ | G37: Remarks
C38: Paragraphs Replaced | D38: =COUNTA(Paragraph!G3:'Paragraph'!G500) -> 45 | E38: =Table685[[#This Row],[Column3]]/D37 -> 1
C39: Paragraphs Replaced correctly | D39: =COUNTIF(QA!AM4:AM124,"Partial Match") -> 4 | E39: =Table685[[#This Row],[Column3]]/D38 -> 0.088888889
C40: Paragraphs Formatted correctly | D40: =D39 -> 4 | E40: =Table685[[#This Row],[Column3]]/D39 -> 1
B42: KeyValue placeholders
B43: Column1 | C43: Column2 | D43: Column3 | E43: Column4
C44: Total KeyValues placeholders | D44: =COUNTA(KeyValue!A3:A48) -> 46 | E44: QA/Debugging ↓ | G44: Remarks
C45: KeyValues Replaced | D45: =COUNTA(KeyValue!G3:G48) -> 46 | E45: =Table687[[#This Row],[Column3]]/D44 -> 1
C46: KeyValues Replaced correctly | D46: =COUNTIF(QA!AP3:AP108, "Match") -> 19 | E46: =Table687[[#This Row],[Column3]]/D45 -> 0.41304348
C47: keyValues Formatted correctly | D47: =D46 -> 19 | E47: =Table687[[#This Row],[Column3]]/D46 -> 1
B49: Table placeholders
...

Sheet QA
R1: Table | AD1: List | AI1: Paragraph | AO1: KeyValue
A2: Placeholder | B2: Column1 | C2: Placeholder Type | D2: Expected Value | E2: Source Document | F2: Writing instruction | G2: AI Replaced Text | H2: Ai detected Source | I2: Matching Accuracy | J2: Similarity Score | K2: Source Match | R2: Expected Rows | S2: Expected Colunms | T2: Expected Footnote | U2: AI replaced Rows | V2: AI replaced Colunms | W2: AI replaced Footnotes | X2: Alignment(yes/no) | Y2: Similarity Score | Z2: Status | AD2: Number of point | AE2: AI Number of point | AF2: Point matching(yes/no) | AG2: Status(human) | AI2: Header Availablity | AJ2: AI Header Availablity | AK2: Par Similarity Score | AL2: Per of Match | AM2: Status | AO2: Similarity Score | AP2: Status
A3: <Sponsor> | C3: KeyValue | D3: Stendarr, Inc. | E3: Protocol Example (28Sep2023) 1 | F3: Insert the sponsor's name in line with the protocol header formatting. | G3: Stendarr, Inc. | I3: {=_xldudf_BOARDFLARE_FMATCH(D3,G3)} -> #VALUE! | J3: =IF(M3>O3, M3,O3) -> 0.99 | L3: {=_xldudf_BOARDFLARE_FMATCH(G3,D3)} -> #VALUE! | M3: {=_FV(L3,"Similarity",TRUE)} -> 0.99 | N3: {=_xldudf_BOARDFLARE_FMATCH(D3,G3)} -> #VALUE! | O3: {=_FV(N3,"Similarity",TRUE)} -> 0.85 | AO3: {=MAX( SUMPRODUCT(--ISNUMBER(MATCH(_xlfn.TEXTSPLIT(LOWER(D3)," "), _xlfn.TEXTSPLIT(LOWER(G3)," "),0))) / COUNTA(_xlfn.TEXTSPLIT(D3," ")), SUMPRODUCT(--ISNUMBER(SEARCH(LEFT(_xlfn.TEXTSPLIT(LOWER(D3)," "),LEN(_xlfn.TEXTSPLIT(LOWER(D3)," "))-1), LOWER(G3)))) / COUNTA(_xlfn.TEXTSPLIT(D3," ")) )} -> 1 | AP3: =IF(AO3>=0.8,"Match","No Match") -> Match
A4: <Full protocol title> | C4: Paragraph | D4: A First-In-Human, Phase 1, Randomized, Double-Blind, Placebo-Controlled Study to Evaluate the Safety, Tolerability, and Pharmacokinetics of ABC-123 as a Single Dose in Healthy Participants and as Multiple Doses in Participants with Grade 2 Boneitis | E4: Protocol Example (28Sep2023) 1 | F4: Insert the full protocol title verbatim, maintaining inline continuity. | G4: A First-In-Human, Phase 1, Randomized, Double-Blind, Placebo-Controlled Study to Evaluate the Safety, Tolerability, and Pharmacokinetics of ABC-123 as a Single Dose in Healthy Participants and as Multiple Doses in Participants with Grade 2 Boneitis | I4: {=_xldudf_BOARDFLARE_FMATCH(D4,G4)} -> #VALUE! | J4: =IF(M4>O4, M4,O4) -> 0.61 | L4: {=_xldudf_BOARDFLARE_FMATCH(G4,D4)} -> #VALUE! | M4: {=_FV(L4,"Similarity",TRUE)} -> 0.61 | N4: {=_xldudf_BOARDFLARE_FMATCH(D4,G4)} -> #VALUE! | O4: {=_FV(N4,"Similarity",TRUE)} -> 0.6 | AI4: yes | AJ4: yes | AK4: {=SUMPRODUCT(--ISNUMBER(SEARCH(_xlfn.TEXTSPLIT(D4," "), G4))) / COUNTA(_xlfn.TEXTSPLIT(D4," "))} -> 0.96969697 | AL4: =AK4*100 -> 96.969697 | AM4: {=IF( SUMPRODUCT(--ISNUMBER(SEARCH(_xlfn.TEXTSPLIT(D4," "), G4))) / COUNTA(_xlfn.TEXTSPLIT(D4," ")) = 1, "Full Match", IF( SUMPRODUCT(--ISNUMBER(SEARCH(_xlfn.TEXTSPLIT(D4," "), G4))) / COUNTA(_xlfn.TEXTSPLIT(D4," ")) > 0.5, "Partial Match", "No Match" ) )} -> Partial Match
A5: <Protocol Number> | C5: KeyValue | D5: SKY-2000-101 | E5: Protocol Example (28Sep2023) 1 | F5: Insert the official protocol number in the format used in the source document. | G5: SKY-2000-101 | I5: {=_xldudf_BOARDFLARE_FMATCH(D5,G5)} -> #VALUE! | J5: =IF(M5>O5, M5,O5) -> 1 | L5: {=_xldudf_BOARDFLARE_FMATCH(G5,D5)} -> #VALUE! | M5: {=_FV(L5,"Similarity",TRUE)} -> 1 | N5: {=_xldudf_BOARDFLARE_FMATCH(D5,G5)} -> #VALUE! | O5: {=_FV(N5,"Similarity",TRUE)} -> 0.92 | AO5: {=MAX( SUMPRODUCT(--ISNUMBER(MATCH(_xlfn.TEXTSPLIT(LOWER(D5)," "), _xlfn.TEXTSPLIT(LOWER(G5)," "),0))) / COUNTA(_xlfn.TEXTSPLIT(D5," ")), SUMPRODUCT(--ISNUMBER(SEARCH(LEFT(_xlfn.TEXTSPLIT(LOWER(D5)," "),LEN(_xlfn.TEXTSPLIT(LOWER(D5)," "))-1), LOWER(G5)))) / COUNTA(_xlfn.TEXTSPLIT(D5," ")) )} -> 1 | AP5: =IF(AO5>=0.8,"Match","No Match") -> Match
A6: <Principal Investigator Name> | C6: KeyValue | D6: Karliah N. Gale, MD​profe​ | E6: Protocol Example (28Sep2023) 1 | I6: {=_xldudf_BOARDFLARE_FMATCH(D6,G6)} -> #VALUE! | J6: =IF(M6>O6, M6,O6) -> 0 | L6: {=_xldudf_BOARDFLARE_FMATCH(G6,D6)} -> #VALUE! | M6: {=_FV(L6,"Similarity",TRUE)} -> 0 | N6: {=_xldudf_BOARDFLARE_FMATCH(D6,G6)} -> #VALUE! | O6: {=_FV(N6,"Similarity",TRUE)} -> 0 | AO6: {=MAX( SUMPRODUCT(--ISNUMBER(MATCH(_xlfn.TEXTSPLIT(LOWER(D6)," "), _xlfn.TEXTSPLIT(LOWER(G6)," "),0))) / COUNTA(_xlfn.TEXTSPLIT(D6," ")), SUMPRODUCT(--ISNUMBER(SEARCH(LEFT(_xlfn.TEXTSPLIT(LOWER(D6)," "),LEN(_xlfn.TEXTSPLIT(LOWER(D6)," "))-1), LOWER(G6)))) / COUNTA(_xlfn.TEXTSPLIT(D6," ")) )} -> 0 | AP6: =IF(AO6>=0.8,"Match","No Match") -> No Match
A7: <Telephone> | C7: KeyValue | D7: 555-999-1111 | E7: Protocol Example (28Sep2023) 1 | F7: Insert the Principal Investigator's telephone number in standard format after 'Telephone:'. | I7: {=_xldudf_BOARDFLARE_FMATCH(D7,G7)} -> #VALUE! | J7: =IF(M7>O7, M7,O7) -> 0 | L7: {=_xldudf_BOARDFLARE_FMATCH(G7,D7)} -> #VALUE! | M7: {=_FV(L7,"Similarity",TRUE)} -> 0 | N7: {=_xldudf_BOARDFLARE_FMATCH(D7,G7)} -> #VALUE! | O7: {=_FV(N7,"Similarity",TRUE)} -> 0 | AO7: {=MAX( SUMPRODUCT(--ISNUMBER(MATCH(_xlfn.TEXTSPLIT(LOWER(D7)," "), _xlfn.TEXTSPLIT(LOWER(G7)," "),0))) / COUNTA(_xlfn.TEXTSPLIT(D7," ")), SUMPRODUCT(--ISNUMBER(SEARCH(LEFT(_xlfn.TEXTSPLIT(LOWER(D7)," "),LEN(_xlfn.TEXTSPLIT(LOWER(D7)," "))-1), LOWER(G7)))) / COUNTA(_xlfn.TEXTSPLIT(D7," ")) )} -> 0 | AP7: =IF(AO7>=0.8,"Match","No Match") -> No Match
A8: <Address> | C8: KeyValue | D8: 123 Fake Street, Anytown, CO, USA 80002 | E8: Protocol Example (28Sep2023) 1 | F8: Insert the registered address in standard mailing format, maintaining inline continuity. | G8: 123 Fake Street, Anytown, CO, USA 80002 | I8: {=_xldudf_BOARDFLARE_FMATCH(D8,G8)} -> #VALUE! | J8: =IF(M8>O8, M8,O8) -> 0.93 | L8: {=_xldudf_BOARDFLARE_FMATCH(G8,D8)} -> #VALUE! | M8: {=_FV(L8,"Similarity",TRUE)} -> 0.93 | N8: {=_xldudf_BOARDFLARE_FMATCH(D8,G8)} -> #VALUE! | O8: {=_FV(N8,"Similarity",TRUE)} -> 0.79 | AO8: {=MAX( SUMPRODUCT(--ISNUMBER(MATCH(_xlfn.TEXTSPLIT(LOWER(D8)," "), _xlfn.TEXTSPLIT(LOWER(G8)," "),0))) / COUNTA(_xlfn.TEXTSPLIT(D8," ")), SUMPRODUCT(--ISNUMBER(SEARCH(LEFT(_xlfn.TEXTSPLIT(LOWER(D8)," "),LEN(_xlfn.TEXTSPLIT(LOWER(D8)," "))-1), LOWER(G8)))) / COUNTA(_xlfn.TEXTSPLIT(D8," ")) )} -> 0.85714286 | AP8: =IF(AO8>=0.8,"Match","No Match") -> Match
A9: <Sponsor Name> | C9: KeyValue | D9: Stendarr, Inc. | E9: Protocol Example (28Sep2023) 1 | F9: Insert the official sponsor name in line with protocol header formatting. | G9: Stendarr, Inc. | I9: {=_xldudf_BOARDFLARE_FMATCH(D9,G9)} -> #VALUE! | J9: =IF(M9>O9, M9,O9) -> 0.99 | L9: {=_xldudf_BOARDFLARE_FMATCH(G9,D9)} -> #VALUE! | M9: {=_FV(L9,"Similarity",TRUE)} -> 0.99 | N9: {=_xldudf_BOARDFLARE_FMATCH(D9,G9)} -> #VALUE! | O9: {=_FV(N9,"Similarity",TRUE)} -> 0.85 | AO9: {=MAX( SUMPRODUCT(--ISNUMBER(MATCH(_xlfn.TEXTSPLIT(LOWER(D9)," "), _xlfn.TEXTSPLIT(LOWER(G9)," "),0))) / COUNTA(_xlfn.TEXTSPLIT(D9," ")), SUMPRODUCT(--ISNUMBER(SEARCH(LEFT(_xlfn.TEXTSPLIT(LOWER(D9)," "),LEN(_xlfn.TEXTSPLIT(LOWER(D9)," "))-1), LOWER(G9)))) / COUNTA(_xlfn.TEXTSPLIT(D9," ")) )} -> 1 | AP9: =IF(AO9>=0.8,"Match","No Match") -> Match
A10: <Protocol Number> | C10: KeyValue | D10: SKY-2000-101 | E10: Protocol Example (28Sep2023) 1 | F10: Insert the official protocol number in the format used in the source document. | G10: SKY-2000-101 | I10: {=_xldudf_BOARDFLARE_FMATCH(D10,G10)} -> #VALUE! | J10: =IF(M10>O10, M10,O10) -> 1 | L10: {=_xldudf_BOARDFLARE_FMATCH(G10,D10)} -> #VALUE! | M10: {=_FV(L10,"Similarity",TRUE)} -> 1 | N10: {=_xldudf_BOARDFLARE_FMATCH(D10,G10)} -> #VALUE! | O10: {=_FV(N10,"Similarity",TRUE)} -> 0.92 | AO10: {=MAX( SUMPRODUCT(--ISNUMBER(MATCH(_xlfn.TEXTSPLIT(LOWER(D10)," "), _xlfn.TEXTSPLIT(LOWER(G10)," "),0))) / COUNTA(_xlfn.TEXTSPLIT(D10," ")), SUMPRODUCT(--ISNUMBER(SEARCH(LEFT(_xlfn.TEXTSPLIT(LOWER(D10)," "),LEN(_xlfn.TEXTSPLIT(LOWER(D10)," "))-1), LOWER(G10)))) / COUNTA(_xlfn.TEXTSPLIT(D10," ")) )} -> 1 | AP10: =IF(AO10>=0.8,"Match","No Match") -> Match
A11: <Principal Investigator Name> | C11: KeyValue | D11: Karliah N. Gale, MD​profe​ | E11: Protocol Example (28Sep2023) 1 | I11: {=_xldudf_BOARDFLARE_FMATCH(D11,G11)} -> #VALUE! | J11: =IF(M11>O11, M11,O11) -> 0 | L11: {=_xldudf_BOARDFLARE_FMATCH(G11,D11)} -> #VALUE! | M11: {=_FV(L11,"Similarity",TRUE)} -> 0 | N11: {=_xldudf_BOARDFLARE_FMATCH(D11,G11)} -> #VALUE! | O11: {=_FV(N11,"Similarity",TRUE)} -> 0 | AO11: {=MAX( SUMPRODUCT(--ISNUMBER(MATCH(_xlfn.TEXTSPLIT(LOWER(D11)," "), _xlfn.TEXTSPLIT(LOWER(G11)," "),0))) / COUNTA(_xlfn.TEXTSPLIT(D11," ")), SUMPRODUCT(--ISNUMBER(SEARCH(LEFT(_xlfn.TEXTSPLIT(LOWER(D11)," "),LEN(_xlfn.TEXTSPLIT(LOWER(D11)," "))-1), LOWER(G11)))) / COUNTA(_xlfn.TEXTSPLIT(D11," ")) )} -> 0 | AP11: =IF(AO11>=0.8,"Match","No Match") -> No Match
A12: <IRB Company Name> | C12: KeyValue | D12: Stendarr, Inc. | E12: Protocol Example (28Sep2023) 1 | F12: Insert the IRB company name in a concise, inline format. | G12: Stendarr, Inc. | I12: {=_xldudf_BOARDFLARE_FMATCH(D12,G12)} -> #VALUE! | J12: =IF(M12>O12, M12,O12) -> 0.99 | L12: {=_xldudf_BOARDFLARE_FMATCH(G12,D12)} -> #VALUE! | M12: {=_FV(L12,"Similarity",TRUE)} -> 0.99 | N12: {=_xldudf_BOARDFLARE_FMATCH(D12,G12)} -> #VALUE! | O12: {=_FV(N12,"Similarity",TRUE)} -> 0.85 | AO12: {=MAX( SUMPRODUCT(--ISNUMBER(MATCH(_xlfn.TEXTSPLIT(LOWER(D12)," "), _xlfn.TEXTSPLIT(LOWER(G12)," "),0))) / COUNTA(_xlfn.TEXTSPLIT(D12," ")), SUMPRODUCT(--ISNUMBER(SEARCH(LEFT(_xlfn.TEXTSPLIT(LOWER(D12)," "),LEN(_xlfn.TEXTSPLIT(LOWER(D12)," "))-1), LOWER(G12)))) / COUNTA(_xlfn.TEXTSPLIT(D12," ")) )} -> 1 | AP12: =IF(AO12>=0.8,"Match","No Match") -> Match
A13: <disease> | C13: KeyValue | D13: Boneitis | E13: Protocol Example (28Sep2023) 1 | I13: {=_xldudf_BOARDFLARE_FMATCH(D13,G13)} -> #VALUE! | J13: =IF(M13>O13, M13,O13) -> 0 | L13: {=_xldudf_BOARDFLARE_FMATCH(G13,D13)} -> #VALUE! | M13: {=_FV(L13,"Similarity",TRUE)} -> 0 | N13: {=_xldudf_BOARDFLARE_FMATCH(D13,G13)} -> #VALUE! | O13: {=_FV(N13,"Similarity",TRUE)} -> 0 | AO13: {=MAX( SUMPRODUCT(--ISNUMBER(MATCH(_xlfn.TEXTSPLIT(LOWER(D13)," "), _xlfn.TEXTSPLIT(LOWER(G13)," "),0))) / COUNTA(_xlfn.TEXTSPLIT(D13," ")), SUMPRODUCT(--ISNUMBER(SEARCH(LEFT(_xlfn.TEXTSPLIT(LOWER(D13)," "),LEN(_xlfn.TEXTSPLIT(LOWER(D13)," "))-1), LOWER(G13)))) / COUNTA(_xlfn.TEXTSPLIT(D13," ")) )} -> 0 | AP13: =IF(AO13>=0.8,"Match","No Match") -> No Match
A14: <brief lay description of disease> | C14: Paragraph | D14: ABC-123 is intended for use in patients with boneitis, a disease that causes bones to change shape or disappear. | E14: Protocol Example (28Sep2023) 1 | F14: Provide a brief, clear lay description of boneitis to fit seamlessly within the sentence. | G14: a disease that causes bones to change shape or disappear | I14: {=_xldudf_BOARDFLARE_FMATCH(D14,G14)} -> #VALUE! | J14: =IF(M14>O14, M14,O14) -> 0.79 | L14: {=_xldudf_BOARDFLARE_FMATCH(G14,D14)} -> #VALUE! | M14: {=_FV(L14,"Similarity",TRUE)} -> 0.79 | N14: {=_xldudf_BOARDFLARE_FMATCH(D14,G14)} -> #VALUE! | O14: {=_FV(N14,"Similarity",TRUE)} -> 0 | AI14: yes | AJ14: yes | AK14: {=SUMPRODUCT(--ISNUMBER(SEARCH(_xlfn.TEXTSPLIT(D14," "), G14))) / COUNTA(_xlfn.TEXTSPLIT(D14," "))} -> 0.57894737 | AL14: =AK14*100 -> 57.894737 | AM14: {=IF( SUMPRODUCT(--ISNUMBER(SEARCH(_xlfn.TEXTSPLIT(D14," "), G14))) / COUNTA(_xlfn.TEXTSPLIT(D14," ")) = 1, "Full Match", IF( SUMPRODUCT(--ISNUMBER(SEARCH(_xlfn.TEXTSPLIT(D14," "), G14))) / COUNTA(_xlfn.TEXTSPLIT(D14," ")) > 0.5, "Partial Match", "No Match" ) )} -> Partial Match
A15: <type of study (eg, first-in-human, Phase 1, Phase 2)> | C15: Paragraph | D15: The SAD portion of this study is a standard design for first-in-human testing with a monoclonal antibody. In addition, a 4-week repeated dose cohort will allow confirmation of the safety, tolerability, and repeat-dose PK and immunogenicity in the target population prior to proceeding to subsequent repeat-dose studies in a patient population. | E15: Protocol Example (28Sep2023) 1 | F15: Provide the study type in concise, inline format (e.g., first-in-human, Phase 1) to maintain paragraph continuity. | G15: first-in-human, Phase 1 | I15: {=_xldudf_BOARDFLARE_FMATCH(D15,G15)} -> #VALUE! | J15: =IF(M15>O15, M15,O15) -> 0 | L15: {=_xldudf_BOARDFLARE_FMATCH(G15,D15)} -> #VALUE! | M15: {=_FV(L15,"Similarity",TRUE)} -> 0 | N15: {=_xldudf_BOARDFLARE_FMATCH(D15,G15)} -> #VALUE! | O15: {=_FV(N15,"Similarity",TRUE)} -> 0 | AI15: yes | AJ15: no | AK15: {=SUMPRODUCT(--ISNUMBER(SEARCH(_xlfn.TEXTSPLIT(D15," "), G15))) / COUNTA(_xlfn.TEXTSPLIT(D15," "))} -> 0.1627907 | AL15: =AK15*100 -> 16.27907 | AM15: {=IF( SUMPRODUCT(--ISNUMBER(SEARCH(_xlfn.TEXTSPLIT(D15," "), G15))) / COUNTA(_xlfn.TEXTSPLIT(D15," ")) = 1, "Full Match", IF( SUMPRODUCT(--ISNUMBER(SEARCH(_xlfn.TEXTSPLIT(D15," "), G15))) / COUNTA(_xlfn.TEXTSPLIT(D15," ")) > 0.5, "Partial Match", "No Match" ) )} -> No Match
A16: <XX participants> | C16: KeyValue | D16: 56 participants | E16: Protocol Example (28Sep2023) 1 | F16: Provide the maximum number of participants expected in this study, formatted for inline continuity. | G16: up to 28 participants | I16: {=_xldudf_BOARDFLARE_FMATCH(D16,G16)} -> #VALUE! | J16: =IF(M16>O16, M16,O16) -> 0.57 | L16: {=_xldudf_BOARDFLARE_FMATCH(G16,D16)} -> #VALUE! | M16: {=_FV(L16,"Similarity",TRUE)} -> 0.57 | N16: {=_xldudf_BOARDFLARE_FMATCH(D16,G16)} -> #VALUE! | O16: {=_FV(N16,"Similarity",TRUE)} -> 0.55 | AI16: yes | AO16: {=MAX( SUMPRODUCT(--ISNUMBER(MATCH(_xlfn.TEXTSPLIT(LOWER(D16)," "), _xlfn.TEXTSPLIT(LOWER(G16)," "),0))) / COUNTA(_xlfn.TEXTSPLIT(D16," ")), SUMPRODUCT(--ISNUMBER(SEARCH(LEFT(_xlfn.TEXTSPLIT(LOWER(D16)," "),LEN(_xlfn.TEXTSPLIT(LOWER(D16)," "))-1), LOWER(G16)))) / COUNTA(_xlfn.TEXTSPLIT(D16," ")) )} -> 0 | AP16: =IF(AO16>=0.8,"Match","No Match") -> No Match
A17: <Brief lay description of study design including purpose/objectives> | C17: Table | D17: Objectives/Endpoints: The following objectives and endpoints will be evaluated in healthy participants during the SAD component of the study and in participants with boneitis in the repeat-dose component of the study. Objectives Endpoints Primary To assess the safety and tolerability after 4 weeks of exposure following single ascending doses of ABC-123 Number of participants with serious and other nonserious AEs Secondary To assess the safety and tolerability following repeated doses over 4 weeks of ABC-123 Number of participants with serious and other nonserious AEs To characterize PK of ABC-123 following single ascending doses Cmax and AUClast To characterize the PK of ABC-123 following repeated doses Cmax and AUClast Exploratory To explore additional PK characteristics of ABC-123 following single ascending doses Tmax, Clast, Tlast, AUCinf, CL, V, and t1/2 To explore additional PK characteristics of ABC-123 following repeated doses Tmax, Clast, Tlast, AUCinf, CL, V, and t1/2 To explore effects of ABC-123 on clinical laboratory assessments, 12-lead ECG, and vital signs following single ascending doses Incidence of clinically significant changes in laboratory parameters, 12-lead ECG parameters, and vital signs measurements To explore effects of ABC-123 on clinical laboratory assessments, 12-lead ECG, and vital signs following repeated doses Incidence of clinically significant changes in laboratory parameters, 12-lead ECG parameters, and vital signs measurements To explore the impact of ADA on the PK profile of ABC-123 following single ascending doses Impact of ADA on AUC or impact on overall exposure of ABC-123 To explore the impact of ADA on the PK profile of ABC-123 following repeated doses Impact of ADA on AUC or impact on overall exposure of ABC-123 To explore the effects on eating behavior in participants following single ascending doses of ABC-123 Hunger, satiety, and appetite VAS scores Abbreviations: ADA = antidrug antibodies; AE = adverse event. | E17: Protocol Example (28Sep2023) 1 | F17: Write a brief lay description of the study design, purpose, and objectives suitable for participant information. | G17: <li>This study is designed to test ABC-123, a new therapy, in healthy volunteers and participants with boneitis.</li><li>The purpose is to evaluate safety, tolerability, and pharmacodynamic effects of ABC-123.</li><li>The study includes a single ascending dose (SAD) portion that is double-blind, randomized, and placebo-controlled.</li><liParticipants may help advance treatment options for boneitis and contribute to medical research.</li> | I17: {=_xldudf_BOARDFLARE_FMATCH(D17,G17)} -> #VALUE! | J17: =IF(M17>O17, M17,O17) -> 0 | L17: {=_xldudf_BOARDFLARE_FMATCH(G17,D17)} -> #VALUE! | M17: {=_FV(L17,"Similarity",TRUE)} -> 0 | N17: {=_xldudf_BOARDFLARE_FMATCH(D17,G17)} -> #VALUE! | O17: {=_FV(N17,"Similarity",TRUE)} -> 0 | R17: 16 | S17: 2 | T17: Abbreviations: ADA = antidrug antibodies; AE = adverse event. | U17: NA | V17: NA | W17: NA | X17: no | Y17: {=SUMPRODUCT(--ISNUMBER(SEARCH(_xlfn.TEXTSPLIT(D17," "), G17))) / COUNTA(_xlfn.TEXTSPLIT(D17," "))} -> 0.37666667 | Z17: {=IF( SUMPRODUCT(--ISNUMBER(SEARCH(_xlfn.TEXTSPLIT(D17," "), G17))) / COUNTA(_xlfn.TEXTSPLIT(D17," ")) = 1, "Full Match", IF( SUMPRODUCT(--ISNUMBER(SEARCH(_xlfn.TEXTSPLIT(D17," "), G8))) / COUNTA(_xlfn.TEXTSPLIT(D17," ")) > 0.5, "Partial Match", "No Match" ) )} -> No Match | AI17: yes
A18: <lay terminology for SAD portion of study> | C18: Paragraph | D18: All screening tests establishing eligibility will be performed following informed consent and within 35 days prior to study intervention administration. Participants will reside at the CRU from Day 2 to Day 5 and Day 28 to Day 33 and will receive SC 150 mg ABC-123 (6 participants) or placebo (2 participants) every other week for 3 doses. The actual dose and regimen selected for this part of the study will be based on the safety, tolerability, and PK of ABC-123 as determined during the ongoing SAD component of the study. To account for anticipated accumulation, the dose selected for the repeat-dose cohort will not exceed 50% of a dose that has previously been shown to be safe and well tolerated in the single-dose cohort. Sentinel dosing is not required during this part of the study. Participants must not have been enrolled in the SAD component. | E18: Protocol Example (28Sep2023) 1 | F18: Provide a concise lay term for the SAD portion of the study, matching the flow for an inline reference. | G18: the single-dose part of the study | I18: {=_xldudf_BOARDFLARE_FMATCH(D18,G18)} -> #VALUE! | J18: =IF(M18>O18, M18,O18) -> 0 | L18: {=_xldudf_BOARDFLARE_FMATCH(G18,D18)} -> #VALUE! | M18: {=_FV(L18,"Similarity",TRUE)} -> 0 | N18: {=_xldudf_BOARDFLARE_FMATCH(D18,G18)} -> #VALUE! | O18: {=_FV(N18,"Similarity",TRUE)} -> 0 | AD18: yes | AI18: yes | AJ18: no | AK18: {=SUMPRODUCT(--ISNUMBER(SEARCH(_xlfn.TEXTSPLIT(D18," "), G18))) / COUNTA(_xlfn.TEXTSPLIT(D18," "))} -> 0.2 | AL18: =AK18*100 -> 20 | AM18: {=IF( SUMPRODUCT(--ISNUMBER(SEARCH(_xlfn.TEXTSPLIT(D18," "), G18))) / COUNTA(_xlfn.TEXTSPLIT(D18," ")) = 1, "Full Match", IF( SUMPRODUCT(--ISNUMBER(SEARCH(_xlfn.TEXTSPLIT(D18," "), G18))) / COUNTA(_xlfn.TEXTSPLIT(D18," ")) > 0.5, "Partial Match", "No Match" ) )} -> No Match
A19: <XX applicable time unit> | C19: KeyValue | D19: 5 week | E19: Protocol Example (28Sep2023) 1 | F19: Replace the placeholder with the estimated total time commitment (in appropriate units) for study participation. | G19: 2 to 4 weeks | I19: {=_xldudf_BOARDFLARE_FMATCH(D19,G19)} -> #VALUE! | J19: =IF(M19>O19, M19,O19) -> 0.59 | L19: {=_xldudf_BOARDFLARE_FMATCH(G19,D19)} -> #VALUE! | M19: {=_FV(L19,"Similarity",TRUE)} -> 0 | N19: {=_xldudf_BOARDFLARE_FMATCH(D19,G19)} -> #VALUE! | O19: {=_FV(N19,"Similarity",TRUE)} -> 0.59 | AD19: yes | AI19: yes | AO19: {=MAX( SUMPRODUCT(--ISNUMBER(MATCH(_xlfn.TEXTSPLIT(LOWER(D19)," "), _xlfn.TEXTSPLIT(LOWER(G19)," "),0))) / COUNTA(_xlfn.TEXTSPLIT(D19," ")), SUMPRODUCT(--ISNUMBER(SEARCH(LEFT(_xlfn.TEXTSPLIT(LOWER(D19)," "),LEN(_xlfn.TEXTSPLIT(LOWER(D19)," "))-1), LOWER(G19)))) / COUNTA(_xlfn.TEXTSPLIT(D19," ")) )} -> 1 | AP19: =IF(AO19>=0.8,"Match","No Match") -> Match
A20: <lay terminology for route of administration of study drug> | C20: Table | D20: Arm Name ABC-123 Placebo Intervention Name ABC-123 Placebo (blinded) Type Blorp inductor NA Dose Formulation Injectable solution Injectable solution Unit Dose Strength(s) 150 mg/mL Matching placebo Dosage Level(s) SAD 5 mg with approximate half-log escalations NA Repeat-dose Proposed dose level: 150 mg every other week for 3 doses (to be confirmed based on SAD data) NA Route of Administration Subcutaneous Subcutaneous Use Experimental Placebo IMP and NIMP IMP IMP Sourcing Provided centrally by the Sponsor Provided centrally by the Sponsor Packaging and Labeling ABC-123 will be provided in glass vials. Each vial will be labeled as required per FDA requirements. Placebo will be provided in matching glass vials. Each vial will be labeled per FDA requirements. | E20: Protocol Example (28Sep2023) 1 | F20: Replace with a lay term for subcutaneous administration of the study drug. | G20: shot under the skin | I20: {=_xldudf_BOARDFLARE_FMATCH(D20,G20)} -> #VALUE! | J20: =IF(M20>O20, M20,O20) -> 0 | L20: {=_xldudf_BOARDFLARE_FMATCH(G20,D20)} -> #VALUE! | M20: {=_FV(L20,"Similarity",TRUE)} -> 0 | N20: {=_xldudf_BOARDFLARE_FMATCH(D20,G20)} -> #VALUE! | O20: {=_FV(N20,"Similarity",TRUE)} -> 0 | R20: 13 | S20: 3 | T20: Abbreviations: FDA = Food and Drug Administration; IMP = investigational medicinal product; NA = not applicable; NIMP = noninvestigational medicinal product. | U20: NA | V20: NA | W20: NA | X20: no | Y20: {=SUMPRODUCT(--ISNUMBER(SEARCH(_xlfn.TEXTSPLIT(D20," "), G20))) / COUNTA(_xlfn.TEXTSPLIT(D20," "))} -> 0.033613445 | Z20: {=IF( SUMPRODUCT(--ISNUMBER(SEARCH(_xlfn.TEXTSPLIT(D20," "), G20))) / COUNTA(_xlfn.TEXTSPLIT(D20," ")) = 1, "Full Match", IF( SUMPRODUCT(--ISNUMBER(SEARCH(_xlfn.TEXTSPLIT(D20," "), G11))) / COUNTA(_xlfn.TEXTSPLIT(D20," ")) > 0.5, "Partial Match", "No Match" ) )} -> No Match | AI20: yes
A21: <study drug ID> | C21: KeyValue | D21: ABC-123 | E21: Protocol Example (28Sep2023) 1 | I21: {=_xldudf_BOARDFLARE_FMATCH(D21,G21)} -> #VALUE! | J21: =IF(M21>O21, M21,O21) -> 0 | L21: {=_xldudf_BOARDFLARE_FMATCH(G21,D21)} -> #VALUE! | M21: {=_FV(L21,"Similarity",TRUE)} -> 0 | N21: {=_xldudf_BOARDFLARE_FMATCH(D21,G21)} -> #VALUE! | O21: {=_FV(N21,"Similarity",TRUE)} -> 0 | AD21: yes | AI21: yes | AO21: {=MAX( SUMPRODUCT(--ISNUMBER(MATCH(_xlfn.TEXTSPLIT(LOWER(D21)," "), _xlfn.TEXTSPLIT(LOWER(G21)," "),0))) / COUNTA(_xlfn.TEXTSPLIT(D21," ")), SUMPRODUCT(--ISNUMBER(SEARCH(LEFT(_xlfn.TEXTSPLIT(LOWER(D21)," "),LEN(_xlfn.TEXTSPLIT(LOWER(D21)," "))-1), LOWER(G21)))) / COUNTA(_xlfn.TEXTSPLIT(D21," ")) )} -> 0 | AP21: =IF(AO21>=0.8,"Match","No Match") -> No Match
A22: <lay terminology for repeat-dose portion of study> | C22: Paragraph | D22: The SAD portion of this study is a standard design for first-in-human testing with a monoclonal antibody. In addition, a 4-week repeated dose cohort will allow confirmation of the safety, tolerability, and repeat-dose PK and immunogenicity in the target population prior to proceeding to subsequent repeat-dose studies in a patient population. | E22: Protocol Example (28Sep2023) 1 | I22: {=_xldudf_BOARDFLARE_FMATCH(D22,G22)} -> #VALUE! | J22: =IF(M22>O22, M22,O22) -> 0 | L22: {=_xldudf_BOARDFLARE_FMATCH(G22,D22)} -> #VALUE! | M22: {=_FV(L22,"Similarity",TRUE)} -> 0 | N22: {=_xldudf_BOARDFLARE_FMATCH(D22,G22)} -> #VALUE! | O22: {=_FV(N22,"Similarity",TRUE)} -> 0 | AD22: yes | AI22: yes | AJ22: no | AK22: {=SUMPRODUCT(--ISNUMBER(SEARCH(_xlfn.TEXTSPLIT(D22," "), G22))) / COUNTA(_xlfn.TEXTSPLIT(D22," "))} -> 0 | AL22: =AK22*100 -> 0 | AM22: {=IF( SUMPRODUCT(--ISNUMBER(SEARCH(_xlfn.TEXTSPLIT(D22," "), G22))) / COUNTA(_xlfn.TEXTSPLIT(D22," ")) = 1, "Full Match", IF( SUMPRODUCT(--ISNUMBER(SEARCH(_xlfn.TEXTSPLIT(D22," "), G22))) / COUNTA(_xlfn.TEXTSPLIT(D22," ")) > 0.5, "Partial Match", "No Match" ) )} -> No Match
A23: <XX applicable time unit> | C23: KeyValue | D23: 5 week | E23: Protocol Example (28Sep2023) 1 | F23: Replace the placeholder with the estimated total time commitment (in appropriate units) for study participation. | G23: 2 to 4 weeks | I23: {=_xldudf_BOARDFLARE_FMATCH(D23,G23)} -> #VALUE! | J23: =IF(M23>O23, M23,O23) -> 0.59 | L23: {=_xldudf_BOARDFLARE_FMATCH(G23,D23)} -> #VALUE! | M23: {=_FV(L23,"Similarity",TRUE)} -> 0 | N23: {=_xldudf_BOARDFLARE_FMATCH(D23,G23)} -> #VALUE! | O23: {=_FV(N23,"Similarity",TRUE)} -> 0.59 | AD23: yes | AI23: yes | AO23: {=MAX( SUMPRODUCT(--ISNUMBER(MATCH(_xlfn.TEXTSPLIT(LOWER(D23)," "), _xlfn.TEXTSPLIT(LOWER(G23)," "),0))) / COUNTA(_xlfn.TEXTSPLIT(D23," ")), SUMPRODUCT(--ISNUMBER(SEARCH(LEFT(_xlfn.TEXTSPLIT(LOWER(D23)," "),LEN(_xlfn.TEXTSPLIT(LOWER(D23)," "))-1), LOWER(G23)))) / COUNTA(_xlfn.TEXTSPLIT(D23," ")) )} -> 1 | AP23: =IF(AO23>=0.8,"Match","No Match") -> Match
A24: <lay terminology for route of administration of study drug> | C24: Table | D24: Arm Name ABC-123 Placebo Intervention Name ABC-123 Placebo (blinded) Type Blorp inductor NA Dose Formulation Injectable solution Injectable solution Unit Dose Strength(s) 150 mg/mL Matching placebo Dosage Level(s) SAD 5 mg with approximate half-log escalations NA Repeat-dose Proposed dose level: 150 mg every other week for 3 doses (to be confirmed based on SAD data) NA Route of Administration Subcutaneous Subcutaneous Use Experimental Placebo IMP and NIMP IMP IMP Sourcing Provided centrally by the Sponsor Provided centrally by the Sponsor Packaging and Labeling ABC-123 will be provided in glass vials. Each vial will be labeled as required per FDA requirements. Placebo will be provided in matching glass vials. Each vial will be labeled per FDA requirements. | E24: Protocol Example (28Sep2023) 1 | F24: Replace with a lay term for subcutaneous administration of the study drug. | G24: shot under the skin | I24: {=_xldudf_BOARDFLARE_FMATCH(D24,G24)} -> #VALUE! | J24: =IF(M24>O24, M24,O24) -> 0 | L24: {=_xldudf_BOARDFLARE_FMATCH(G24,D24)} -> #VALUE! | M24: {=_FV(L24,"Similarity",TRUE)} -> 0 | N24: {=_xldudf_BOARDFLARE_FMATCH(D24,G24)} -> #VALUE! | O24: {=_FV(N24,"Similarity",TRUE)} -> 0 | R24: 13 | S24: 3 | T24: Abbreviations: FDA = Food and Drug Administration; IMP = investigational medicinal product; NA = not applicable; NIMP = noninvestigational medicinal product. | U24: NA | V24: NA | W24: NA | X24: no | Y24: {=SUMPRODUCT(--ISNUMBER(SEARCH(_xlfn.TEXTSPLIT(D24," "), G24))) / COUNTA(_xlfn.TEXTSPLIT(D24," "))} -> 0.033613445 | Z24: {=IF( SUMPRODUCT(--ISNUMBER(SEARCH(_xlfn.TEXTSPLIT(D24," "), G24))) / COUNTA(_xlfn.TEXTSPLIT(D24," ")) = 1, "Full Match", IF( SUMPRODUCT(--ISNUMBER(SEARCH(_xlfn.TEXTSPLIT(D24," "), G15))) / COUNTA(_xlfn.TEXTSPLIT(D24," ")) > 0.5, "Partial Match", "No Match" ) )} -> No Match | AI24: yes
A25: <study drug ID> | C25: KeyValue | D25: ABC-123 | E25: Protocol Example (28Sep2023) 1 | I25: {=_xldudf_BOARDFLARE_FMATCH(D25,G25)} -> #VALUE! | J25: =IF(M25>O25, M25,O25) -> 0 | L25: {=_xldudf_BOARDFLARE_FMATCH(G25,D25)} -> #VALUE! | M25: {=_FV(L25,"Similarity",TRUE)} -> 0 | N25: {=_xldudf_BOARDFLARE_FMATCH(D25,G25)} -> #VALUE! | O25: {=_FV(N25,"Similarity",TRUE)} -> 0 | AD25: yes | AI25: yes | AO25: {=MAX( SUMPRODUCT(--ISNUMBER(MATCH(_xlfn.TEXTSPLIT(LOWER(D25)," "), _xlfn.TEXTSPLIT(LOWER(G25)," "),0))) / COUNTA(_xlfn.TEXTSPLIT(D25," ")), SUMPRODUCT(--ISNUMBER(SEARCH(LEFT(_xlfn.TEXTSPLIT(LOWER(D25)," "),LEN(_xlfn.TEXTSPLIT(LOWER(D25)," "))-1), LOWER(G25)))) / COUNTA(_xlfn.TEXTSPLIT(D25," ")) )} -> 0 | AP25: =IF(AO25>=0.8,"Match","No Match") -> No Match
A26: <lay terminology for dosing regimen/duration> | C26: Paragraph | D26: Following Check-out from the CRU, all participants will return for Follow-up study visits up to 6 weeks post dosing in the first 3 cohorts and 10 weeks post dosing in the remaining cohorts as shown in the Schedule of Assessments | E26: Protocol Example (28Sep2023) 1 | F26: Rewrite the dosing regimen and duration in clear lay terms suitable for an informed consent document. | G26: every other week for 3 doses over up to 6 weeks | I26: {=_xldudf_BOARDFLARE_FMATCH(D26,G26)} -> #VALUE! | J26: =IF(M26>O26, M26,O26) -> 0 | L26: {=_xldudf_BOARDFLARE_FMATCH(G26,D26)} -> #VALUE! | M26: {=_FV(L26,"Similarity",TRUE)} -> 0 | N26: {=_xldudf_BOARDFLARE_FMATCH(D26,G26)} -> #VALUE! | O26: {=_FV(N26,"Similarity",TRUE)} -> 0 | AD26: yes | AI26: yes | AJ26: yes | AK26: {=SUMPRODUCT(--ISNUMBER(SEARCH(_xlfn.TEXTSPLIT(D26," "), G26))) / COUNTA(_xlfn.TEXTSPLIT(D26," "))} -> 0.25 | AL26: =AK26*100 -> 25 | AM26: {=IF( SUMPRODUCT(--ISNUMBER(SEARCH(_xlfn.TEXTSPLIT(D26," "), G26))) / COUNTA(_xlfn.TEXTSPLIT(D26," ")) = 1, "Full Match", IF( SUMPRODUCT(--ISNUMBER(SEARCH(_xlfn.TEXTSPLIT(D26," "), G26))) / COUNTA(_xlfn.TEXTSPLIT(D26," ")) > 0.5, "Partial Match", "No Match" ) )} -> No Match
A27: <CRO Name> | E27: Protocol Example (28Sep2023) 1 | I27: {=_xldudf_BOARDFLARE_FMATCH(D27,G27)} -> #VALUE! | J27: =IF(M27>O27, M27,O27) -> 0 | L27: {=_xldudf_BOARDFLARE_FMATCH(G27,D27)} -> #VALUE! | M27: {=_FV(L27,"Similarity",TRUE)} -> 0 | N27: {=_xldudf_BOARDFLARE_FMATCH(D27,G27)} -> #VALUE! | O27: {=_FV(N27,"Similarity",TRUE)} -> 0 | AD27: yes | AI27: yes
A28: <Sponsor Name> | C28: KeyValue | D28: Stendarr, Inc. | E28: Protocol Example (28Sep2023) 1 | F28: Insert the official sponsor name in line with protocol header formatting. | G28: Stendarr, Inc. | I28: {=_xldudf_BOARDFLARE_FMATCH(D28,G28)} -> #VALUE! | J28: =IF(M28>O28, M28,O28) -> 0.99 | L28: {=_xldudf_BOARDFLARE_FMATCH(G28,D28)} -> #VALUE! | M28: {=_FV(L28,"Similarity",TRUE)} -> 0.99 | N28: {=_xldudf_BOARDFLARE_FMATCH(D28,G28)} -> #VALUE! | O28: {=_FV(N28,"Similarity",TRUE)} -> 0.85 | AD28: yes | AI28: yes | AO28: {=MAX( SUMPRODUCT(--ISNUMBER(MATCH(_xlfn.TEXTSPLIT(LOWER(D28)," "), _xlfn.TEXTSPLIT(LOWER(G28)," "),0))) / COUNTA(_xlfn.TEXTSPLIT(D28," ")), SUMPRODUCT(--ISNUMBER(SEARCH(LEFT(_xlfn.TEXTSPLIT(LOWER(D28)," "),LEN(_xlfn.TEXTSPLIT(LOWER(D28)," "))-1), LOWER(G28)))) / COUNTA(_xlfn.TEXTSPLIT(D28," ")) )} -> 1 | AP28: =IF(AO28>=0.8,"Match","No Match") -> Match
A29: <Protocol Number> | C29: KeyValue | D29: SKY-2000-101 | E29: Protocol Example (28Sep2023) 1 | F29: Insert the official protocol number in the format used in the source document. | G29: SKY-2000-101 | I29: {=_xldudf_BOARDFLARE_FMATCH(D29,G29)} -> #VALUE! | J29: =IF(M29>O29, M29,O29) -> 1 | L29: {=_xldudf_BOARDFLARE_FMATCH(G29,D29)} -> #VALUE! | M29: {=_FV(L29,"Similarity",TRUE)} -> 1 | N29: {=_xldudf_BOARDFLARE_FMATCH(D29,G29)} -> #VALUE! | O29: {=_FV(N29,"Similarity",TRUE)} -> 0.92 | AD29: yes | AI29: yes | AO29: {=MAX( SUMPRODUCT(--ISNUMBER(MATCH(_xlfn.TEXTSPLIT(LOWER(D29)," "), _xlfn.TEXTSPLIT(LOWER(G29)," "),0))) / COUNTA(_xlfn.TEXTSPLIT(D29," ")), SUMPRODUCT(--ISNUMBER(SEARCH(LEFT(_xlfn.TEXTSPLIT(LOWER(D29)," "),LEN(_xlfn.TEXTSPLIT(LOWER(D29)," "))-1), LOWER(G29)))) / COUNTA(_xlfn.TEXTSPLIT(D29," ")) )} -> 1 | AP29: =IF(AO29>=0.8,"Match","No Match") -> Match
A30: <Principal Investigator Name> | C30: KeyValue | D30: Karliah N. Gale, MD​profe​ | E30: Protocol Example (28Sep2023) 1 | I30: {=_xldudf_BOARDFLARE_FMATCH(D30,G30)} -> #VALUE! | J30: =IF(M30>O30, M30,O30) -> 0 | L30: {=_xldudf_BOARDFLARE_FMATCH(G30,D30)} -> #VALUE! | M30: {=_FV(L30,"Similarity",TRUE)} -> 0 | N30: {=_xldudf_BOARDFLARE_FMATCH(D30,G30)} -> #VALUE! | O30: {=_FV(N30,"Similarity",TRUE)} -> 0 | AD30: yes | AI30: yes | AO30: {=MAX( SUMPRODUCT(--ISNUMBER(MATCH(_xlfn.TEXTSPLIT(LOWER(D30)," "), _xlfn.TEXTSPLIT(LOWER(G30)," "),0))) / COUNTA(_xlfn.TEXTSPLIT(D30," ")), SUMPRODUCT(--ISNUMBER(SEARCH(LEFT(_xlfn.TEXTSPLIT(LOWER(D30)," "),LEN(_xlfn.TEXTSPLIT(LOWER(D30)," "))-1), LOWER(G30)))) / COUNTA(_xlfn.TEXTSPLIT(D30," ")) )} -> 0 | AP30: =IF(AO30>=0.8,"Match","No Match") -> No Match
A31: <IRB Company Name> | C31: KeyValue | D31: Stendarr, Inc. | E31: Protocol Example (28Sep2023) 1 | F31: Insert the IRB company name in a concise, inline format. | G31: Stendarr, Inc. | I31: {=_xldudf_BOARDFLARE_FMATCH(D31,G31)} -> #VALUE! | J31: =IF(M31>O31, M31,O31) -> 0.99 | L31: {=_xldudf_BOARDFLARE_FMATCH(G31,D31)} -> #VALUE! | M31: {=_FV(L31,"Similarity",TRUE)} -> 0.99 | N31: {=_xldudf_BOARDFLARE_FMATCH(D31,G31)} -> #VALUE! | O31: {=_FV(N31,"Similarity",TRUE)} -> 0.85 | AD31: yes | AI31: yes | AO31: {=MAX( SUMPRODUCT(--ISNUMBER(MATCH(_xlfn.TEXTSPLIT(LOWER(D31)," "), _xlfn.TEXTSPLIT(LOWER(G31)," "),0))) / COUNTA(_xlfn.TEXTSPLIT(D31," ")), SUMPRODUCT(--ISNUMBER(SEARCH(LEFT(_xlfn.TEXTSPLIT(LOWER(D31)," "),LEN(_xlfn.TEXTSPLIT(LOWER(D31)," "))-1), LOWER(G31)))) / COUNTA(_xlfn.TEXTSPLIT(D31," ")) )} -> 1 | AP31: =IF(AO31>=0.8,"Match","No Match") -> Match
A32: <disease> | C32: KeyValue | D32: Boneitis | E32: Protocol Example (28Sep2023) 1 | F32: Insert the disease name treated by the investigational drug, formatted for inline continuity. | G32: boneitis | I32: {=_xldudf_BOARDFLARE_FMATCH(D32,G32)} -> #VALUE! | J32: =IF(M32>O32, M32,O32) -> 1 | L32: {=_xldudf_BOARDFLARE_FMATCH(G32,D32)} -> #VALUE! | M32: {=_FV(L32,"Similarity",TRUE)} -> 1 | N32: {=_xldudf_BOARDFLARE_FMATCH(D32,G32)} -> #VALUE! | O32: {=_FV(N32,"Similarity",TRUE)} -> 1 | AD32: yes | AI32: yes | AO32: {=MAX( SUMPRODUCT(--ISNUMBER(MATCH(_xlfn.TEXTSPLIT(LOWER(D32)," "), _xlfn.TEXTSPLIT(LOWER(G32)," "),0))) / COUNTA(_xlfn.TEXTSPLIT(D32," ")), SUMPRODUCT(--ISNUMBER(SEARCH(LEFT(_xlfn.TEXTSPLIT(LOWER(D32)," "),LEN(_xlfn.TEXTSPLIT(LOWER(D32)," "))-1), LOWER(G32)))) / COUNTA(_xlfn.TEXTSPLIT(D32," ")) )} -> 1 | AP32: =IF(AO32>=0.8,"Match","No Match") -> Match
A33: <brief lay description of disease> | C33: Paragraph | D33: ABC-123 is intended for use in patients with boneitis, a disease that causes bones to change shape or disappear. | E33: Protocol Example (28Sep2023) 1 | F33: Provide a brief, clear lay description of boneitis to fit seamlessly within the sentence. | G33: a disease that causes bones to change shape or disappear | I33: {=_xldudf_BOARDFLARE_FMATCH(D33,G33)} -> #VALUE! | J33: =IF(M33>O33, M33,O33) -> 0.79 | L33: {=_xldudf_BOARDFLARE_FMATCH(G33,D33)} -> #VALUE! | M33: {=_FV(L33,"Similarity",TRUE)} -> 0.79 | N33: {=_xldudf_BOARDFLARE_FMATCH(D33,G33)} -> #VALUE! | O33: {=_FV(N33,"Similarity",TRUE)} -> 0 | AD33: yes | AI33: yes | AJ33: yes | AK33: {=SUMPRODUCT(--ISNUMBER(SEARCH(_xlfn.TEXTSPLIT(D33," "), G33))) / COUNTA(_xlfn.TEXTSPLIT(D33," "))} -> 0.57894737 | AL33: =AK33*100 -> 57.894737 | AM33: {=IF( SUMPRODUCT(--ISNUMBER(SEARCH(_xlfn.TEXTSPLIT(D33," "), G33))) / COUNTA(_xlfn.TEXTSPLIT(D33," ")) = 1, "Full Match", IF( SUMPRODUCT(--ISNUMBER(SEARCH(_xlfn.TEXTSPLIT(D33," "), G33))) / COUNTA(_xlfn.TEXTSPLIT(D33," ")) > 0.5, "Partial Match", "No Match" ) )} -> Partial Match
A34: <Brief lay description of study design including purpose/objectives> | C34: Table | D34: Objectives/Endpoints: The following objectives and endpoints will be evaluated in healthy participants during the SAD component of the study and in participants with boneitis in the repeat-dose component of the study. Objectives Endpoints Primary To assess the safety and tolerability after 4 weeks of exposure following single ascending doses of ABC-123 Number of participants with serious and other nonserious AEs Secondary To assess the safety and tolerability following repeated doses over 4 weeks of ABC-123 Number of participants with serious and other nonserious AEs To characterize PK of ABC-123 following single ascending doses Cmax and AUClast To characterize the PK of ABC-123 following repeated doses Cmax and AUClast Exploratory To explore additional PK characteristics of ABC-123 following single ascending doses Tmax, Clast, Tlast, AUCinf, CL, V, and t1/2 To explore additional PK characteristics of ABC-123 following repeated doses Tmax, Clast, Tlast, AUCinf, CL, V, and t1/2 To explore effects of ABC-123 on clinical laboratory assessments, 12-lead ECG, and vital signs following single ascending doses Incidence of clinically significant changes in laboratory parameters, 12-lead ECG parameters, and vital signs measurements To explore effects of ABC-123 on clinical laboratory assessments, 12-lead ECG, and vital signs following repeated doses Incidence of clinically significant changes in laboratory parameters, 12-lead ECG parameters, and vital signs measurements To explore the impact of ADA on the PK profile of ABC-123 following single ascending doses Impact of ADA on AUC or impact on overall exposure of ABC-123 To explore the impact of ADA on the PK profile of ABC-123 following repeated doses Impact of ADA on AUC or impact on overall exposure of ABC-123 To explore the effects on eating behavior in participants following single ascending doses of ABC-123 Hunger, satiety, and appetite VAS scores Abbreviations: ADA = antidrug antibodies; AE = adverse event. | E34: Protocol Example (28Sep2023) 1 | F34: Write a brief, layperson-oriented paragraph describing the study design, including its main goals and what will be assessed. | G34: This study is being conducted to evaluate the safety and effects of a new investigational drug, ABC-123. It includes both healthy volunteers and participants with boneitis. The study will help researchers learn how the drug works in the body, how safe it is, and how it affects certain health measurements. The results will provide important information for future studies and may help identify the best dose and people who could benefit from ABC-123. | I34: {=_xldudf_BOARDFLARE_FMATCH(D34,G34)} -> #VALUE! | J34: =IF(M34>O34, M34,O34) -> 0 | L34: {=_xldudf_BOARDFLARE_FMATCH(G34,D34)} -> #VALUE! | M34: {=_FV(L34,"Similarity",TRUE)} -> 0 | N34: {=_xldudf_BOARDFLARE_FMATCH(D34,G34)} -> #VALUE! | O34: {=_FV(N34,"Similarity",TRUE)} -> 0 | R34: 16 | S34: 2 | T34: Abbreviations: ADA = antidrug antibodies; AE = adverse event. | U34: NA | V34: NA | W34: NA | X34: no | Y34: {=SUMPRODUCT(--ISNUMBER(SEARCH(_xlfn.TEXTSPLIT(D34," "), G34))) / COUNTA(_xlfn.TEXTSPLIT(D34," "))} -> 0.34 | Z34: {=IF( SUMPRODUCT(--ISNUMBER(SEARCH(_xlfn.TEXTSPLIT(D34," "), G34))) / COUNTA(_xlfn.TEXTSPLIT(D34," ")) = 1, "Full Match", IF( SUMPRODUCT(--ISNUMBER(SEARCH(_xlfn.TEXTSPLIT(D34," "), G25))) / COUNTA(_xlfn.TEXTSPLIT(D34," ")) > 0.5, "Partial Match", "No Match" ) )} -> No Match | AI34: yes
A35: <lay terminology for SAD portion of study> | C35: Paragraph | D35: All screening tests establishing eligibility will be performed following informed consent and within 35 days prior to study intervention administration. Participants will reside at the CRU from Day 2 to Day 5 and Day 28 to Day 33 and will receive SC 150 mg ABC-123 (6 participants) or placebo (2 participants) every other week for 3 doses. The actual dose and regimen selected for this part of the study will be based on the safety, tolerability, and PK of ABC-123 as determined during the ongoing SAD component of the study. To account for anticipated accumulation, the dose selected for the repeat-dose cohort will not exceed 50% of a dose that has previously been shown to be safe and well tolerated in the single-dose cohort. Sentinel dosing is not required during this part of the study. Participants must not have been enrolled in the SAD component. | E35: Protocol Example (28Sep2023) 1 | F35: Provide a concise lay term for the SAD portion of the study, matching the flow for an inline reference. | G35: the single-dose part of the study | I35: {=_xldudf_BOARDFLARE_FMATCH(D35,G35)} -> #VALUE! | J35: =IF(M35>O35, M35,O35) -> 0 | L35: {=_xldudf_BOARDFLARE_FMATCH(G35,D35)} -> #VALUE! | M35: {=_FV(L35,"Similarity",TRUE)} -> 0 | N35: {=_xldudf_BOARDFLARE_FMATCH(D35,G35)} -> #VALUE! | O35: {=_FV(N35,"Similarity",TRUE)} -> 0 | AD35: yes | AI35: yes | AJ35: yes | AK35: {=SUMPRODUCT(--ISNUMBER(SEARCH(_xlfn.TEXTSPLIT(D35," "), G35))) / COUNTA(_xlfn.TEXTSPLIT(D35," "))} -> 0.2 | AL35: =AK35*100 -> 20 | AM35: {=IF( SUMPRODUCT(--ISNUMBER(SEARCH(_xlfn.TEXTSPLIT(D35," "), G35))) / COUNTA(_xlfn.TEXTSPLIT(D35," ")) = 1, "Full Match", IF( SUMPRODUCT(--ISNUMBER(SEARCH(_xlfn.TEXTSPLIT(D35," "), G35))) / COUNTA(_xlfn.TEXTSPLIT(D35," ")) > 0.5, "Partial Match", "No Match" ) )} -> No Match
A36: <X cohorts (or groups) of X participants> | C36: KeyValue | D36: 3 cohorts of 56 participants | E36: Protocol Example (28Sep2023) 1 | F36: Insert the number of cohorts and participants per cohort for the SAD phase in the format 'X cohorts of X participants'. | G36: 6 cohorts of 8 participants | I36: {=_xldudf_BOARDFLARE_FMATCH(D36,G36)} -> #VALUE! | J36: =IF(M36>O36, M36,O36) -> 0.63 | L36: {=_xldudf_BOARDFLARE_FMATCH(G36,D36)} -> #VALUE! | M36: {=_FV(L36,"Similarity",TRUE)} -> 0.63 | N36: {=_xldudf_BOARDFLARE_FMATCH(D36,G36)} -> #VALUE! | O36: {=_FV(N36,"Similarity",TRUE)} -> 0.63 | AD36: yes | AI36: yes | AO36: {=MAX( SUMPRODUCT(--ISNUMBER(MATCH(_xlfn.TEXTSPLIT(LOWER(D36)," "), _xlfn.TEXTSPLIT(LOWER(G36)," "),0))) / COUNTA(_xlfn.TEXTSPLIT(D36," ")), SUMPRODUCT(--ISNUMBER(SEARCH(LEFT(_xlfn.TEXTSPLIT(LOWER(D36)," "),LEN(_xlfn.TEXTSPLIT(LOWER(D36)," "))-1), LOWER(G36)))) / COUNTA(_xlfn.TEXTSPLIT(D36," ")) )} -> 0.8 | AP36: =IF(AO36>=0.8,"Match","No Match") -> Match
A37: <lay terminology for route of administration of study drug> | C37: Table | D37: Arm Name ABC-123 Placebo Intervention Name ABC-123 Placebo (blinded) Type Blorp inductor NA Dose Formulation Injectable solution Injectable solution Unit Dose Strength(s) 150 mg/mL Matching placebo Dosage Level(s) SAD 5 mg with approximate half-log escalations NA Repeat-dose Proposed dose level: 150 mg every other week for 3 doses (to be confirmed based on SAD data) NA Route of Administration Subcutaneous Subcutaneous Use Experimental Placebo IMP and NIMP IMP IMP Sourcing Provided centrally by the Sponsor Provided centrally by the Sponsor Packaging and Labeling ABC-123 will be provided in glass vials. Each vial will be labeled as required per FDA requirements. Placebo will be provided in matching glass vials. Each vial will be labeled per FDA requirements. | E37: Protocol Example (28Sep2023) 1 | F37: Replace with a lay term for subcutaneous administration of the study drug. | G37: shot under the skin | I37: {=_xldudf_BOARDFLARE_FMATCH(D37,G37)} -> #VALUE! | J37: =IF(M37>O37, M37,O37) -> 0 | L37: {=_xldudf_BOARDFLARE_FMATCH(G37,D37)} -> #VALUE! | M37: {=_FV(L37,"Similarity",TRUE)} -> 0 | N37: {=_xldudf_BOARDFLARE_FMATCH(D37,G37)} -> #VALUE! | O37: {=_FV(N37,"Similarity",TRUE)} -> 0 | R37: 13 | S37: 3 | T37: Abbreviations: FDA = Food and Drug Administration; IMP = investigational medicinal product; NA = not applicable; NIMP = noninvestigational medicinal product. | U37: NA | V37: NA | W37: NA | X37: no | Y37: {=SUMPRODUCT(--ISNUMBER(SEARCH(_xlfn.TEXTSPLIT(D37," "), G37))) / COUNTA(_xlfn.TEXTSPLIT(D37," "))} -> 0.033613445 | Z37: {=IF( SUMPRODUCT(--ISNUMBER(SEARCH(_xlfn.TEXTSPLIT(D37," "), G37))) / COUNTA(_xlfn.TEXTSPLIT(D37," ")) = 1, "Full Match", IF( SUMPRODUCT(--ISNUMBER(SEARCH(_xlfn.TEXTSPLIT(D37," "), G28))) / COUNTA(_xlfn.TEXTSPLIT(D37," ")) > 0.5, "Partial Match", "No Match" ) )} -> No Match | AI37: yes
A38: <study drug ID> | C38: KeyValue | D38: Abc-123 | E38: Protocol Example (28Sep2023) 1 | I38: {=_xldudf_BOARDFLARE_FMATCH(D38,G38)} -> #VALUE! | J38: =IF(M38>O38, M38,O38) -> 0 | L38: {=_xldudf_BOARDFLARE_FMATCH(G38,D38)} -> #VALUE! | M38: {=_FV(L38,"Similarity",TRUE)} -> 0 | N38: {=_xldudf_BOARDFLARE_FMATCH(D38,G38)} -> #VALUE! | O38: {=_FV(N38,"Similarity",TRUE)} -> 0 | AD38: yes | AI38: yes | AO38: {=MAX( SUMPRODUCT(--ISNUMBER(MATCH(_xlfn.TEXTSPLIT(LOWER(D38)," "), _xlfn.TEXTSPLIT(LOWER(G38)," "),0))) / COUNTA(_xlfn.TEXTSPLIT(D38," ")), SUMPRODUCT(--ISNUMBER(SEARCH(LEFT(_xlfn.TEXTSPLIT(LOWER(D38)," "),LEN(_xlfn.TEXTSPLIT(LOWER(D38)," "))-1), LOWER(G38)))) / COUNTA(_xlfn.TEXTSPLIT(D38," ")) )} -> 0 | AP38: =IF(AO38>=0.8,"Match","No Match") -> No Match
A39: <X mg> | C39: KeyValue | D39: 600 mg | E39: Protocol Example (28Sep2023) 1 | I39: {=_xldudf_BOARDFLARE_FMATCH(D39,G39)} -> #VALUE! | J39: =IF(M39>O39, M39,O39) -> 0 | L39: {=_xldudf_BOARDFLARE_FMATCH(G39,D39)} -> #VALUE! | M39: {=_FV(L39,"Similarity",TRUE)} -> 0 | N39: {=_xldudf_BOARDFLARE_FMATCH(D39,G39)} -> #VALUE! | O39: {=_FV(N39,"Similarity",TRUE)} -> 0 | AD39: yes | AI39: yes | AO39: {=MAX( SUMPRODUCT(--ISNUMBER(MATCH(_xlfn.TEXTSPLIT(LOWER(D39)," "), _xlfn.TEXTSPLIT(LOWER(G39)," "),0))) / COUNTA(_xlfn.TEXTSPLIT(D39," ")), SUMPRODUCT(--ISNUMBER(SEARCH(LEFT(_xlfn.TEXTSPLIT(LOWER(D39)," "),LEN(_xlfn.TEXTSPLIT(LOWER(D39)," "))-1), LOWER(G39)))) / COUNTA(_xlfn.TEXTSPLIT(D39," ")) )} -> 0 | AP39: =IF(AO39>=0.8,"Match","No Match") -> No Match
A40: <XXXX-fold> | C40: KeyValue | D40: 318 fold | E40: Protocol Example (28Sep2023) 1 | I40: {=_xldudf_BOARDFLARE_FMATCH(D40,G40)} -> #VALUE! | J40: =IF(M40>O40, M40,O40) -> 0 | L40: {=_xldudf_BOARDFLARE_FMATCH(G40,D40)} -> #VALUE! | M40: {=_FV(L40,"Similarity",TRUE)} -> 0 | N40: {=_xldudf_BOARDFLARE_FMATCH(D40,G40)} -> #VALUE! | O40: {=_FV(N40,"Similarity",TRUE)} -> 0 | AD40: yes | AI40: yes | AO40: {=MAX( SUMPRODUCT(--ISNUMBER(MATCH(_xlfn.TEXTSPLIT(LOWER(D40)," "), _xlfn.TEXTSPLIT(LOWER(G40)," "),0))) / COUNTA(_xlfn.TEXTSPLIT(D40," ")), SUMPRODUCT(--ISNUMBER(SEARCH(LEFT(_xlfn.TEXTSPLIT(LOWER(D40)," "),LEN(_xlfn.TEXTSPLIT(LOWER(D40)," "))-1), LOWER(G40)))) / COUNTA(_xlfn.TEXTSPLIT(D40," ")) )} -> 0 | AP40: =IF(AO40>=0.8,"Match","No Match") -> No Match
...

Sheet Inline
A2: Placeholder | C2: Placeholder Type | D2: Expected Value | E2: Source Document | F2: Writing instruction | G2: AI Replaced Text | H2: Ai detected Source | I2: Matching Accuracy | J2: Similarity Score | K2: Source Match
A3: {=_xlfn._xlws.FILTER(QA!A3:K500, QA!C3:C500="Inline")} -> #VALUE!

Sheet Paragraph
A2: Placeholder | C2: Placeholder Type | D2: Expected Value | E2: Source Document | F2: Writing instruction | G2: AI Replaced Text | H2: Ai detected Source | I2: Matching Accuracy | J2: Similarity Score | K2: Source Match
A3: {=_xlfn._xlws.FILTER(QA!A3:K500, QA!C3:C500="Paragraph")} -> <Full protocol title> | B3: 0 | C3: Paragraph | D3: A First-In-Human, Phase 1, Randomized, Double-Blind, Placebo-Controlled Study to Evaluate the Safety, Tolerability, and Pharmacokinetics of ABC-123 as a Single Dose in Healthy Participants and as Multiple Doses in Participants with Grade 2 Boneitis | E3: Protocol Example (28Sep2023) 1 | F3: Insert the full protocol title verbatim, maintaining inline continuity. | G3: A First-In-Human, Phase 1, Randomized, Double-Blind, Placebo-Controlled Study to Evaluate the Safety, Tolerability, and Pharmacokinetics of ABC-123 as a Single Dose in Healthy Participants and as Multiple Doses in Participants with Grade 2 Boneitis | H3: 0 | I3: #VALUE! | J3: 0.61 | K3: 0
A4: <brief lay description of disease> | B4: 0 | C4: Paragraph | D4: ABC-123 is intended for use in patients with boneitis, a disease that causes bones to change shape or disappear. | E4: Protocol Example (28Sep2023) 1 | F4: Provide a brief, clear lay description of boneitis to fit seamlessly within the sentence. | G4: a disease that causes bones to change shape or disappear | H4: 0 | I4: #VALUE! | J4: 0.79 | K4: 0
A5: <type of study (eg, first-in-human, Phase 1, Phase 2)> | B5: 0 | C5: Paragraph | D5: The SAD portion of this study is a standard design for first-in-human testing with a monoclonal antibody. In addition, a 4-week repeated dose cohort will allow confirmation of the safety, tolerability, and repeat-dose PK and immunogenicity in the target population prior to proceeding to subsequent repeat-dose studies in a patient population. | E5: Protocol Example (28Sep2023) 1 | F5: Provide the study type in concise, inline format (e.g., first-in-human, Phase 1) to maintain paragraph continuity. | G5: first-in-human, Phase 1 | H5: 0 | I5: #VALUE! | J5: 0 | K5: 0
A6: <lay terminology for SAD portion of study> | B6: 0 | C6: Paragraph | D6: All screening tests establishing eligibility will be performed following informed consent and within 35 days prior to study intervention administration. Participants will reside at the CRU from Day 2 to Day 5 and Day 28 to Day 33 and will receive SC 150 mg ABC-123 (6 participants) or placebo (2 participants) every other week for 3 doses. The actual dose and regimen selected for this part of the study will be based on the safety, tolerability, and PK of ABC-123 as determined during the ongoing SAD component of the study. To account for anticipated accumulation, the dose selected for the repeat-dose cohort will not exceed 50% of a dose that has previously been shown to be safe and well tolerated in the single-dose cohort. Sentinel dosing is not required during this part of the study. Participants must not have been enrolled in the SAD component. | E6: Protocol Example (28Sep2023) 1 | F6: Provide a concise lay term for the SAD portion of the study, matching the flow for an inline reference. | G6: the single-dose part of the study | H6: 0 | I6: #VALUE! | J6: 0 | K6: 0
A7: <lay terminology for repeat-dose portion of study> | B7: 0 | C7: Paragraph | D7: The SAD portion of this study is a standard design for first-in-human testing with a monoclonal antibody. In addition, a 4-week repeated dose cohort will allow confirmation of the safety, tolerability, and repeat-dose PK and immunogenicity in the target population prior to proceeding to subsequent repeat-dose studies in a patient population. | E7: Protocol Example (28Sep2023) 1 | F7: 0 | G7: 0 | H7: 0 | I7: #VALUE! | J7: 0 | K7: 0
A8: <lay terminology for dosing regimen/duration> | B8: 0 | C8: Paragraph | D8: Following Check-out from the CRU, all participants will return for Follow-up study visits up to 6 weeks post dosing in the first 3 cohorts and 10 weeks post dosing in the remaining cohorts as shown in the Schedule of Assessments | E8: Protocol Example (28Sep2023) 1 | F8: Rewrite the dosing regimen and duration in clear lay terms suitable for an informed consent document. | G8: every other week for 3 doses over up to 6 weeks | H8: 0 | I8: #VALUE! | J8: 0 | K8: 0
A9: <brief lay description of disease> | B9: 0 | C9: Paragraph | D9: ABC-123 is intended for use in patients with boneitis, a disease that causes bones to change shape or disappear. | E9: Protocol Example (28Sep2023) 1 | F9: Provide a brief, clear lay description of boneitis to fit seamlessly within the sentence. | G9: a disease that causes bones to change shape or disappear | H9: 0 | I9: #VALUE! | J9: 0.79 | K9: 0
A10: <lay terminology for SAD portion of study> | B10: 0 | C10: Paragraph | D10: All screening tests establishing eligibility will be performed following informed consent and within 35 days prior to study intervention administration. Participants will reside at the CRU from Day 2 to Day 5 and Day 28 to Day 33 and will receive SC 150 mg ABC-123 (6 participants) or placebo (2 participants) every other week for 3 doses. The actual dose and regimen selected for this part of the study will be based on the safety, tolerability, and PK of ABC-123 as determined during the ongoing SAD component of the study. To account for anticipated accumulation, the dose selected for the repeat-dose cohort will not exceed 50% of a dose that has previously been shown to be safe and well tolerated in the single-dose cohort. Sentinel dosing is not required during this part of the study. Participants must not have been enrolled in the SAD component. | E10: Protocol Example (28Sep2023) 1 | F10: Provide a concise lay term for the SAD portion of the study, matching the flow for an inline reference. | G10: the single-dose part of the study | H10: 0 | I10: #VALUE! | J10: 0 | K10: 0
A11: <lay terminology summarizing design and enrollment plan for Cohort 1 with sentinel participants> | B11: 0 | C11: Paragraph | D11: All screening tests establishing eligibility will be performed following informed consent and within 35 days prior to study intervention administration. Each participant will be enrolled in 1 dose cohort only; participants will reside at the Clinical Research Unit (CRU) from Day 2 to Day 8. In each cohort, participants will receive a subcutaneous (SC) dose of ABC-123 (6 participants) or placebo (2 participants) on Day 1. To assure safety and tolerability of the starting dose, 2 sentinel participants will be dosed first in Cohort 1 (1 active drug and 1 placebo to maintain study blinding); the remaining Cohort 1 participants may be dosed at least 48 hours later, after initial safety of the sentinel participants is confirmed by the Phase 1 Unit Principal Investigator in consultation with the Sponsor. | E11: Protocol Example (28Sep2023) 1 | F11: Summarize the design and enrollment plan for Cohort 1, explaining sentinel dosing in lay language. | G11: The first group (Cohort 1) will include 8 participants, with 2 participants (called sentinels) receiving the study drug or placebo first to monitor safety. If no safety concerns are found after 48 hours, the remaining participants in the group will receive their doses. | H11: 0 | I11: #VALUE! | J11: 0 | K11: 0
A12: <lay terminology for repeat-dose portion of study> | B12: 0 | C12: Paragraph | D12: The SAD portion of this study is a standard design for first-in-human testing with a monoclonal antibody. In addition, a 4-week repeated dose cohort will allow confirmation of the safety, tolerability, and repeat-dose PK and immunogenicity in the target population prior to proceeding to subsequent repeat-dose studies in a patient population. | E12: Protocol Example (28Sep2023) 1 | F12: 0 | G12: 0 | H12: 0 | I12: #VALUE! | J12: 0 | K12: 0
A13: <lay terminology for dosing regimen/duration> | B13: 0 | C13: Paragraph | D13: Following Check-out from the CRU, all participants will return for Follow-up study visits up to 6 weeks post dosing in the first 3 cohorts and 10 weeks post dosing in the remaining cohorts as shown in the Schedule of Assessments | E13: Protocol Example (28Sep2023) 1 | F13: Rewrite the dosing regimen and duration in clear lay terms suitable for an informed consent document. | G13: every other week for 3 doses over up to 6 weeks | H13: 0 | I13: #VALUE! | J13: 0 | K13: 0
A14: <lay terminology for choice of dose for repeat-dose portion of study based on data from SAD portion of study> | B14: 0 | C14: Paragraph | D14: The repeat-dose portion of the study is a double-blind, randomized, placebo-controlled design in 1 cohort of participants with boneitis. All screening tests establishing eligibility will be performed following informed consent and within 35 days prior to study intervention administration. Participants will reside at the CRU from Day 2 to Day 5 and Day 28 to Day 33 and will receive SC 150 mg ABC-123 (6 participants) or placebo (2 participants) every other week for 3 doses. The actual dose and regimen selected for this part of the study will be based on the safety, tolerability, and PK of ABC-123 as determined during the ongoing SAD component of the study. To account for anticipated accumulation, the dose selected for the repeat-dose cohort will not exceed 50% of a dose that has previously been shown to be safe and well tolerated in the single-dose cohort. Sentinel dosing is not required during this part of the study. Participants must not have been enrolled in the SAD component. | E14: Protocol Example (28Sep2023) 1 | F14: Provide a lay summary explaining that the repeat-dose regimen is chosen based on safety, tolerability, and PK data from the SAD portion. | G14: was selected based on safety, tolerability, and PK data from the single ascending dose (SAD) portion of the study | H14: 0 | I14: #VALUE! | J14: 0 | K14: 0
