Workbook

Sheet Evaluation_Data
A1: Placeholder | E1: Instruction | J1: Replacement
A2: Ai detected placeholder | B2: Judgement on AI's Accuracy (feedback by human) | C2: Expected Detection (feedback by human) | E2: Instruction text | F2: Writing instruction | G2: Writing instruction updated? (yes/no) | H2: Updated writing instruction | J2: AI Replaced Text | K2: Judgement on AI's Accuracy (feedback by human) | L2: Expected Detection (feedback by human) | M2: Replacement Element Type | N2: Matched Sources | O2: Matched Sources Reference | P2: Matched Sources Score | Q2: Matched Sources Result | R2: Placeholder Type | S2: Placeholder ID | T2: Placeholder Score | U2: Replacement Score
A3: <Sponsor's Name> | F3: Retrieve details about the sponsor's name for inclusion in inline text, focusing on its role in the Clinical Study Report. | G3: yes | H3: Insert the sponsor's name 'Stendarr, Inc.' inline, ensuring continuity with the surrounding text 'Clinical Study Report'. | J3: Stendarr, Inc. | M3: Paragraph | N3: [{"id": "doc::fd2ccc75:layout::0:para::51", "content": "Similarly, five subjects (13.9%) were discontinued from the study, overall, three from the Treatment group and two from the Placebo group. The most common reason for study discontinuation was death (n=3), all occurring in the Treatment group. One subject in the Placebo group withdrew consent, and one was lost to follow-up. No subjects discontinued due to sponsor decision or unknown reasons.", "index": "section@para", "score": 2.0, "type": "PWR_DROP", "heading_path": ["4. Key Results"], "filename": "Mock_CSR Key messages_with_heading.docx"}, {"id": "doc::fd2ccc75:layout::0:para::7", "content": "Sponsor: Stendarr, Inc.", "index": "section@para", "score": 2.0, "type": "PWR_USED", "heading_path": ["Study Title:"], "filename": "Mock_CSR Key messages_with_heading.docx"}, {"id": "doc::4877313e:layout::0:para::14", "content": "Sponsor Signatory:", "index": "section@para", "score": 2.0, "type": "PWR_DROP", "heading_path": ["TITLE PAGE"], "filename": "Mock_CSR_Protocol.docx"}, {"id": "doc::4877313e:layout::0:para::6", "content": "Acronym: Not applicable Sponsor Name: Stendarr, Inc.", "index": "section@para", "score": 2.0, "type": "PWR_USED", "heading_path": ["TITLE PAGE"], "filename": "Mock_CSR_Protocol.docx"}, {"id": "doc::4877313e:layout::15:para::8", "content": "(6 participants) or placebo (2 participants) on Day 1. To assure safety and tolerability of the starting dose, 2 sentinel participants will be dosed first in Cohort 1 (1 active drug and 1 placebo to maintain study blinding); the remaining Cohort 1 participants may be dosed at least 48 hours later, after initial safety of the sentinel participants is confirmed by the Phase 1 Unit Principal Investigator in consultation with the Sponsor.", "index": "section@para", "score": 2.0, "type": "PWR_DROP", "heading_path": ["Overall Design", "Single Ascending Dose"], "filename": "Mock_CSR_Protocol.docx"}, {"id": "doc::4877313e:layout::22:para::11", "content": "The bioanalytical laboratory personnel responsible for assaying PK samples will be unblinded but will provide ABC-123 concentration data to selected contract research organizations (CRO) and the Sponsor in a blinded manner.", "index": "section@para", "score": 2.0, "type": "PWR_DROP", "heading_path": ["Measures to Minimize Bias: Randomization and Blinding"], "filename": "Mock_CSR_Protocol.docx"}, {"id": "doc::4877313e:layout::22:para::12", "content": "The CRO and Sponsor PK, absorption, distribution, metabolism, and excretion (ADME), biomarker, or clinical scientists who are not directly involved with study management or in direct contact with the site personnel may be unblinded for the purposes of exploratory biomarker evaluation and development of PK and PD response models during the course of the study.", "index": "section@para", "score": 2.0, "type": "PWR_DROP", "heading_path": ["Measures to Minimize Bias: Randomization and Blinding"], "filename": "Mock_CSR_Protocol.docx"}, {"id": "doc::4877313e:layout::22:para::15", "content": "The treatment assignment should be unblinded at the clinic only in the case of an emergency, when knowledge of the study intervention assignment is absolutely necessary for the clinical management or welfare of the participant, or where necessary to determine if dose-limiting toxicity (DLT) criteria have been met (). Breaking of the blind at the clinic under any other circumstances will be considered a protocol deviation. The Investigator is strongly encouraged to contact the Sponsor before unblinding the study intervention assignment prior to the scheduled assessment of tolerance and safety data unless there is an urgent safety issue that must be addressed as a priority. If the blind is broken for any reason, the Investigator must notify the Sponsor within 24 hours, and an SAE form must be completed, if appropriate. In addition, the Investigator will record the date and reason for revealing the blinded study intervention assignment for that participant in the source documents and appropriate electronic case report form (eCRF) page(s).", "index": "section@para", "score": 2.0, "type": "PWR_DROP", "heading_path": ["Measures to Minimize Bias: Randomization and Blinding"], "filename": "Mock_CSR_Protocol.docx"}, {"id": "doc::4877313e:layout::22:para::5", "content": "The Investigator is responsible for study intervention accountability, reconciliation, and record maintenance (ie, receipt, reconciliation, and final disposition records). The Investigator (or designee) will maintain an accurate record of the study supplies received. In addition, an accurate drug disposition record will be kept, specifying the amount dispensed to each participant and the date of dispensing. This drug accountability record will be available for inspection at any time. At the completion of the study, the original drug accountability record will be available for review by the Sponsor upon request.", "index": "section@para", "score": 2.0, "type": "PWR_DROP", "heading_path": ["Preparation/Handling/Storage/Accountability"], "filename": "Mock_CSR_Protocol.docx"}, {"id": "doc::4877313e:layout::23:para::4", "content": "Dose escalation will proceed in no greater than half-log (approximately 3.3-fold) increments. As described in 1, the Sponsor and Principal Investigator will be responsible for reviewing safety and tolerability data and making dose escalation decisions for each cohort. A smaller dose escalation increment may be chosen for any cohort. A dose escalation increment greater than the planned half-log increment is not permitted.", "index": "section@para", "score": 2.0, "type": "PWR_DROP", "heading_path": ["Dose Modification", "Dose Escalation and Stopping Criteria"], "filename": "Mock_CSR_Protocol.docx"}] | R3: Inline | S3: doc::7cd3e10f:layout::0:header::0::ph::0
A4: <Study Title> | F4: Retrieve detailed information about the study title, ensuring alignment with the placeholder's positional context in the document. | G4: yes | H4: Resolve the placeholder 'Study Title' located at the beginning of the paragraph following the previous paragraph context. Ensure the resolved title matches the explicitly stated study title in the document, and format it as a standalone paragraph. | J4: <p>A First-In-Human, Phase 1, Randomized, Double-Blind, Placebo-Controlled Study to Evaluate the Safety, Tolerability, and Pharmacokinetics of ABC-123 as a Single Dose in Healthy Participants and as Multiple Doses in Participants with Grade 2 Boneitis</p> | M4: Paragraph | N4: [{"id": "doc::fd2ccc75:layout::0:para::1", "content": "Document Title: Clinical Study Report", "index": "section@para", "score": 4.0, "type": "PWR_DROP", "heading_path": [], "filename": "Mock_CSR Key messages_with_heading.docx"}, {"id": "doc::fd2ccc75:layout::0:para::2", "content": "Study Title:\n\n<p style=\"margin-top: 6pt; margin-bottom: 6pt\"><span class=\"Default Paragraph Font font:Times New Roman\">A First-In-Human, Phase 1, Randomized, Double-Blind, Placebo-Controlled Study to Evaluate the Safety, Tolerability, and Pharmacokinetics of ABC-123 as a Single Dose in Healthy Participants and as Multiple Doses in Participants with Grade 2 Boneitis</span></p>\n\n<p style=\"margin-top: 6pt; margin-bottom: 6pt\"><span class=\"Default Paragraph Font font:Times New Roman\"><strong>Protocol No.: </strong></span><span class=\"Default Paragraph Font font:Times New Roman\">SKY-2000-101</span></p>\n\n<p style=\"margin-top: 6pt; margin-bottom: 6pt\"><span class=\"Default Paragraph Font font:Times New Roman\"><strong>Study Drug: </strong></span><span class=\"Default Paragraph Font font:Times New Roman\">ABC-123</span><span class=\"Default Paragraph Font font:Times New Roman\"><strong> </strong></span></p>\n\n<p style=\"margin-top: 6pt; margin-bottom: 6pt\"><span class=\"Default Paragraph Font font:Times New Roman\"><strong>Indication: </strong></span><span class=\"Default Paragraph Font font:Times New Roman\">Grade 2 boneitis</span></p>\n\n<p style=\"margin-top: 6pt; margin-bottom: 6pt\"><span class=\"Default Paragraph Font font:Times New Roman\"><strong>Sponsor: </strong></span><span class=\"Default Paragraph Font font:Times New Roman\">Stendarr, Inc.</span></p>\n\n<p style=\"margin-top: 6pt; margin-bottom: 6pt\"><span class=\"Default Paragraph Font font:Times New Roman\"><strong>Date: </strong></span><span class=\"Default Paragraph Font font:Times New Roman\">DD MM YYYY</span></p>", "index": "section@para", "score": 4.0, "type": "PWR_USED", "heading_path": [], "filename": "Mock_CSR Key messages_with_heading.docx"}, {"id": "doc::4877313e:layout::0:para::1", "content": "Protocol Title: A First-In-Human, Phase 1, Randomized, Double-Blind, Placebo-Controlled Study to Evaluate the Safety, Tolerability, and Pharmacokinetics of ABC-123 as a Single Dose in Healthy Participants and as Multiple Doses in Participants with Grade 2 Boneitis", "index": "section@para", "score": 4.0, "type": "PWR_USED", "heading_path": ["TITLE PAGE"], "filename": "Mock_CSR_Protocol.docx"}, {"id": "doc::4877313e:layout::5:para::2", "content": "Protocol Title: A First-In-Human, Phase 1, Randomized, Double-Blind, Placebo-Controlled Study to Evaluate the Safety, Tolerability, and Pharmacokinetics of ABC-123 as a Single Dose in Healthy Participants and as Multiple Doses in Participants with Grade 2 Boneitis", "index": "section@para", "score": 4.0, "type": "PWR_USED", "heading_path": ["Synopsis"], "filename": "Mock_CSR_Protocol.docx"}, {"id": "doc::fd2ccc75:layout::0:para::0", "content": "Clinical Study Report: Key Message", "index": "section@para", "score": 2.0, "type": "PWR_DROP", "heading_path": [], "filename": "Mock_CSR Key messages_with_heading.docx"}, {"id": "doc::fd2ccc75:layout::0:para::10", "content": "The primary objective of this clinical study was to assess the safety and tolerability after 4 weeks of exposure following single ascending doses of ABC-123", "index": "section@para", "score": 2.0, "type": "PWR_DROP", "heading_path": ["1. Study Objective"], "filename": "Mock_CSR Key messages_with_heading.docx"}, {"id": "doc::fd2ccc75:layout::0:para::11", "content": "The secondary objective of this study:", "index": "section@para", "score": 2.0, "type": "PWR_DROP", "heading_path": ["1. Study Objective"], "filename": "Mock_CSR Key messages_with_heading.docx"}, {"id": "doc::fd2ccc75:layout::0:para::15", "content": "The exploratory objective of this study:", "index": "section@para", "score": 2.0, "type": "PWR_DROP", "heading_path": ["1. Study Objective"], "filename": "Mock_CSR Key messages_with_heading.docx"}, {"id": "doc::fd2ccc75:layout::0:para::24", "content": "2. Study Design Overview\n\n<p style=\"margin-top: 6pt; margin-bottom: 6pt\"><span class=\"Default Paragraph Font font:Times New Roman color:000000\">This study will comprise a SAD escalation component in healthy volunteer participants and a repeat-dose component to confirm repeat-dose safety, tolerability, PK, and immunogenicity in participants with boneitis. It will also explore potential blorp activity, participant selection, PD, and differential response biomarkers. This study will be conducted in a single Phase 1 unit.</span></p>\n\n<p style=\"margin-top: 6pt; margin-bottom: 6pt\"><span class=\"Default Paragraph Font font:Times New Roman color:000000\">Total Participants: 36</span></p>", "index": "section@para", "score": 2.0, "type": "PWR_DROP", "heading_path": [], "filename": "Mock_CSR Key messages_with_heading.docx"}, {"id": "doc::fd2ccc75:layout::0:para::25", "content": "This study will comprise a SAD escalation component in healthy volunteer participants and a repeat-dose component to confirm repeat-dose safety, tolerability, PK, and immunogenicity in participants with boneitis. It will also explore potential blorp activity, participant selection, PD, and differential response biomarkers. This study will be conducted in a single Phase 1 unit.", "index": "section@para", "score": 2.0, "type": "PWR_DROP", "heading_path": ["2. Study Design Overview"], "filename": "Mock_CSR Key messages_with_heading.docx"}] | R4: Paragraph | S4: doc::7cd3e10f:layout::0:para::2::ph::0
A5: <Investigational Drug Name> | F5: Retrieve specific details about the investigational drug name, focusing on TITLE PAGE or Study Title sections. | G5: yes | H5: Resolve the placeholder 'Investigational Drug Name' for the table caption '<Study Title>' with column headers 'Investigational Drug Name:', 'Indication Studied:', and 'Protocol Number:', ensuring the output matches the positional context provided. | J5: ABC-123 | M5: Paragraph | N5: [{"id": "doc::4877313e:layout::0:para::1", "content": "Protocol Title: A First-In-Human, Phase 1, Randomized, Double-Blind, Placebo-Controlled Study to Evaluate the Safety, Tolerability, and Pharmacokinetics of ABC-123 as a Single Dose in Healthy Participants and as Multiple Doses in Participants with Grade 2 Boneitis", "index": "section@para", "score": 10.0, "type": "CNM_ADD", "heading_path": ["TITLE PAGE"], "filename": "Mock_CSR_Protocol.docx"}, {"id": "doc::4877313e:layout::5:para::2", "content": "Protocol Title: A First-In-Human, Phase 1, Randomized, Double-Blind, Placebo-Controlled Study to Evaluate the Safety, Tolerability, and Pharmacokinetics of ABC-123 as a Single Dose in Healthy Participants and as Multiple Doses in Participants with Grade 2 Boneitis", "index": "section@para", "score": 10.0, "type": "CNM_ADD", "heading_path": ["Synopsis"], "filename": "Mock_CSR_Protocol.docx"}, {"id": "doc::fd2ccc75:layout::0:para::1", "content": "Document Title: Clinical Study Report", "index": "section@para", "score": 8.0, "type": "CNM_ADD", "heading_path": [], "filename": "Mock_CSR Key messages_with_heading.docx"}, {"id": "doc::fd2ccc75:layout::0:para::2", "content": "Study Title:\n\n<p style=\"margin-top: 6pt; margin-bottom: 6pt\"><span class=\"Default Paragraph Font font:Times New Roman\">A First-In-Human, Phase 1, Randomized, Double-Blind, Placebo-Controlled Study to Evaluate the Safety, Tolerability, and Pharmacokinetics of ABC-123 as a Single Dose in Healthy Participants and as Multiple Doses in Participants with Grade 2 Boneitis</span></p>\n\n<p style=\"margin-top: 6pt; margin-bottom: 6pt\"><span class=\"Default Paragraph Font font:Times New Roman\"><strong>Protocol No.: </strong></span><span class=\"Default Paragraph Font font:Times New Roman\">SKY-2000-101</span></p>\n\n<p style=\"margin-top: 6pt; margin-bottom: 6pt\"><span class=\"Default Paragraph Font font:Times New Roman\"><strong>Study Drug: </strong></span><span class=\"Default Paragraph Font font:Times New Roman\">ABC-123</span><span class=\"Default Paragraph Font font:Times New Roman\"><strong> </strong></span></p>\n\n<p style=\"margin-top: 6pt; margin-bottom: 6pt\"><span class=\"Default Paragraph Font font:Times New Roman\"><strong>Indication: </strong></span><span class=\"Default Paragraph Font font:Times New Roman\">Grade 2 boneitis</span></p>\n\n<p style=\"margin-top: 6pt; margin-bottom: 6pt\"><span class=\"Default Paragraph Font font:Times New Roman\"><strong>Sponsor: </strong></span><span class=\"Default Paragraph Font font:Times New Roman\">Stendarr, Inc.</span></p>\n\n<p style=\"margin-top: 6pt; margin-bottom: 6pt\"><span class=\"Default Paragraph Font font:Times New Roman\"><strong>Date: </strong></span><span class=\"Default Paragraph Font font:Times New Roman\">DD MM YYYY</span></p>", "index": "section@para", "score": 8.0, "type": "PWR_USED", "heading_path": [], "filename": "Mock_CSR Key messages_with_heading.docx"}, {"id": "doc::fd2ccc75:layout::0:para::68", "content": "No dose-limiting toxicities, or dose reductions due to treatment-emergent adverse events were reported. The study evaluated treatment-emergent adverse events (TEAEs) among participants receiving either the treatment (N=21) or placebo (N=10). Overall, 85.7% of participants in the treatment group experienced at least one TEAE, compared to 50.0% in the placebo group, with a total incidence of 74.2%. Treatment-related TEAEs were reported in 61.9% of participants in the treatment group, while none were observed in the placebo group. Grade 3 or higher TEAEs occurred in 22.6% of the treatment group and 20.0% of the placebo group, accounting for 29.0% of all participants. Serious TEAEs were reported in 22.6% of the treatment group and 20.0% of the placebo group, also totaling 29.0%. Serious treatment-related TEAEs were observed in 23.8% of the treatment group, with none in the placebo group. TEAEs leading to study drug discontinuation occurred in 9.5% of the treatment group and none in the placebo group, representing 6.5% overall. Dose modifications and reductions due to TEAEs were rare, reported in 4.8% and 0% of the treatment group, respectively, with no occurrences in the placebo group. Deaths attributed to TEAEs occurred in 14.2% of the treatment group and none in the placebo group, accounting for 9.7% overall, all of which were classified as treatment-related.", "index": "section@para", "score": 8.0, "type": "CNM_ADD", "heading_path": ["4. Key Results"], "filename": "Mock_CSR Key messages_with_heading.docx"}, {"id": "doc::fd2ccc75:layout::0:para::70", "content": "This study demonstrated that ABC-123 is safe and well-tolerated when administered as a single dose in healthy participants and as multiple doses in participants with Grade 2 Boneitis. No dose-limiting toxicities, or dose reductions due to treatment-emergent adverse events were reported. The study evaluated treatment-emergent adverse events (TEAEs) among participants receiving either the treatment (N=21) or placebo (N=10). Overall, 85.7% of participants in the treatment group experienced at least one TEAE, compared to 50.0% in the placebo group, with a total incidence of 74.2%. Treatment-related TEAEs were reported in 61.9% of participants in the treatment group, while none were observed in the placebo group. Grade 3 or higher TEAEs occurred in 22.6% of the treatment group and 20.0% of the placebo group, accounting for 29.0% of all participants. Serious TEAEs were reported in 22.6% of the treatment group and 20.0% of the placebo group, also totaling 29.0%. Serious treatment-related TEAEs were observed in 23.8% of the treatment group, with none in the placebo group. TEAEs leading to study drug discontinuation occurred in 9.5% of the treatment group and none in the placebo group, representing 6.5% overall. Dose modifications and reductions due to TEAEs were rare, reported in 4.8% and 0% of the treatment group, respectively, with no occurrences in the placebo group. Deaths attributed to TEAEs occurred in 14.2% of the treatment group and none in the placebo group, accounting for 9.7% overall, all of which were classified as treatment-related.", "index": "section@para", "score": 8.0, "type": "CNM_ADD", "heading_path": ["5. Interpretation & Conclusion"], "filename": "Mock_CSR Key messages_with_heading.docx"}, {"id": "doc::4877313e:layout::18:para::26", "content": "Participation in a clinical study involving administration of an investigational drug (new chemical entity) in the past 30 days or 5 half-lives of last dose (whichever is longer) prior to first dosing.", "index": "section@para", "score": 8.0, "type": "PWR_DROP", "heading_path": ["Exclusion Criteria"], "filename": "Mock_CSR_Protocol.docx"}, {"id": "doc::4877313e:layout::0:para::0", "content": "TITLE PAGE\n\n<p style=\"margin-top: 6.15pt\"><span style=\"font-size: 12pt\" class=\"Default Paragraph Font color:000000\"><strong>Protocol Title: </strong></span><span style=\"font-size: 12pt\" class=\"Default Paragraph Font color:000000\">A First-In-Human, Phase 1, Randomized, Double-Blind, Placebo-Controlled Study to Evaluate the Safety, Tolerability, and Pharmacokinetics of ABC-123 as a Single Dose in Healthy Participants and as Multiple Doses in Participants with Grade 2 Boneitis</span></p>\n\n<p style=\"margin-top: 6.3pt\"><span style=\"font-size: 12pt\" class=\"Default Paragraph Font\"><strong>Protocol Number: </strong></span><span style=\"font-size: 12pt\" class=\"Default Paragraph Font\">SKY-2000-101</span></p>\n\n<p style=\"margin-top: 6.15pt\"><span style=\"font-size: 12pt\" class=\"Default Paragraph Font\"><strong>Compound: </strong></span><span style=\"font-size: 12pt\" class=\"Default Paragraph Font\">ABC-123</span></p>\n\n<p style=\"margin-top: 6.2pt\"><span style=\"font-size: 12pt\" class=\"Default Paragraph Font\"><strong>Study Phase: </strong></span><span style=\"font-size: 12pt\" class=\"Default Paragraph Font\">Phase 1</span></p>\n\n<p style=\"margin-top: 6.15pt\"><span style=\"font-size: 12pt\" class=\"Default Paragraph Font color:000000\"><strong>Short Title: </strong></span><span style=\"font-size: 12pt\" class=\"Default Paragraph Font color:000000\">Phase 1 RCT of ABC-123 in healthy participants (SAD) and participants with boneitis (repeat-dose)</span></p>\n\n<p style=\"margin-top: 5.9pt\"><span style=\"font-size: 12pt\" class=\"Default Paragraph Font\"><strong>Acronym: </strong></span><span style=\"font-size: 12pt\" class=\"Default Paragraph Font\">Not applicable </span><span style=\"font-size: 12pt\" class=\"Default Paragraph Font\"><strong>Sponsor Name: </strong></span><span style=\"font-size: 12pt\" class=\"Default Paragraph Font\">Stendarr, Inc.</span></p>\n\n<p style=\"margin-top: 5.9pt\"><span style=\"font-size: 12pt\" class=\"Default Paragraph Font\"> </span><span style=\"font-size: 12pt\" class=\"Default Paragraph Font\"><strong>Legal Registered Address:</strong></span></p>\n\n<p><span style=\"font-size: 12pt\" class=\"Default Paragraph Font color:000000\">123 Fake Street</span></p>\n\n<p><span style=\"font-size: 12pt\" class=\"Default Paragraph Font color:000000\">Anytown, CO</span></p>\n\n<p><span style=\"font-size: 12pt\" class=\"Default Paragraph Font color:000000\">USA 80002</span></p>\n\n<p style=\"margin-top: 6.2pt\"><span style=\"font-size: 12pt\" class=\"Default Paragraph Font\"><strong>Regulatory Agency Identifier Number(s): </strong></span><span style=\"font-size: 12pt\" class=\"Default Paragraph Font\">IND: 123456</span></p>\n\n<p style=\"margin-top: 6.2pt\"><span style=\"font-size: 12pt\" class=\"Default Paragraph Font\"><strong>Amendment Number: 2.0</strong></span></p>\n\n<p style=\"margin-top: 6.1pt\"><span style=\"font-size: 12pt\" class=\"Default Paragraph Font\"><strong>Approval Date: </strong></span><span style=\"font-size: 12pt\" class=\"Default Paragraph Font\">1 March 2023</span></p>\n\n<p style=\"margin-top: 6.1pt\"><span style=\"font-size: 12pt\" class=\"Default Paragraph Font\"><strong>Sponsor Signatory:</strong></span></p>\n\n<p style=\"margin-top: 2.3pt\"><span style=\"font-size: 12pt\" class=\"Default Paragraph Font color:000000\">Karliah N. Gale, MD</span></p>\n\n<p style=\"margin-top: 2.3pt\"><span style=\"font-size: 12pt\" class=\"Default Paragraph Font color:000000\">Medical Director</span></p>", "index": "section@para", "score": 6.0, "type": "PWR_USED", "heading_path": [], "filename": "Mock_CSR_Protocol.docx"}, {"id": "doc::4877313e:layout::21:para::1", "content": "Study intervention is defined as any investigational intervention(s), marketed product(s), or placebo intended to be administered to a study participant according to the study protocol.", "index": "section@para", "score": 6.0, "type": "PWR_DROP", "heading_path": ["STUDY INTERVENTION"], "filename": "Mock_CSR_Protocol.docx"}, {"id": "doc::4877313e:layout::22:para::15", "content": "The treatment assignment should be unblinded at the clinic only in the case of an emergency, when knowledge of the study intervention assignment is absolutely necessary for the clinical management or welfare of the participant, or where necessary to determine if dose-limiting toxicity (DLT) criteria have been met (). Breaking of the blind at the clinic under any other circumstances will be considered a protocol deviation. The Investigator is strongly encouraged to contact the Sponsor before unblinding the study intervention assignment prior to the scheduled assessment of tolerance and safety data unless there is an urgent safety issue that must be addressed as a priority. If the blind is broken for any reason, the Investigator must notify the Sponsor within 24 hours, and an SAE form must be completed, if appropriate. In addition, the Investigator will record the date and reason for revealing the blinded study intervention assignment for that participant in the source documents and appropriate electronic case report form (eCRF) page(s).", "index": "section@para", "score": 6.0, "type": "PWR_DROP", "heading_path": ["Measures to Minimize Bias: Randomization and Blinding"], "filename": "Mock_CSR_Protocol.docx"}] | R5: KeyValue | S5: doc::7cd3e10f:layout::0:table::3:row::0:cell::1::ph::0
A6: <Insert Disease Name> | F6: Search for the disease or indication studied in the clinical trial, specifically under the TITLE PAGE section or related headings. | G6: yes | H6: Resolve the placeholder '<Insert Disease Name>' in the context of the TITLE PAGE section, under the table caption '<Study Title>' and column headers 'Investigational Drug Name', 'Indication Studied', and 'Protocol Number', ensuring it aligns with the row labeled 'Indication Studied'. | J6: Grade 2 boneitis | M6: Paragraph | N6: [{"id": "doc::4877313e:layout::0:para::1", "content": "Protocol Title: A First-In-Human, Phase 1, Randomized, Double-Blind, Placebo-Controlled Study to Evaluate the Safety, Tolerability, and Pharmacokinetics of ABC-123 as a Single Dose in Healthy Participants and as Multiple Doses in Participants with Grade 2 Boneitis", "index": "section@para", "score": 10.0, "type": "CNM_ADD", "heading_path": ["TITLE PAGE"], "filename": "Mock_CSR_Protocol.docx"}, {"id": "doc::4877313e:layout::5:para::2", "content": "Protocol Title: A First-In-Human, Phase 1, Randomized, Double-Blind, Placebo-Controlled Study to Evaluate the Safety, Tolerability, and Pharmacokinetics of ABC-123 as a Single Dose in Healthy Participants and as Multiple Doses in Participants with Grade 2 Boneitis", "index": "section@para", "score": 10.0, "type": "CNM_ADD", "heading_path": ["Synopsis"], "filename": "Mock_CSR_Protocol.docx"}, {"id": "doc::fd2ccc75:layout::0:para::1", "content": "Document Title: Clinical Study Report", "index": "section@para", "score": 8.0, "type": "CNM_ADD", "heading_path": [], "filename": "Mock_CSR Key messages_with_heading.docx"}, {"id": "doc::fd2ccc75:layout::0:para::2", "content": "Study Title:\n\n<p style=\"margin-top: 6pt; margin-bottom: 6pt\"><span class=\"Default Paragraph Font font:Times New Roman\">A First-In-Human, Phase 1, Randomized, Double-Blind, Placebo-Controlled Study to Evaluate the Safety, Tolerability, and Pharmacokinetics of ABC-123 as a Single Dose in Healthy Participants and as Multiple Doses in Participants with Grade 2 Boneitis</span></p>\n\n<p style=\"margin-top: 6pt; margin-bottom: 6pt\"><span class=\"Default Paragraph Font font:Times New Roman\"><strong>Protocol No.: </strong></span><span class=\"Default Paragraph Font font:Times New Roman\">SKY-2000-101</span></p>\n\n<p style=\"margin-top: 6pt; margin-bottom: 6pt\"><span class=\"Default Paragraph Font font:Times New Roman\"><strong>Study Drug: </strong></span><span class=\"Default Paragraph Font font:Times New Roman\">ABC-123</span><span class=\"Default Paragraph Font font:Times New Roman\"><strong> </strong></span></p>\n\n<p style=\"margin-top: 6pt; margin-bottom: 6pt\"><span class=\"Default Paragraph Font font:Times New Roman\"><strong>Indication: </strong></span><span class=\"Default Paragraph Font font:Times New Roman\">Grade 2 boneitis</span></p>\n\n<p style=\"margin-top: 6pt; margin-bottom: 6pt\"><span class=\"Default Paragraph Font font:Times New Roman\"><strong>Sponsor: </strong></span><span class=\"Default Paragraph Font font:Times New Roman\">Stendarr, Inc.</span></p>\n\n<p style=\"margin-top: 6pt; margin-bottom: 6pt\"><span class=\"Default Paragraph Font font:Times New Roman\"><strong>Date: </strong></span><span class=\"Default Paragraph Font font:Times New Roman\">DD MM YYYY</span></p>", "index": "section@para", "score": 8.0, "type": "PWR_USED", "heading_path": [], "filename": "Mock_CSR Key messages_with_heading.docx"}, {"id": "doc::fd2ccc75:layout::0:para::50", "content": "A total of 36 subjects were enrolled in the study, with 24 assigned to the Treatment group and 12 to the Placebo group. At the time of analysis, 31 subjects (86.1%) remained ongoing in the study and on treatment (87.5% in the Treatment group and 83.3% in the Placebo group). Five subjects (13.9%) discontinued study treatment, three (12.5%) from the Treatment group and two (16.7%) from the Placebo group. The reasons for treatment discontinuation included adverse events (n=2, Treatment group), progressive disease (n=1, Treatment group), patient withdrawal of informed consent (n=1, Placebo group), and other reasons (n=1, Placebo group).", "index": "section@para", "score": 6.0, "type": "CNM_ADD", "heading_path": ["4. Key Results"], "filename": "Mock_CSR Key messages_with_heading.docx"}, {"id": "doc::fd2ccc75:layout::0:para::68", "content": "No dose-limiting toxicities, or dose reductions due to treatment-emergent adverse events were reported. The study evaluated treatment-emergent adverse events (TEAEs) among participants receiving either the treatment (N=21) or placebo (N=10). Overall, 85.7% of participants in the treatment group experienced at least one TEAE, compared to 50.0% in the placebo group, with a total incidence of 74.2%. Treatment-related TEAEs were reported in 61.9% of participants in the treatment group, while none were observed in the placebo group. Grade 3 or higher TEAEs occurred in 22.6% of the treatment group and 20.0% of the placebo group, accounting for 29.0% of all participants. Serious TEAEs were reported in 22.6% of the treatment group and 20.0% of the placebo group, also totaling 29.0%. Serious treatment-related TEAEs were observed in 23.8% of the treatment group, with none in the placebo group. TEAEs leading to study drug discontinuation occurred in 9.5% of the treatment group and none in the placebo group, representing 6.5% overall. Dose modifications and reductions due to TEAEs were rare, reported in 4.8% and 0% of the treatment group, respectively, with no occurrences in the placebo group. Deaths attributed to TEAEs occurred in 14.2% of the treatment group and none in the placebo group, accounting for 9.7% overall, all of which were classified as treatment-related.", "index": "section@para", "score": 6.0, "type": "CNM_ADD", "heading_path": ["4. Key Results"], "filename": "Mock_CSR Key messages_with_heading.docx"}, {"id": "doc::fd2ccc75:layout::0:para::70", "content": "This study demonstrated that ABC-123 is safe and well-tolerated when administered as a single dose in healthy participants and as multiple doses in participants with Grade 2 Boneitis. No dose-limiting toxicities, or dose reductions due to treatment-emergent adverse events were reported. The study evaluated treatment-emergent adverse events (TEAEs) among participants receiving either the treatment (N=21) or placebo (N=10). Overall, 85.7% of participants in the treatment group experienced at least one TEAE, compared to 50.0% in the placebo group, with a total incidence of 74.2%. Treatment-related TEAEs were reported in 61.9% of participants in the treatment group, while none were observed in the placebo group. Grade 3 or higher TEAEs occurred in 22.6% of the treatment group and 20.0% of the placebo group, accounting for 29.0% of all participants. Serious TEAEs were reported in 22.6% of the treatment group and 20.0% of the placebo group, also totaling 29.0%. Serious treatment-related TEAEs were observed in 23.8% of the treatment group, with none in the placebo group. TEAEs leading to study drug discontinuation occurred in 9.5% of the treatment group and none in the placebo group, representing 6.5% overall. Dose modifications and reductions due to TEAEs were rare, reported in 4.8% and 0% of the treatment group, respectively, with no occurrences in the placebo group. Deaths attributed to TEAEs occurred in 14.2% of the treatment group and none in the placebo group, accounting for 9.7% overall, all of which were classified as treatment-related.", "index": "section@para", "score": 6.0, "type": "CNM_ADD", "heading_path": ["5. Interpretation & Conclusion"], "filename": "Mock_CSR Key messages_with_heading.docx"}, {"id": "doc::4877313e:layout::0:para::0", "content": "TITLE PAGE\n\n<p style=\"margin-top: 6.15pt\"><span style=\"font-size: 12pt\" class=\"Default Paragraph Font color:000000\"><strong>Protocol Title: </strong></span><span style=\"font-size: 12pt\" class=\"Default Paragraph Font color:000000\">A First-In-Human, Phase 1, Randomized, Double-Blind, Placebo-Controlled Study to Evaluate the Safety, Tolerability, and Pharmacokinetics of ABC-123 as a Single Dose in Healthy Participants and as Multiple Doses in Participants with Grade 2 Boneitis</span></p>\n\n<p style=\"margin-top: 6.3pt\"><span style=\"font-size: 12pt\" class=\"Default Paragraph Font\"><strong>Protocol Number: </strong></span><span style=\"font-size: 12pt\" class=\"Default Paragraph Font\">SKY-2000-101</span></p>\n\n<p style=\"margin-top: 6.15pt\"><span style=\"font-size: 12pt\" class=\"Default Paragraph Font\"><strong>Compound: </strong></span><span style=\"font-size: 12pt\" class=\"Default Paragraph Font\">ABC-123</span></p>\n\n<p style=\"margin-top: 6.2pt\"><span style=\"font-size: 12pt\" class=\"Default Paragraph Font\"><strong>Study Phase: </strong></span><span style=\"font-size: 12pt\" class=\"Default Paragraph Font\">Phase 1</span></p>\n\n<p style=\"margin-top: 6.15pt\"><span style=\"font-size: 12pt\" class=\"Default Paragraph Font color:000000\"><strong>Short Title: </strong></span><span style=\"font-size: 12pt\" class=\"Default Paragraph Font color:000000\">Phase 1 RCT of ABC-123 in healthy participants (SAD) and participants with boneitis (repeat-dose)</span></p>\n\n<p style=\"margin-top: 5.9pt\"><span style=\"font-size: 12pt\" class=\"Default Paragraph Font\"><strong>Acronym: </strong></span><span style=\"font-size: 12pt\" class=\"Default Paragraph Font\">Not applicable </span><span style=\"font-size: 12pt\" class=\"Default Paragraph Font\"><strong>Sponsor Name: </strong></span><span style=\"font-size: 12pt\" class=\"Default Paragraph Font\">Stendarr, Inc.</span></p>\n\n<p style=\"margin-top: 5.9pt\"><span style=\"font-size: 12pt\" class=\"Default Paragraph Font\"> </span><span style=\"font-size: 12pt\" class=\"Default Paragraph Font\"><strong>Legal Registered Address:</strong></span></p>\n\n<p><span style=\"font-size: 12pt\" class=\"Default Paragraph Font color:000000\">123 Fake Street</span></p>\n\n<p><span style=\"font-size: 12pt\" class=\"Default Paragraph Font color:000000\">Anytown, CO</span></p>\n\n<p><span style=\"font-size: 12pt\" class=\"Default Paragraph Font color:000000\">USA 80002</span></p>\n\n<p style=\"margin-top: 6.2pt\"><span style=\"font-size: 12pt\" class=\"Default Paragraph Font\"><strong>Regulatory Agency Identifier Number(s): </strong></span><span style=\"font-size: 12pt\" class=\"Default Paragraph Font\">IND: 123456</span></p>\n\n<p style=\"margin-top: 6.2pt\"><span style=\"font-size: 12pt\" class=\"Default Paragraph Font\"><strong>Amendment Number: 2.0</strong></span></p>\n\n<p style=\"margin-top: 6.1pt\"><span style=\"font-size: 12pt\" class=\"Default Paragraph Font\"><strong>Approval Date: </strong></span><span style=\"font-size: 12pt\" class=\"Default Paragraph Font\">1 March 2023</span></p>\n\n<p style=\"margin-top: 6.1pt\"><span style=\"font-size: 12pt\" class=\"Default Paragraph Font\"><strong>Sponsor Signatory:</strong></span></p>\n\n<p style=\"margin-top: 2.3pt\"><span style=\"font-size: 12pt\" class=\"Default Paragraph Font color:000000\">Karliah N. Gale, MD</span></p>\n\n<p style=\"margin-top: 2.3pt\"><span style=\"font-size: 12pt\" class=\"Default Paragraph Font color:000000\">Medical Director</span></p>", "index": "section@para", "score": 6.0, "type": "CNM_ADD", "heading_path": [], "filename": "Mock_CSR_Protocol.docx"}, {"id": "doc::4877313e:layout::12:para::18", "content": "ABC-123 has not been studied in humans; therefore, the risk-benefit analysis considerations are based on nonclinical data and reports in the literature on similar therapies. The benefits to participants in the ABC-123 clinical program may include contributing to the process of developing new therapies in an area of unmet need and medical evaluations/assessments associated with study procedures (eg, physical examination); participants with boneitis due to lurgi may or may not experience an impact on progression of the disease. The risks of participation are primarily those associated with adverse reactions to the investigational medicinal product, although there may also be some discomfort associated with subcutaneous (SC) injections or study procedures (eg, blood collection).", "index": "section@para", "score": 6.0, "type": "PWR_DROP", "heading_path": ["Benefit/Risk Assessment"], "filename": "Mock_CSR_Protocol.docx"}, {"id": "doc::4877313e:layout::18:para::26", "content": "Participation in a clinical study involving administration of an investigational drug (new chemical entity) in the past 30 days or 5 half-lives of last dose (whichever is longer) prior to first dosing.", "index": "section@para", "score": 6.0, "type": "PWR_DROP", "heading_path": ["Exclusion Criteria"], "filename": "Mock_CSR_Protocol.docx"}] | R6: KeyValue | S6: doc::7cd3e10f:layout::0:table::3:row::0:cell::1::ph::1
A7: <Protocol Identification (Code or Number)> | F7: Retrieve details specifically related to protocol identification, including codes or numbers, ensuring alignment with the table caption 'Study Title' and the context of the TITLE PAGE. | G7: yes | H7: Resolve the placeholder '<Protocol Identification (Code or Number)>' by referencing the protocol number provided under the TITLE PAGE section, within the context of the table caption 'Study Title' and the column headers 'Investigational Drug Name', 'Indication Studied', and 'Protocol Number'. | J7: SKY-2000-101 | M7: Paragraph | N7: [{"id": "doc::4877313e:layout::0:para::1", "content": "Protocol Title: A First-In-Human, Phase 1, Randomized, Double-Blind, Placebo-Controlled Study to Evaluate the Safety, Tolerability, and Pharmacokinetics of ABC-123 as a Single Dose in Healthy Participants and as Multiple Doses in Participants with Grade 2 Boneitis", "index": "section@para", "score": 12.0, "type": "CNM_ADD", "heading_path": ["TITLE PAGE"], "filename": "Mock_CSR_Protocol.docx"}, {"id": "doc::4877313e:layout::5:para::2", "content": "Protocol Title: A First-In-Human, Phase 1, Randomized, Double-Blind, Placebo-Controlled Study to Evaluate the Safety, Tolerability, and Pharmacokinetics of ABC-123 as a Single Dose in Healthy Participants and as Multiple Doses in Participants with Grade 2 Boneitis", "index": "section@para", "score": 12.0, "type": "CNM_ADD", "heading_path": ["Synopsis"], "filename": "Mock_CSR_Protocol.docx"}, {"id": "doc::72df3a00:layout::22:para::0", "content": "Protocol Version No: Final Version 2.0, 01MAR2023 Study Code: ST-4536", "index": "section@para", "score": 10.0, "type": "CNM_ADD", "heading_path": ["SOFTWARE"], "filename": "Mock SAP _03Jun2026.docx"}, {"id": "doc::72df3a00:layout::28:para::1", "content": "Protocol Version No: Final Version 2.0, 01MAR2023 Study Code: ST-4536", "index": "section@para", "score": 10.0, "type": "CNM_ADD", "heading_path": ["SOFTWARE"], "filename": "Mock SAP _03Jun2026.docx"}, {"id": "doc::fd2ccc75:layout::0:para::1", "content": "Document Title: Clinical Study Report", "index": "section@para", "score": 8.0, "type": "CNM_ADD", "heading_path": [], "filename": "Mock_CSR Key messages_with_heading.docx"}, {"id": "doc::fd2ccc75:layout::0:para::2", "content": "Study Title:\n\n<p style=\"margin-top: 6pt; margin-bottom: 6pt\"><span class=\"Default Paragraph Font font:Times New Roman\">A First-In-Human, Phase 1, Randomized, Double-Blind, Placebo-Controlled Study to Evaluate the Safety, Tolerability, and Pharmacokinetics of ABC-123 as a Single Dose in Healthy Participants and as Multiple Doses in Participants with Grade 2 Boneitis</span></p>\n\n<p style=\"margin-top: 6pt; margin-bottom: 6pt\"><span class=\"Default Paragraph Font font:Times New Roman\"><strong>Protocol No.: </strong></span><span class=\"Default Paragraph Font font:Times New Roman\">SKY-2000-101</span></p>\n\n<p style=\"margin-top: 6pt; margin-bottom: 6pt\"><span class=\"Default Paragraph Font font:Times New Roman\"><strong>Study Drug: </strong></span><span class=\"Default Paragraph Font font:Times New Roman\">ABC-123</span><span class=\"Default Paragraph Font font:Times New Roman\"><strong> </strong></span></p>\n\n<p style=\"margin-top: 6pt; margin-bottom: 6pt\"><span class=\"Default Paragraph Font font:Times New Roman\"><strong>Indication: </strong></span><span class=\"Default Paragraph Font font:Times New Roman\">Grade 2 boneitis</span></p>\n\n<p style=\"margin-top: 6pt; margin-bottom: 6pt\"><span class=\"Default Paragraph Font font:Times New Roman\"><strong>Sponsor: </strong></span><span class=\"Default Paragraph Font font:Times New Roman\">Stendarr, Inc.</span></p>\n\n<p style=\"margin-top: 6pt; margin-bottom: 6pt\"><span class=\"Default Paragraph Font font:Times New Roman\"><strong>Date: </strong></span><span class=\"Default Paragraph Font font:Times New Roman\">DD MM YYYY</span></p>", "index": "section@para", "score": 8.0, "type": "PWR_USED", "heading_path": [], "filename": "Mock_CSR Key messages_with_heading.docx"}, {"id": "doc::4877313e:layout::0:para::2", "content": "Protocol Number: SKY-2000-101", "index": "section@para", "score": 8.0, "type": "PWR_USED", "heading_path": ["TITLE PAGE"], "filename": "Mock_CSR_Protocol.docx"}, {"id": "doc::4877313e:layout::21:para::1", "content": "Study intervention is defined as any investigational intervention(s), marketed product(s), or placebo intended to be administered to a study participant according to the study protocol.", "index": "section@para", "score": 8.0, "type": "PWR_DROP", "heading_path": ["STUDY INTERVENTION"], "filename": "Mock_CSR_Protocol.docx"}, {"id": "doc::4877313e:layout::22:para::15", "content": "The treatment assignment should be unblinded at the clinic only in the case of an emergency, when knowledge of the study intervention assignment is absolutely necessary for the clinical management or welfare of the participant, or where necessary to determine if dose-limiting toxicity (DLT) criteria have been met (). Breaking of the blind at the clinic under any other circumstances will be considered a protocol deviation. The Investigator is strongly encouraged to contact the Sponsor before unblinding the study intervention assignment prior to the scheduled assessment of tolerance and safety data unless there is an urgent safety issue that must be addressed as a priority. If the blind is broken for any reason, the Investigator must notify the Sponsor within 24 hours, and an SAE form must be completed, if appropriate. In addition, the Investigator will record the date and reason for revealing the blinded study intervention assignment for that participant in the source documents and appropriate electronic case report form (eCRF) page(s).", "index": "section@para", "score": 8.0, "type": "PWR_DROP", "heading_path": ["Measures to Minimize Bias: Randomization and Blinding"], "filename": "Mock_CSR_Protocol.docx"}, {"id": "doc::4877313e:layout::28:para::1", "content": "Study procedures and their timing are summarized in the SoA (). Protocol waivers or exemptions are not allowed.", "index": "section@para", "score": 8.0, "type": "PWR_DROP", "heading_path": ["STUDY ASSESSMENTS AND PROCEDURES"], "filename": "Mock_CSR_Protocol.docx"}] | R7: KeyValue | S7: doc::7cd3e10f:layout::0:table::3:row::0:cell::1::ph::2
A8: <Investigational Drug Name> | F8: Retrieve details about the investigational drug name specifically for the TITLE PAGE context and related study materials. | G8: yes | H8: Resolve the placeholder 'Investigational Drug Name' for the table caption 'Study Title' under the parent heading 'TITLE PAGE', ensuring alignment with the column header 'Investigational Drug Name:' and contextual references. | J8: ABC-123 | M8: Paragraph | N8: [{"id": "doc::4877313e:layout::0:para::1", "content": "Protocol Title: A First-In-Human, Phase 1, Randomized, Double-Blind, Placebo-Controlled Study to Evaluate the Safety, Tolerability, and Pharmacokinetics of ABC-123 as a Single Dose in Healthy Participants and as Multiple Doses in Participants with Grade 2 Boneitis", "index": "section@para", "score": 10.0, "type": "CNM_ADD", "heading_path": ["TITLE PAGE"], "filename": "Mock_CSR_Protocol.docx"}, {"id": "doc::4877313e:layout::5:para::2", "content": "Protocol Title: A First-In-Human, Phase 1, Randomized, Double-Blind, Placebo-Controlled Study to Evaluate the Safety, Tolerability, and Pharmacokinetics of ABC-123 as a Single Dose in Healthy Participants and as Multiple Doses in Participants with Grade 2 Boneitis", "index": "section@para", "score": 10.0, "type": "CNM_ADD", "heading_path": ["Synopsis"], "filename": "Mock_CSR_Protocol.docx"}, {"id": "doc::fd2ccc75:layout::0:para::1", "content": "Document Title: Clinical Study Report", "index": "section@para", "score": 8.0, "type": "CNM_ADD", "heading_path": [], "filename": "Mock_CSR Key messages_with_heading.docx"}, {"id": "doc::fd2ccc75:layout::0:para::2", "content": "Study Title:\n\n<p style=\"margin-top: 6pt; margin-bottom: 6pt\"><span class=\"Default Paragraph Font font:Times New Roman\">A First-In-Human, Phase 1, Randomized, Double-Blind, Placebo-Controlled Study to Evaluate the Safety, Tolerability, and Pharmacokinetics of ABC-123 as a Single Dose in Healthy Participants and as Multiple Doses in Participants with Grade 2 Boneitis</span></p>\n\n<p style=\"margin-top: 6pt; margin-bottom: 6pt\"><span class=\"Default Paragraph Font font:Times New Roman\"><strong>Protocol No.: </strong></span><span class=\"Default Paragraph Font font:Times New Roman\">SKY-2000-101</span></p>\n\n<p style=\"margin-top: 6pt; margin-bottom: 6pt\"><span class=\"Default Paragraph Font font:Times New Roman\"><strong>Study Drug: </strong></span><span class=\"Default Paragraph Font font:Times New Roman\">ABC-123</span><span class=\"Default Paragraph Font font:Times New Roman\"><strong> </strong></span></p>\n\n<p style=\"margin-top: 6pt; margin-bottom: 6pt\"><span class=\"Default Paragraph Font font:Times New Roman\"><strong>Indication: </strong></span><span class=\"Default Paragraph Font font:Times New Roman\">Grade 2 boneitis</span></p>\n\n<p style=\"margin-top: 6pt; margin-bottom: 6pt\"><span class=\"Default Paragraph Font font:Times New Roman\"><strong>Sponsor: </strong></span><span class=\"Default Paragraph Font font:Times New Roman\">Stendarr, Inc.</span></p>\n\n<p style=\"margin-top: 6pt; margin-bottom: 6pt\"><span class=\"Default Paragraph Font font:Times New Roman\"><strong>Date: </strong></span><span class=\"Default Paragraph Font font:Times New Roman\">DD MM YYYY</span></p>", "index": "section@para", "score": 8.0, "type": "PWR_USED", "heading_path": [], "filename": "Mock_CSR Key messages_with_heading.docx"}, {"id": "doc::fd2ccc75:layout::0:para::68", "content": "No dose-limiting toxicities, or dose reductions due to treatment-emergent adverse events were reported. The study evaluated treatment-emergent adverse events (TEAEs) among participants receiving either the treatment (N=21) or placebo (N=10). Overall, 85.7% of participants in the treatment group experienced at least one TEAE, compared to 50.0% in the placebo group, with a total incidence of 74.2%. Treatment-related TEAEs were reported in 61.9% of participants in the treatment group, while none were observed in the placebo group. Grade 3 or higher TEAEs occurred in 22.6% of the treatment group and 20.0% of the placebo group, accounting for 29.0% of all participants. Serious TEAEs were reported in 22.6% of the treatment group and 20.0% of the placebo group, also totaling 29.0%. Serious treatment-related TEAEs were observed in 23.8% of the treatment group, with none in the placebo group. TEAEs leading to study drug discontinuation occurred in 9.5% of the treatment group and none in the placebo group, representing 6.5% overall. Dose modifications and reductions due to TEAEs were rare, reported in 4.8% and 0% of the treatment group, respectively, with no occurrences in the placebo group. Deaths attributed to TEAEs occurred in 14.2% of the treatment group and none in the placebo group, accounting for 9.7% overall, all of which were classified as treatment-related.", "index": "section@para", "score": 8.0, "type": "CNM_ADD", "heading_path": ["4. Key Results"], "filename": "Mock_CSR Key messages_with_heading.docx"}, {"id": "doc::fd2ccc75:layout::0:para::70", "content": "This study demonstrated that ABC-123 is safe and well-tolerated when administered as a single dose in healthy participants and as multiple doses in participants with Grade 2 Boneitis. No dose-limiting toxicities, or dose reductions due to treatment-emergent adverse events were reported. The study evaluated treatment-emergent adverse events (TEAEs) among participants receiving either the treatment (N=21) or placebo (N=10). Overall, 85.7% of participants in the treatment group experienced at least one TEAE, compared to 50.0% in the placebo group, with a total incidence of 74.2%. Treatment-related TEAEs were reported in 61.9% of participants in the treatment group, while none were observed in the placebo group. Grade 3 or higher TEAEs occurred in 22.6% of the treatment group and 20.0% of the placebo group, accounting for 29.0% of all participants. Serious TEAEs were reported in 22.6% of the treatment group and 20.0% of the placebo group, also totaling 29.0%. Serious treatment-related TEAEs were observed in 23.8% of the treatment group, with none in the placebo group. TEAEs leading to study drug discontinuation occurred in 9.5% of the treatment group and none in the placebo group, representing 6.5% overall. Dose modifications and reductions due to TEAEs were rare, reported in 4.8% and 0% of the treatment group, respectively, with no occurrences in the placebo group. Deaths attributed to TEAEs occurred in 14.2% of the treatment group and none in the placebo group, accounting for 9.7% overall, all of which were classified as treatment-related.", "index": "section@para", "score": 8.0, "type": "CNM_ADD", "heading_path": ["5. Interpretation & Conclusion"], "filename": "Mock_CSR Key messages_with_heading.docx"}, {"id": "doc::4877313e:layout::18:para::26", "content": "Participation in a clinical study involving administration of an investigational drug (new chemical entity) in the past 30 days or 5 half-lives of last dose (whichever is longer) prior to first dosing.", "index": "section@para", "score": 8.0, "type": "CNM_ADD", "heading_path": ["Exclusion Criteria"], "filename": "Mock_CSR_Protocol.docx"}, {"id": "doc::4877313e:layout::0:para::0", "content": "TITLE PAGE\n\n<p style=\"margin-top: 6.15pt\"><span style=\"font-size: 12pt\" class=\"Default Paragraph Font color:000000\"><strong>Protocol Title: </strong></span><span style=\"font-size: 12pt\" class=\"Default Paragraph Font color:000000\">A First-In-Human, Phase 1, Randomized, Double-Blind, Placebo-Controlled Study to Evaluate the Safety, Tolerability, and Pharmacokinetics of ABC-123 as a Single Dose in Healthy Participants and as Multiple Doses in Participants with Grade 2 Boneitis</span></p>\n\n<p style=\"margin-top: 6.3pt\"><span style=\"font-size: 12pt\" class=\"Default Paragraph Font\"><strong>Protocol Number: </strong></span><span style=\"font-size: 12pt\" class=\"Default Paragraph Font\">SKY-2000-101</span></p>\n\n<p style=\"margin-top: 6.15pt\"><span style=\"font-size: 12pt\" class=\"Default Paragraph Font\"><strong>Compound: </strong></span><span style=\"font-size: 12pt\" class=\"Default Paragraph Font\">ABC-123</span></p>\n\n<p style=\"margin-top: 6.2pt\"><span style=\"font-size: 12pt\" class=\"Default Paragraph Font\"><strong>Study Phase: </strong></span><span style=\"font-size: 12pt\" class=\"Default Paragraph Font\">Phase 1</span></p>\n\n<p style=\"margin-top: 6.15pt\"><span style=\"font-size: 12pt\" class=\"Default Paragraph Font color:000000\"><strong>Short Title: </strong></span><span style=\"font-size: 12pt\" class=\"Default Paragraph Font color:000000\">Phase 1 RCT of ABC-123 in healthy participants (SAD) and participants with boneitis (repeat-dose)</span></p>\n\n<p style=\"margin-top: 5.9pt\"><span style=\"font-size: 12pt\" class=\"Default Paragraph Font\"><strong>Acronym: </strong></span><span style=\"font-size: 12pt\" class=\"Default Paragraph Font\">Not applicable </span><span style=\"font-size: 12pt\" class=\"Default Paragraph Font\"><strong>Sponsor Name: </strong></span><span style=\"font-size: 12pt\" class=\"Default Paragraph Font\">Stendarr, Inc.</span></p>\n\n<p style=\"margin-top: 5.9pt\"><span style=\"font-size: 12pt\" class=\"Default Paragraph Font\"> </span><span style=\"font-size: 12pt\" class=\"Default Paragraph Font\"><strong>Legal Registered Address:</strong></span></p>\n\n<p><span style=\"font-size: 12pt\" class=\"Default Paragraph Font color:000000\">123 Fake Street</span></p>\n\n<p><span style=\"font-size: 12pt\" class=\"Default Paragraph Font color:000000\">Anytown, CO</span></p>\n\n<p><span style=\"font-size: 12pt\" class=\"Default Paragraph Font color:000000\">USA 80002</span></p>\n\n<p style=\"margin-top: 6.2pt\"><span style=\"font-size: 12pt\" class=\"Default Paragraph Font\"><strong>Regulatory Agency Identifier Number(s): </strong></span><span style=\"font-size: 12pt\" class=\"Default Paragraph Font\">IND: 123456</span></p>\n\n<p style=\"margin-top: 6.2pt\"><span style=\"font-size: 12pt\" class=\"Default Paragraph Font\"><strong>Amendment Number: 2.0</strong></span></p>\n\n<p style=\"margin-top: 6.1pt\"><span style=\"font-size: 12pt\" class=\"Default Paragraph Font\"><strong>Approval Date: </strong></span><span style=\"font-size: 12pt\" class=\"Default Paragraph Font\">1 March 2023</span></p>\n\n<p style=\"margin-top: 6.1pt\"><span style=\"font-size: 12pt\" class=\"Default Paragraph Font\"><strong>Sponsor Signatory:</strong></span></p>\n\n<p style=\"margin-top: 2.3pt\"><span style=\"font-size: 12pt\" class=\"Default Paragraph Font color:000000\">Karliah N. Gale, MD</span></p>\n\n<p style=\"margin-top: 2.3pt\"><span style=\"font-size: 12pt\" class=\"Default Paragraph Font color:000000\">Medical Director</span></p>", "index": "section@para", "score": 6.0, "type": "PWR_USED", "heading_path": [], "filename": "Mock_CSR_Protocol.docx"}, {"id": "doc::4877313e:layout::21:para::1", "content": "Study intervention is defined as any investigational intervention(s), marketed product(s), or placebo intended to be administered to a study participant according to the study protocol.", "index": "section@para", "score": 6.0, "type": "PWR_DROP", "heading_path": ["STUDY INTERVENTION"], "filename": "Mock_CSR_Protocol.docx"}, {"id": "doc::4877313e:layout::22:para::15", "content": "The treatment assignment should be unblinded at the clinic only in the case of an emergency, when knowledge of the study intervention assignment is absolutely necessary for the clinical management or welfare of the participant, or where necessary to determine if dose-limiting toxicity (DLT) criteria have been met (). Breaking of the blind at the clinic under any other circumstances will be considered a protocol deviation. The Investigator is strongly encouraged to contact the Sponsor before unblinding the study intervention assignment prior to the scheduled assessment of tolerance and safety data unless there is an urgent safety issue that must be addressed as a priority. If the blind is broken for any reason, the Investigator must notify the Sponsor within 24 hours, and an SAE form must be completed, if appropriate. In addition, the Investigator will record the date and reason for revealing the blinded study intervention assignment for that participant in the source documents and appropriate electronic case report form (eCRF) page(s).", "index": "section@para", "score": 6.0, "type": "PWR_DROP", "heading_path": ["Measures to Minimize Bias: Randomization and Blinding"], "filename": "Mock_CSR_Protocol.docx"}] | R8: KeyValue | S8: doc::7cd3e10f:layout::0:table::3:row::0:cell::2::ph::0
