Workbook
Name AnnualCostOfTime_BuyCar: #REF!
Name AnnualCostOfTime_Ridesharing: #REF!
Name AnnualFareCost: #REF!
Name AnnualFuelCost: #REF!
Name AnnualPurchaseCost: #REF!
Name AnnualUsageCost: #REF!
Name AveDistancePerTrip: Summary!$D$24
Name AveParkingTime: #REF!
Name AverageTripsPerDay: Summary!$D$19
Name AveSurgeMultiplier: #REF!
Name AveTimePerTrip: Summary!$D$20
Name AveWaitTime: #REF!
Name BaseFare: #REF!
Name DistanceFare: #REF!
Name DownPayment: #REF!
Name FuelCost: #REF!
Name FuelEfficiency: #REF!
Name GarageExpenses: #REF!
Name GaragePropertyTax: #REF!
Name Insurance: #REF!
Name InterestRate: #REF!
Name LoanTerm: #REF!
Name MaintenanceAndRepairs: #REF!
Name Parking: #REF!
Name PercentRideDuringSurge: #REF!
Name PriceOfCar: #REF!
Name ProductivePercent: #REF!
Name PurchaseFees: #REF!
Name RatePerHour: Summary!$D$65
Name RegistrationAndTaxes: #REF!
Name SalesTax: #REF!
Name TimeFare: #REF!
Name TotalMileage: Summary!#REF!

Sheet Summary
B2: ICF FULL Report
C4: Report ID | D4: CSR_08/04/2026 | G4: Generated doc
C5: AW version | D5: Sandbox | G5: Clean Ver
C6: Generated By | D6: Paras | G6: Date | J6: 46120
G7: No. of Pages
C8: Remarks | G8: Generation Time
C11: Destination Template | E11: .docx - 2 pages
C12: Source Documents | D12: Protocol Example (28Sep2023) 1
C13: Doc Type | D13: .docx | E13: .docx | G13: .rtf
C14: No. of Pages
B16: Placeholder Analysis | G16: Accuracy Analysis
B17: Column1 | C17: Column2 | D17: Column3 | E17: Column4
D18: Count | E18: Replaced
C19: Total Placeholders Identified | D19: =COUNTA(QA!A3:'QA'!A49) -> 47 | E19: =COUNTA(QA!G3:'QA'!G48) -> 32
C20: Unique Placeholders | D20: =COUNTA(_xlfn.UNIQUE(QA!A3:'QA'!A49)) -> 26
C21: Paragraph Placeholders | D21: =COUNTIF(QA!C3:'QA'!C49, "=Paragraph") -> 10
C22: Inline Placeholders | D22: =COUNTIF(QA!C3:'QA'!C49, "=Inline") -> 0
C23: List Placeholders | D23: =COUNTIF(QA!C3:'QA'!C49, "=List") -> 0
C24: Table Placeholders | D24: =COUNTIF(QA!C3:'QA'!C49, "=Table") -> 6 | E24: 3
C25: Multi Tables Placeholders | D25: =COUNTIF(QA!C3:'QA'!C49, "=MultiTable") -> 0
C26: Figure Placeholders | D26: =COUNTIF(QA!C3:'QA'!C49, "=Figure") -> 0
B28: Inline placeholders
B29: Column1 | C29: Column2 | D29: Column3 | E29: Column4
C30: Total Inline placeholders | D30: =COUNTA(Inline!A3:'Inline'!A500) -> 1 | E30: QA/Debugging ↓ | G30: Remarks
C31: Inline Replaced | D31: =COUNTA(Inline!G3:'Inline'!G500) -> 0 | E31: =D31/D30 -> 0
C32: Inline Replaced correctly | D32: =COUNTIF(Inline!J3:J27, ">0.7") -> 0 | E32: =D32*100%/D31 -> #DIV/0!
C33: Inline Formatted correctly | D33: =D32 -> 0 | E33: =D33*100%/D32 -> #DIV/0!
B35: Paragraph placeholders
B36: Column1 | C36: Column2 | D36: Column3 | E36: Column4
C37: Total paragraph placeholders | D37: =COUNTA(Paragraph!A3:'Paragraph'!A500) -> 45 | E37: QA/Debugging ↓ | G37: Remarks
C38: Paragraphs Replaced | D38: =COUNTA(Paragraph!G3:'Paragraph'!G500) -> 45 | E38: =Table685[[#This Row],[Column3]]/D37 -> 1
C39: Paragraphs Replaced correctly | D39: =COUNTIF(Paragraph!J3:J27, ">0.7") -> 2 | E39: =Table685[[#This Row],[Column3]]/D38 -> 0.044444444
C40: Paragraphs Formatted correctly | D40: =D39 -> 2 | E40: =Table685[[#This Row],[Column3]]/D39 -> 1
B42: KeyValue placeholders
B43: Column1 | C43: Column2 | D43: Column3 | E43: Column4
C44: Total paragraph placeholders | D44: =COUNTA(KeyValue!A3:'KeyValue'!A500) -> 50 | E44: QA/Debugging ↓ | G44: Remarks
C45: KeyValues Replaced | D45: =(COUNTA(_xlfn.UNIQUE(KeyValue!G3:'KeyValue'!G500))) -> 16 | E45: =Table687[[#This Row],[Column3]]/D44 -> 0.32
C46: KeyValues Replaced correctly | D46: =COUNTIF(KeyValue!J3:J27, ">0.7") -> 13 | E46: =Table687[[#This Row],[Column3]]/D45 -> 0.8125
C47: keyValues Formatted correctly | D47: =D46 -> 13 | E47: =Table687[[#This Row],[Column3]]/D46 -> 1
B49: Table placeholders
...

Sheet QA
R1: Table | AF1: Paragraph
A2: Placeholder | B2: Column1 | C2: Placeholder Type | D2: Expected Value | E2: Source Document | F2: Writing instruction | G2: AI Replaced Text | H2: Ai detected Source | I2: Matching Accuracy | J2: Similarity Score | K2: Source Match | R2: Expected Rows | S2: Expected Colunms | T2: Expected Footnote | U2: AI replaced Rows | V2: AI replaced Colunms | W2: AI replaced Footnotes | X2: Alignment(yes/no) | Z2: Number of point | AA2: AI Number of point | AB2: Point matching(yes/no) | AC2: Status(with formula) | AD2: Status(human) | AF2: Header Availablity | AG2: AI Header Availablity | AH2: Status(True/false) | AI2: Content matching status
A3: <Sponsor Name> | C3: KeyValue | D3: Stendarr, Inc. | E3: Protocol Example (28Sep2023) 1 | F3: Insert the official sponsor name in line with protocol header formatting. | G3: Stendarr, Inc. | I3: {=_xldudf_BOARDFLARE_FMATCH(G3,D3)} -> #VALUE! | J3: =IF(M3>O3, M3,O3) -> 0.99 | L3: {=_xldudf_BOARDFLARE_FMATCH(G3,D3)} -> #VALUE! | M3: {=_FV(L3,"Similarity",TRUE)} -> 0.99 | N3: {=_xldudf_BOARDFLARE_FMATCH(D3,G3)} -> #VALUE! | O3: {=_FV(N3,"Similarity",TRUE)} -> 0.85
A4: <Protocol Number> | C4: KeyValue | D4: SKY-2000-101 | E4: Protocol Example (28Sep2023) 1 | F4: Insert the official protocol number in the format used in the source document. | G4: SKY-2000-101 | I4: {=_xldudf_BOARDFLARE_FMATCH(G4,D4)} -> #VALUE! | J4: =IF(M4>O4, M4,O4) -> 1 | L4: {=_xldudf_BOARDFLARE_FMATCH(G4,D4)} -> #VALUE! | M4: {=_FV(L4,"Similarity",TRUE)} -> 1 | N4: {=_xldudf_BOARDFLARE_FMATCH(D4,G4)} -> #VALUE! | O4: {=_FV(N4,"Similarity",TRUE)} -> 0.92
A5: <Principal Investigator Name> | C5: KeyValue | D5: Karliah N. Gale, MD​profe​ | E5: Protocol Example (28Sep2023) 1 | I5: {=_xldudf_BOARDFLARE_FMATCH(G5,D5)} -> #VALUE! | J5: =IF(M5>O5, M5,O5) -> 0 | L5: {=_xldudf_BOARDFLARE_FMATCH(G5,D5)} -> #VALUE! | M5: {=_FV(L5,"Similarity",TRUE)} -> 0 | N5: {=_xldudf_BOARDFLARE_FMATCH(D5,G5)} -> #VALUE! | O5: {=_FV(N5,"Similarity",TRUE)} -> 0
A6: <IRB Company Name> | C6: KeyValue | D6: Stendarr, Inc. | E6: Protocol Example (28Sep2023) 1 | F6: Insert the IRB company name in a concise, inline format. | G6: Stendarr, Inc. | I6: {=_xldudf_BOARDFLARE_FMATCH(G6,D6)} -> #VALUE! | J6: =IF(M6>O6, M6,O6) -> 0.99 | L6: {=_xldudf_BOARDFLARE_FMATCH(G6,D6)} -> #VALUE! | M6: {=_FV(L6,"Similarity",TRUE)} -> 0.99 | N6: {=_xldudf_BOARDFLARE_FMATCH(D6,G6)} -> #VALUE! | O6: {=_FV(N6,"Similarity",TRUE)} -> 0.85
A7: <Sponsor> | C7: KeyValue | D7: Stendarr, Inc. | E7: Protocol Example (28Sep2023) 1 | F7: Insert the sponsor's name in line with the protocol header formatting. | G7: Stendarr, Inc. | I7: {=_xldudf_BOARDFLARE_FMATCH(G7,D7)} -> #VALUE! | J7: =IF(M7>O7, M7,O7) -> 0.99 | L7: {=_xldudf_BOARDFLARE_FMATCH(G7,D7)} -> #VALUE! | M7: {=_FV(L7,"Similarity",TRUE)} -> 0.99 | N7: {=_xldudf_BOARDFLARE_FMATCH(D7,G7)} -> #VALUE! | O7: {=_FV(N7,"Similarity",TRUE)} -> 0.85
A8: <Full protocol title> | C8: Paragraph | D8: A First-In-Human, Phase 1, Randomized, Double-Blind, Placebo-Controlled Study to Evaluate the Safety, Tolerability, and Pharmacokinetics of ABC-123 as a Single Dose in Healthy Participants and as Multiple Doses in Participants with Grade 2 Boneitis | E8: Protocol Example (28Sep2023) 1 | F8: Insert the full protocol title verbatim, maintaining inline continuity. | G8: A First-In-Human, Phase 1, Randomized, Double-Blind, Placebo-Controlled Study to Evaluate the Safety, Tolerability, and Pharmacokinetics of ABC-123 as a Single Dose in Healthy Participants and as Multiple Doses in Participants with Grade 2 Boneitis | I8: {=_xldudf_BOARDFLARE_FMATCH(G8,D8)} -> #VALUE! | J8: =IF(M8>O8, M8,O8) -> 0.61 | L8: {=_xldudf_BOARDFLARE_FMATCH(G8,D8)} -> #VALUE! | M8: {=_FV(L8,"Similarity",TRUE)} -> 0.61 | N8: {=_xldudf_BOARDFLARE_FMATCH(D8,G8)} -> #VALUE! | O8: {=_FV(N8,"Similarity",TRUE)} -> 0.6 | AF8: yes | AG8: yes | AH8: =AF8=AG8 -> TRUE | AI8: =Table113[[#This Row],[Expected Value]]=Table113[[#This Row],[AI Replaced Text]] -> FALSE
A9: <Protocol Number> | C9: KeyValue | D9: SKY-2000-101 | E9: Protocol Example (28Sep2023) 1 | F9: Insert the official protocol number in the format used in the source document. | G9: SKY-2000-101 | I9: {=_xldudf_BOARDFLARE_FMATCH(G9,D9)} -> #VALUE! | J9: =IF(M9>O9, M9,O9) -> 1 | L9: {=_xldudf_BOARDFLARE_FMATCH(G9,D9)} -> #VALUE! | M9: {=_FV(L9,"Similarity",TRUE)} -> 1 | N9: {=_xldudf_BOARDFLARE_FMATCH(D9,G9)} -> #VALUE! | O9: {=_FV(N9,"Similarity",TRUE)} -> 0.92
A10: <Principal Investigator Name> | C10: KeyValue | D10: Karliah N. Gale, MD​profe​ | E10: Protocol Example (28Sep2023) 1 | I10: {=_xldudf_BOARDFLARE_FMATCH(G10,D10)} -> #VALUE! | J10: =IF(M10>O10, M10,O10) -> 0 | L10: {=_xldudf_BOARDFLARE_FMATCH(G10,D10)} -> #VALUE! | M10: {=_FV(L10,"Similarity",TRUE)} -> 0 | N10: {=_xldudf_BOARDFLARE_FMATCH(D10,G10)} -> #VALUE! | O10: {=_FV(N10,"Similarity",TRUE)} -> 0
A11: <Telephone> | C11: KeyValue | D11: 555-999-1111 | E11: Protocol Example (28Sep2023) 1 | F11: Insert the Principal Investigator's telephone number in standard format after 'Telephone:'. | I11: {=_xldudf_BOARDFLARE_FMATCH(G11,D11)} -> #VALUE! | J11: =IF(M11>O11, M11,O11) -> 0 | L11: {=_xldudf_BOARDFLARE_FMATCH(G11,D11)} -> #VALUE! | M11: {=_FV(L11,"Similarity",TRUE)} -> 0 | N11: {=_xldudf_BOARDFLARE_FMATCH(D11,G11)} -> #VALUE! | O11: {=_FV(N11,"Similarity",TRUE)} -> 0 | AH11: =AF11=AG11 -> TRUE | AI11: =O11=R11 -> TRUE
A12: <Address> | C12: KeyValue | D12: 123 Fake Street, Anytown, CO, USA 80002 | E12: Protocol Example (28Sep2023) 1 | F12: Insert the registered address in standard mailing format, maintaining inline continuity. | G12: 123 Fake Street, Anytown, CO, USA 80002 | I12: {=_xldudf_BOARDFLARE_FMATCH(G12,D12)} -> #VALUE! | J12: =IF(M12>O12, M12,O12) -> 0.93 | L12: {=_xldudf_BOARDFLARE_FMATCH(G12,D12)} -> #VALUE! | M12: {=_FV(L12,"Similarity",TRUE)} -> 0.93 | N12: {=_xldudf_BOARDFLARE_FMATCH(D12,G12)} -> #VALUE! | O12: {=_FV(N12,"Similarity",TRUE)} -> 0.79 | AH12: =AF12=AG12 -> TRUE | AI12: =O12=R12 -> FALSE
A13: <Sponsor Name> | C13: KeyValue | D13: Stendarr, Inc. | E13: Protocol Example (28Sep2023) 1 | F13: Insert the official sponsor name in line with protocol header formatting. | G13: Stendarr, Inc. | I13: {=_xldudf_BOARDFLARE_FMATCH(G13,D13)} -> #VALUE! | J13: =IF(M13>O13, M13,O13) -> 0.99 | L13: {=_xldudf_BOARDFLARE_FMATCH(G13,D13)} -> #VALUE! | M13: {=_FV(L13,"Similarity",TRUE)} -> 0.99 | N13: {=_xldudf_BOARDFLARE_FMATCH(D13,G13)} -> #VALUE! | O13: {=_FV(N13,"Similarity",TRUE)} -> 0.85 | AH13: =AF13=AG13 -> TRUE | AI13: =O13=R13 -> FALSE
A14: <Protocol Number> | C14: KeyValue | D14: SKY-2000-101 | E14: Protocol Example (28Sep2023) 1 | F14: Insert the official protocol number in the format used in the source document. | G14: SKY-2000-101 | I14: {=_xldudf_BOARDFLARE_FMATCH(G14,D14)} -> #VALUE! | J14: =IF(M14>O14, M14,O14) -> 1 | L14: {=_xldudf_BOARDFLARE_FMATCH(G14,D14)} -> #VALUE! | M14: {=_FV(L14,"Similarity",TRUE)} -> 1 | N14: {=_xldudf_BOARDFLARE_FMATCH(D14,G14)} -> #VALUE! | O14: {=_FV(N14,"Similarity",TRUE)} -> 0.92
A15: <Principal Investigator Name> | C15: KeyValue | D15: Karliah N. Gale, MD​profe​ | E15: Protocol Example (28Sep2023) 1 | I15: {=_xldudf_BOARDFLARE_FMATCH(G15,D15)} -> #VALUE! | J15: =IF(M15>O15, M15,O15) -> 0 | L15: {=_xldudf_BOARDFLARE_FMATCH(G15,D15)} -> #VALUE! | M15: {=_FV(L15,"Similarity",TRUE)} -> 0 | N15: {=_xldudf_BOARDFLARE_FMATCH(D15,G15)} -> #VALUE! | O15: {=_FV(N15,"Similarity",TRUE)} -> 0
A16: <IRB Company Name> | C16: KeyValue | D16: Stendarr, Inc. | E16: Protocol Example (28Sep2023) 1 | F16: Insert the IRB company name in a concise, inline format. | G16: Stendarr, Inc. | I16: {=_xldudf_BOARDFLARE_FMATCH(G16,D16)} -> #VALUE! | J16: =IF(M16>O16, M16,O16) -> 0.99 | L16: {=_xldudf_BOARDFLARE_FMATCH(G16,D16)} -> #VALUE! | M16: {=_FV(L16,"Similarity",TRUE)} -> 0.99 | N16: {=_xldudf_BOARDFLARE_FMATCH(D16,G16)} -> #VALUE! | O16: {=_FV(N16,"Similarity",TRUE)} -> 0.85 | AH16: =AF16=AG16 -> TRUE | AI16: =O16=R16 -> FALSE
A17: <disease> | C17: KeyValue | D17: Boneitis | E17: Protocol Example (28Sep2023) 1 | I17: {=_xldudf_BOARDFLARE_FMATCH(G17,D17)} -> #VALUE! | J17: =IF(M17>O17, M17,O17) -> 0 | L17: {=_xldudf_BOARDFLARE_FMATCH(G17,D17)} -> #VALUE! | M17: {=_FV(L17,"Similarity",TRUE)} -> 0 | N17: {=_xldudf_BOARDFLARE_FMATCH(D17,G17)} -> #VALUE! | O17: {=_FV(N17,"Similarity",TRUE)} -> 0
A18: <brief lay description of disease> | C18: Paragraph | D18: ABC-123 is intended for use in patients with boneitis, a disease that causes bones to change shape or disappear. | E18: Protocol Example (28Sep2023) 1 | F18: Provide a brief, clear lay description of boneitis to fit seamlessly within the sentence. | G18: a disease that causes bones to change shape or disappear | I18: {=_xldudf_BOARDFLARE_FMATCH(G18,D18)} -> #VALUE! | J18: =IF(M18>O18, M18,O18) -> 0.79 | L18: {=_xldudf_BOARDFLARE_FMATCH(G18,D18)} -> #VALUE! | M18: {=_FV(L18,"Similarity",TRUE)} -> 0.79 | N18: {=_xldudf_BOARDFLARE_FMATCH(D18,G18)} -> #VALUE! | O18: {=_FV(N18,"Similarity",TRUE)} -> 0 | AF18: yes | AG18: yes | AH18: =AF18=AG18 -> TRUE | AI18: =Table113[[#This Row],[Expected Value]]=Table113[[#This Row],[AI Replaced Text]] -> FALSE
A19: <type of study (eg, first-in-human, Phase 1, Phase 2)> | C19: Paragraph | D19: The SAD portion of this study is a standard design for first-in-human testing with a monoclonal antibody. In addition, a 4-week repeated dose cohort will allow confirmation of the safety, tolerability, and repeat-dose PK and immunogenicity in the target population prior to proceeding to subsequent repeat-dose studies in a patient population. | E19: Protocol Example (28Sep2023) 1 | F19: Provide the study type in concise, inline format (e.g., first-in-human, Phase 1) to maintain paragraph continuity. | G19: first-in-human, Phase 1 | I19: {=_xldudf_BOARDFLARE_FMATCH(G19,D19)} -> #VALUE! | J19: =IF(M19>O19, M19,O19) -> 0 | L19: {=_xldudf_BOARDFLARE_FMATCH(G19,D19)} -> #VALUE! | M19: {=_FV(L19,"Similarity",TRUE)} -> 0 | N19: {=_xldudf_BOARDFLARE_FMATCH(D19,G19)} -> #VALUE! | O19: {=_FV(N19,"Similarity",TRUE)} -> 0 | AF19: yes | AG19: no | AH19: =AF19=AG19 -> FALSE | AI19: =Table113[[#This Row],[Expected Value]]=Table113[[#This Row],[AI Replaced Text]] -> FALSE
A20: <XX participants> | C20: KeyValue | D20: 56 participants | E20: Protocol Example (28Sep2023) 1 | F20: Provide the maximum number of participants expected in this study, formatted for inline continuity. | G20: up to 28 participants | I20: {=_xldudf_BOARDFLARE_FMATCH(G20,D20)} -> #VALUE! | J20: =IF(M20>O20, M20,O20) -> 0.57 | L20: {=_xldudf_BOARDFLARE_FMATCH(G20,D20)} -> #VALUE! | M20: {=_FV(L20,"Similarity",TRUE)} -> 0.57 | N20: {=_xldudf_BOARDFLARE_FMATCH(D20,G20)} -> #VALUE! | O20: {=_FV(N20,"Similarity",TRUE)} -> 0.55 | AF20: yes
A21: <Brief lay description of study design including purpose/objectives> | C21: Table | D21: Objectives/Endpoints: The following objectives and endpoints will be evaluated in healthy participants during the SAD component of the study and in participants with boneitis in the repeat-dose component of the study. Objectives Endpoints Primary To assess the safety and tolerability after 4 weeks of exposure following single ascending doses of ABC-123 Number of participants with serious and other nonserious AEs Secondary To assess the safety and tolerability following repeated doses over 4 weeks of ABC-123 Number of participants with serious and other nonserious AEs To characterize PK of ABC-123 following single ascending doses Cmax and AUClast To characterize the PK of ABC-123 following repeated doses Cmax and AUClast Exploratory To explore additional PK characteristics of ABC-123 following single ascending doses Tmax, Clast, Tlast, AUCinf, CL, V, and t1/2 To explore additional PK characteristics of ABC-123 following repeated doses Tmax, Clast, Tlast, AUCinf, CL, V, and t1/2 To explore effects of ABC-123 on clinical laboratory assessments, 12-lead ECG, and vital signs following single ascending doses Incidence of clinically significant changes in laboratory parameters, 12-lead ECG parameters, and vital signs measurements To explore effects of ABC-123 on clinical laboratory assessments, 12-lead ECG, and vital signs following repeated doses Incidence of clinically significant changes in laboratory parameters, 12-lead ECG parameters, and vital signs measurements To explore the impact of ADA on the PK profile of ABC-123 following single ascending doses Impact of ADA on AUC or impact on overall exposure of ABC-123 To explore the impact of ADA on the PK profile of ABC-123 following repeated doses Impact of ADA on AUC or impact on overall exposure of ABC-123 To explore the effects on eating behavior in participants following single ascending doses of ABC-123 Hunger, satiety, and appetite VAS scores Abbreviations: ADA = antidrug antibodies; AE = adverse event. | E21: Protocol Example (28Sep2023) 1 | F21: Write a brief lay description of the study design, purpose, and objectives suitable for participant information. | G21: <li>This study is designed to test ABC-123, a new therapy, in healthy volunteers and participants with boneitis.</li><li>The purpose is to evaluate safety, tolerability, and pharmacodynamic effects of ABC-123.</li><li>The study includes a single ascending dose (SAD) portion that is double-blind, randomized, and placebo-controlled.</li><liParticipants may help advance treatment options for boneitis and contribute to medical research.</li> | I21: {=_xldudf_BOARDFLARE_FMATCH(G21,D21)} -> #VALUE! | J21: =IF(M21>O21, M21,O21) -> 0 | L21: {=_xldudf_BOARDFLARE_FMATCH(G21,D21)} -> #VALUE! | M21: {=_FV(L21,"Similarity",TRUE)} -> 0 | N21: {=_xldudf_BOARDFLARE_FMATCH(D21,G21)} -> #VALUE! | O21: {=_FV(N21,"Similarity",TRUE)} -> 0 | R21: 16 | S21: 2 | T21: Abbreviations: ADA = antidrug antibodies; AE = adverse event. | U21: NA | V21: NA | W21: NA | X21: no | AF21: yes
A22: <lay terminology for SAD portion of study> | C22: Paragraph | D22: All screening tests establishing eligibility will be performed following informed consent and within 35 days prior to study intervention administration. Participants will reside at the CRU from Day 2 to Day 5 and Day 28 to Day 33 and will receive SC 150 mg ABC-123 (6 participants) or placebo (2 participants) every other week for 3 doses. The actual dose and regimen selected for this part of the study will be based on the safety, tolerability, and PK of ABC-123 as determined during the ongoing SAD component of the study. To account for anticipated accumulation, the dose selected for the repeat-dose cohort will not exceed 50% of a dose that has previously been shown to be safe and well tolerated in the single-dose cohort. Sentinel dosing is not required during this part of the study. Participants must not have been enrolled in the SAD component. | E22: Protocol Example (28Sep2023) 1 | F22: Provide a concise lay term for the SAD portion of the study, matching the flow for an inline reference. | G22: the single-dose part of the study | I22: {=_xldudf_BOARDFLARE_FMATCH(G22,D22)} -> #VALUE! | J22: =IF(M22>O22, M22,O22) -> 0 | L22: {=_xldudf_BOARDFLARE_FMATCH(G22,D22)} -> #VALUE! | M22: {=_FV(L22,"Similarity",TRUE)} -> 0 | N22: {=_xldudf_BOARDFLARE_FMATCH(D22,G22)} -> #VALUE! | O22: {=_FV(N22,"Similarity",TRUE)} -> 0 | AF22: yes | AG22: no | AH22: =AF22=AG22 -> FALSE | AI22: =Table113[[#This Row],[Expected Value]]=Table113[[#This Row],[AI Replaced Text]] -> FALSE
A23: <XX applicable time unit> | C23: KeyValue | D23: 5 week | E23: Protocol Example (28Sep2023) 1 | F23: Replace the placeholder with the estimated total time commitment (in appropriate units) for study participation. | G23: 2 to 4 weeks | I23: {=_xldudf_BOARDFLARE_FMATCH(G23,D23)} -> #VALUE! | J23: =IF(M23>O23, M23,O23) -> 0.59 | L23: {=_xldudf_BOARDFLARE_FMATCH(G23,D23)} -> #VALUE! | M23: {=_FV(L23,"Similarity",TRUE)} -> 0 | N23: {=_xldudf_BOARDFLARE_FMATCH(D23,G23)} -> #VALUE! | O23: {=_FV(N23,"Similarity",TRUE)} -> 0.59 | AF23: yes
A24: <lay terminology for route of administration of study drug> | C24: Table | D24: Arm Name ABC-123 Placebo Intervention Name ABC-123 Placebo (blinded) Type Blorp inductor NA Dose Formulation Injectable solution Injectable solution Unit Dose Strength(s) 150 mg/mL Matching placebo Dosage Level(s) SAD 5 mg with approximate half-log escalations NA Repeat-dose Proposed dose level: 150 mg every other week for 3 doses (to be confirmed based on SAD data) NA Route of Administration Subcutaneous Subcutaneous Use Experimental Placebo IMP and NIMP IMP IMP Sourcing Provided centrally by the Sponsor Provided centrally by the Sponsor Packaging and Labeling ABC-123 will be provided in glass vials. Each vial will be labeled as required per FDA requirements. Placebo will be provided in matching glass vials. Each vial will be labeled per FDA requirements. | E24: Protocol Example (28Sep2023) 1 | F24: Replace with a lay term for subcutaneous administration of the study drug. | G24: shot under the skin | I24: {=_xldudf_BOARDFLARE_FMATCH(G24,D24)} -> #VALUE! | J24: =IF(M24>O24, M24,O24) -> 0 | L24: {=_xldudf_BOARDFLARE_FMATCH(G24,D24)} -> #VALUE! | M24: {=_FV(L24,"Similarity",TRUE)} -> 0 | N24: {=_xldudf_BOARDFLARE_FMATCH(D24,G24)} -> #VALUE! | O24: {=_FV(N24,"Similarity",TRUE)} -> 0 | R24: 13 | S24: 3 | T24: Abbreviations: FDA = Food and Drug Administration; IMP = investigational medicinal product; NA = not applicable; NIMP = noninvestigational medicinal product. | U24: NA | V24: NA | W24: NA | X24: no | AF24: yes
A25: <study drug ID> | C25: KeyValue | D25: ABC-123 | E25: Protocol Example (28Sep2023) 1 | I25: {=_xldudf_BOARDFLARE_FMATCH(G25,D25)} -> #VALUE! | J25: =IF(M25>O25, M25,O25) -> 0 | L25: {=_xldudf_BOARDFLARE_FMATCH(G25,D25)} -> #VALUE! | M25: {=_FV(L25,"Similarity",TRUE)} -> 0 | N25: {=_xldudf_BOARDFLARE_FMATCH(D25,G25)} -> #VALUE! | O25: {=_FV(N25,"Similarity",TRUE)} -> 0 | AF25: yes
A26: <lay terminology for repeat-dose portion of study> | C26: Paragraph | D26: The SAD portion of this study is a standard design for first-in-human testing with a monoclonal antibody. In addition, a 4-week repeated dose cohort will allow confirmation of the safety, tolerability, and repeat-dose PK and immunogenicity in the target population prior to proceeding to subsequent repeat-dose studies in a patient population. | E26: Protocol Example (28Sep2023) 1 | I26: {=_xldudf_BOARDFLARE_FMATCH(G26,D26)} -> #VALUE! | J26: =IF(M26>O26, M26,O26) -> 0 | L26: {=_xldudf_BOARDFLARE_FMATCH(G26,D26)} -> #VALUE! | M26: {=_FV(L26,"Similarity",TRUE)} -> 0 | N26: {=_xldudf_BOARDFLARE_FMATCH(D26,G26)} -> #VALUE! | O26: {=_FV(N26,"Similarity",TRUE)} -> 0 | AF26: yes | AG26: no | AH26: =AF26=AG26 -> FALSE | AI26: =Table113[[#This Row],[Expected Value]]=Table113[[#This Row],[AI Replaced Text]] -> FALSE
A27: <XX applicable time unit> | C27: KeyValue | D27: 5 week | E27: Protocol Example (28Sep2023) 1 | F27: Replace the placeholder with the estimated total time commitment (in appropriate units) for study participation. | G27: 2 to 4 weeks | I27: {=_xldudf_BOARDFLARE_FMATCH(G27,D27)} -> #VALUE! | J27: =IF(M27>O27, M27,O27) -> 0.59 | L27: {=_xldudf_BOARDFLARE_FMATCH(G27,D27)} -> #VALUE! | M27: {=_FV(L27,"Similarity",TRUE)} -> 0 | N27: {=_xldudf_BOARDFLARE_FMATCH(D27,G27)} -> #VALUE! | O27: {=_FV(N27,"Similarity",TRUE)} -> 0.59 | AF27: yes
A28: <lay terminology for route of administration of study drug> | C28: Table | D28: Arm Name ABC-123 Placebo Intervention Name ABC-123 Placebo (blinded) Type Blorp inductor NA Dose Formulation Injectable solution Injectable solution Unit Dose Strength(s) 150 mg/mL Matching placebo Dosage Level(s) SAD 5 mg with approximate half-log escalations NA Repeat-dose Proposed dose level: 150 mg every other week for 3 doses (to be confirmed based on SAD data) NA Route of Administration Subcutaneous Subcutaneous Use Experimental Placebo IMP and NIMP IMP IMP Sourcing Provided centrally by the Sponsor Provided centrally by the Sponsor Packaging and Labeling ABC-123 will be provided in glass vials. Each vial will be labeled as required per FDA requirements. Placebo will be provided in matching glass vials. Each vial will be labeled per FDA requirements. | E28: Protocol Example (28Sep2023) 1 | F28: Replace with a lay term for subcutaneous administration of the study drug. | G28: shot under the skin | I28: {=_xldudf_BOARDFLARE_FMATCH(G28,D28)} -> #VALUE! | J28: =IF(M28>O28, M28,O28) -> 0 | L28: {=_xldudf_BOARDFLARE_FMATCH(G28,D28)} -> #VALUE! | M28: {=_FV(L28,"Similarity",TRUE)} -> 0 | N28: {=_xldudf_BOARDFLARE_FMATCH(D28,G28)} -> #VALUE! | O28: {=_FV(N28,"Similarity",TRUE)} -> 0 | R28: 13 | S28: 3 | T28: Abbreviations: FDA = Food and Drug Administration; IMP = investigational medicinal product; NA = not applicable; NIMP = noninvestigational medicinal product. | U28: NA | V28: NA | W28: NA | X28: no | AF28: yes
A29: <study drug ID> | C29: KeyValue | D29: ABC-123 | E29: Protocol Example (28Sep2023) 1 | I29: {=_xldudf_BOARDFLARE_FMATCH(G29,D29)} -> #VALUE! | J29: =IF(M29>O29, M29,O29) -> 0 | L29: {=_xldudf_BOARDFLARE_FMATCH(G29,D29)} -> #VALUE! | M29: {=_FV(L29,"Similarity",TRUE)} -> 0 | N29: {=_xldudf_BOARDFLARE_FMATCH(D29,G29)} -> #VALUE! | O29: {=_FV(N29,"Similarity",TRUE)} -> 0 | AF29: yes | AH29: =AF29=AG29 -> FALSE | AI29: =O29=R29 -> TRUE
A30: <lay terminology for dosing regimen/duration> | C30: Paragraph | D30: Following Check-out from the CRU, all participants will return for Follow-up study visits up to 6 weeks post dosing in the first 3 cohorts and 10 weeks post dosing in the remaining cohorts as shown in the Schedule of Assessments | E30: Protocol Example (28Sep2023) 1 | F30: Rewrite the dosing regimen and duration in clear lay terms suitable for an informed consent document. | G30: every other week for 3 doses over up to 6 weeks | I30: {=_xldudf_BOARDFLARE_FMATCH(G30,D30)} -> #VALUE! | J30: =IF(M30>O30, M30,O30) -> 0 | L30: {=_xldudf_BOARDFLARE_FMATCH(G30,D30)} -> #VALUE! | M30: {=_FV(L30,"Similarity",TRUE)} -> 0 | N30: {=_xldudf_BOARDFLARE_FMATCH(D30,G30)} -> #VALUE! | O30: {=_FV(N30,"Similarity",TRUE)} -> 0 | AF30: yes | AG30: yes | AH30: =AF30=AG30 -> TRUE | AI30: =Table113[[#This Row],[Expected Value]]=Table113[[#This Row],[AI Replaced Text]] -> FALSE
A31: <CRO Name> | E31: Protocol Example (28Sep2023) 1 | I31: {=_xldudf_BOARDFLARE_FMATCH(G31,D31)} -> #VALUE! | J31: =IF(M31>O31, M31,O31) -> 0 | L31: {=_xldudf_BOARDFLARE_FMATCH(G31,D31)} -> #VALUE! | M31: {=_FV(L31,"Similarity",TRUE)} -> 0 | N31: {=_xldudf_BOARDFLARE_FMATCH(D31,G31)} -> #VALUE! | O31: {=_FV(N31,"Similarity",TRUE)} -> 0 | AF31: yes
A32: <Sponsor Name> | C32: KeyValue | D32: Stendarr, Inc. | E32: Protocol Example (28Sep2023) 1 | F32: Insert the official sponsor name in line with protocol header formatting. | G32: Stendarr, Inc. | I32: {=_xldudf_BOARDFLARE_FMATCH(G32,D32)} -> #VALUE! | J32: =IF(M32>O32, M32,O32) -> 0.99 | L32: {=_xldudf_BOARDFLARE_FMATCH(G32,D32)} -> #VALUE! | M32: {=_FV(L32,"Similarity",TRUE)} -> 0.99 | N32: {=_xldudf_BOARDFLARE_FMATCH(D32,G32)} -> #VALUE! | O32: {=_FV(N32,"Similarity",TRUE)} -> 0.85 | AF32: yes
A33: <Protocol Number> | C33: KeyValue | D33: SKY-2000-101 | E33: Protocol Example (28Sep2023) 1 | F33: Insert the official protocol number in the format used in the source document. | G33: SKY-2000-101 | I33: {=_xldudf_BOARDFLARE_FMATCH(G33,D33)} -> #VALUE! | J33: =IF(M33>O33, M33,O33) -> 1 | L33: {=_xldudf_BOARDFLARE_FMATCH(G33,D33)} -> #VALUE! | M33: {=_FV(L33,"Similarity",TRUE)} -> 1 | N33: {=_xldudf_BOARDFLARE_FMATCH(D33,G33)} -> #VALUE! | O33: {=_FV(N33,"Similarity",TRUE)} -> 0.92 | AF33: yes
A34: <Principal Investigator Name> | C34: KeyValue | D34: Karliah N. Gale, MD​profe​ | E34: Protocol Example (28Sep2023) 1 | I34: {=_xldudf_BOARDFLARE_FMATCH(G34,D34)} -> #VALUE! | J34: =IF(M34>O34, M34,O34) -> 0 | L34: {=_xldudf_BOARDFLARE_FMATCH(G34,D34)} -> #VALUE! | M34: {=_FV(L34,"Similarity",TRUE)} -> 0 | N34: {=_xldudf_BOARDFLARE_FMATCH(D34,G34)} -> #VALUE! | O34: {=_FV(N34,"Similarity",TRUE)} -> 0 | AF34: yes
A35: <IRB Company Name> | C35: KeyValue | D35: Stendarr, Inc. | E35: Protocol Example (28Sep2023) 1 | F35: Insert the IRB company name in a concise, inline format. | G35: Stendarr, Inc. | I35: {=_xldudf_BOARDFLARE_FMATCH(G35,D35)} -> #VALUE! | J35: =IF(M35>O35, M35,O35) -> 0.99 | L35: {=_xldudf_BOARDFLARE_FMATCH(G35,D35)} -> #VALUE! | M35: {=_FV(L35,"Similarity",TRUE)} -> 0.99 | N35: {=_xldudf_BOARDFLARE_FMATCH(D35,G35)} -> #VALUE! | O35: {=_FV(N35,"Similarity",TRUE)} -> 0.85 | AF35: yes | AH35: =AF35=AG35 -> FALSE | AI35: =O35=R35 -> FALSE
A36: <disease> | C36: KeyValue | D36: Boneitis | E36: Protocol Example (28Sep2023) 1 | F36: Insert the disease name treated by the investigational drug, formatted for inline continuity. | G36: boneitis | I36: {=_xldudf_BOARDFLARE_FMATCH(G36,D36)} -> #VALUE! | J36: =IF(M36>O36, M36,O36) -> 1 | L36: {=_xldudf_BOARDFLARE_FMATCH(G36,D36)} -> #VALUE! | M36: {=_FV(L36,"Similarity",TRUE)} -> 1 | N36: {=_xldudf_BOARDFLARE_FMATCH(D36,G36)} -> #VALUE! | O36: {=_FV(N36,"Similarity",TRUE)} -> 1 | AF36: yes | AH36: =AF36=AG36 -> FALSE | AI36: =O36=R36 -> FALSE
A37: <brief lay description of disease> | C37: Paragraph | D37: ABC-123 is intended for use in patients with boneitis, a disease that causes bones to change shape or disappear. | E37: Protocol Example (28Sep2023) 1 | F37: Provide a brief, clear lay description of boneitis to fit seamlessly within the sentence. | G37: a disease that causes bones to change shape or disappear | I37: {=_xldudf_BOARDFLARE_FMATCH(G37,D37)} -> #VALUE! | J37: =IF(M37>O37, M37,O37) -> 0.79 | L37: {=_xldudf_BOARDFLARE_FMATCH(G37,D37)} -> #VALUE! | M37: {=_FV(L37,"Similarity",TRUE)} -> 0.79 | N37: {=_xldudf_BOARDFLARE_FMATCH(D37,G37)} -> #VALUE! | O37: {=_FV(N37,"Similarity",TRUE)} -> 0 | AF37: yes | AG37: yes | AH37: =AF37=AG37 -> TRUE | AI37: =Table113[[#This Row],[Expected Value]]=Table113[[#This Row],[AI Replaced Text]] -> FALSE
A38: <Brief lay description of study design including purpose/objectives> | C38: Table | D38: Objectives/Endpoints: The following objectives and endpoints will be evaluated in healthy participants during the SAD component of the study and in participants with boneitis in the repeat-dose component of the study. Objectives Endpoints Primary To assess the safety and tolerability after 4 weeks of exposure following single ascending doses of ABC-123 Number of participants with serious and other nonserious AEs Secondary To assess the safety and tolerability following repeated doses over 4 weeks of ABC-123 Number of participants with serious and other nonserious AEs To characterize PK of ABC-123 following single ascending doses Cmax and AUClast To characterize the PK of ABC-123 following repeated doses Cmax and AUClast Exploratory To explore additional PK characteristics of ABC-123 following single ascending doses Tmax, Clast, Tlast, AUCinf, CL, V, and t1/2 To explore additional PK characteristics of ABC-123 following repeated doses Tmax, Clast, Tlast, AUCinf, CL, V, and t1/2 To explore effects of ABC-123 on clinical laboratory assessments, 12-lead ECG, and vital signs following single ascending doses Incidence of clinically significant changes in laboratory parameters, 12-lead ECG parameters, and vital signs measurements To explore effects of ABC-123 on clinical laboratory assessments, 12-lead ECG, and vital signs following repeated doses Incidence of clinically significant changes in laboratory parameters, 12-lead ECG parameters, and vital signs measurements To explore the impact of ADA on the PK profile of ABC-123 following single ascending doses Impact of ADA on AUC or impact on overall exposure of ABC-123 To explore the impact of ADA on the PK profile of ABC-123 following repeated doses Impact of ADA on AUC or impact on overall exposure of ABC-123 To explore the effects on eating behavior in participants following single ascending doses of ABC-123 Hunger, satiety, and appetite VAS scores Abbreviations: ADA = antidrug antibodies; AE = adverse event. | E38: Protocol Example (28Sep2023) 1 | F38: Write a brief, layperson-oriented paragraph describing the study design, including its main goals and what will be assessed. | G38: This study is being conducted to evaluate the safety and effects of a new investigational drug, ABC-123. It includes both healthy volunteers and participants with boneitis. The study will help researchers learn how the drug works in the body, how safe it is, and how it affects certain health measurements. The results will provide important information for future studies and may help identify the best dose and people who could benefit from ABC-123. | I38: {=_xldudf_BOARDFLARE_FMATCH(G38,D38)} -> #VALUE! | J38: =IF(M38>O38, M38,O38) -> 0 | L38: {=_xldudf_BOARDFLARE_FMATCH(G38,D38)} -> #VALUE! | M38: {=_FV(L38,"Similarity",TRUE)} -> 0 | N38: {=_xldudf_BOARDFLARE_FMATCH(D38,G38)} -> #VALUE! | O38: {=_FV(N38,"Similarity",TRUE)} -> 0 | R38: 16 | S38: 2 | T38: Abbreviations: ADA = antidrug antibodies; AE = adverse event. | U38: NA | V38: NA | W38: NA | X38: no | AF38: yes
A39: <lay terminology for SAD portion of study> | C39: Paragraph | D39: All screening tests establishing eligibility will be performed following informed consent and within 35 days prior to study intervention administration. Participants will reside at the CRU from Day 2 to Day 5 and Day 28 to Day 33 and will receive SC 150 mg ABC-123 (6 participants) or placebo (2 participants) every other week for 3 doses. The actual dose and regimen selected for this part of the study will be based on the safety, tolerability, and PK of ABC-123 as determined during the ongoing SAD component of the study. To account for anticipated accumulation, the dose selected for the repeat-dose cohort will not exceed 50% of a dose that has previously been shown to be safe and well tolerated in the single-dose cohort. Sentinel dosing is not required during this part of the study. Participants must not have been enrolled in the SAD component. | E39: Protocol Example (28Sep2023) 1 | F39: Provide a concise lay term for the SAD portion of the study, matching the flow for an inline reference. | G39: the single-dose part of the study | I39: {=_xldudf_BOARDFLARE_FMATCH(G39,D39)} -> #VALUE! | J39: =IF(M39>O39, M39,O39) -> 0 | L39: {=_xldudf_BOARDFLARE_FMATCH(G39,D39)} -> #VALUE! | M39: {=_FV(L39,"Similarity",TRUE)} -> 0 | N39: {=_xldudf_BOARDFLARE_FMATCH(D39,G39)} -> #VALUE! | O39: {=_FV(N39,"Similarity",TRUE)} -> 0 | AF39: yes | AG39: yes | AH39: =AF39=AG39 -> TRUE | AI39: =Table113[[#This Row],[Expected Value]]=Table113[[#This Row],[AI Replaced Text]] -> FALSE
A40: <X cohorts (or groups) of X participants> | C40: KeyValue | D40: 3 cohorts of 56 participants | E40: Protocol Example (28Sep2023) 1 | F40: Insert the number of cohorts and participants per cohort for the SAD phase in the format 'X cohorts of X participants'. | G40: 6 cohorts of 8 participants | I40: {=_xldudf_BOARDFLARE_FMATCH(G40,D40)} -> #VALUE! | J40: =IF(M40>O40, M40,O40) -> 0.63 | L40: {=_xldudf_BOARDFLARE_FMATCH(G40,D40)} -> #VALUE! | M40: {=_FV(L40,"Similarity",TRUE)} -> 0.63 | N40: {=_xldudf_BOARDFLARE_FMATCH(D40,G40)} -> #VALUE! | O40: {=_FV(N40,"Similarity",TRUE)} -> 0.63 | AF40: yes | AH40: =AF40=AG40 -> FALSE | AI40: =O40=R40 -> FALSE
...

Sheet Inline
A2: Placeholder | C2: Placeholder Type | D2: Expected Value | E2: Source Document | F2: Writing instruction | G2: AI Replaced Text | H2: Ai detected Source | I2: Matching Accuracy | J2: Similarity Score | K2: Source Match
A3: {=_xlfn._xlws.FILTER(QA!A3:K500, QA!C3:C500="Inline")} -> #VALUE!

Sheet Paragraph
A2: Placeholder | C2: Placeholder Type | D2: Expected Value | E2: Source Document | F2: Writing instruction | G2: AI Replaced Text | H2: Ai detected Source | I2: Matching Accuracy | J2: Similarity Score | K2: Source Match
A3: {=_xlfn._xlws.FILTER(QA!A3:K500, QA!C3:C500="Paragraph")} -> <Full protocol title> | B3: 0 | C3: Paragraph | D3: A First-In-Human, Phase 1, Randomized, Double-Blind, Placebo-Controlled Study to Evaluate the Safety, Tolerability, and Pharmacokinetics of ABC-123 as a Single Dose in Healthy Participants and as Multiple Doses in Participants with Grade 2 Boneitis | E3: Protocol Example (28Sep2023) 1 | F3: Insert the full protocol title verbatim, maintaining inline continuity. | G3: A First-In-Human, Phase 1, Randomized, Double-Blind, Placebo-Controlled Study to Evaluate the Safety, Tolerability, and Pharmacokinetics of ABC-123 as a Single Dose in Healthy Participants and as Multiple Doses in Participants with Grade 2 Boneitis | H3: 0 | I3: #VALUE! | J3: 0.61 | K3: 0
A4: <brief lay description of disease> | B4: 0 | C4: Paragraph | D4: ABC-123 is intended for use in patients with boneitis, a disease that causes bones to change shape or disappear. | E4: Protocol Example (28Sep2023) 1 | F4: Provide a brief, clear lay description of boneitis to fit seamlessly within the sentence. | G4: a disease that causes bones to change shape or disappear | H4: 0 | I4: #VALUE! | J4: 0.79 | K4: 0
A5: <type of study (eg, first-in-human, Phase 1, Phase 2)> | B5: 0 | C5: Paragraph | D5: The SAD portion of this study is a standard design for first-in-human testing with a monoclonal antibody. In addition, a 4-week repeated dose cohort will allow confirmation of the safety, tolerability, and repeat-dose PK and immunogenicity in the target population prior to proceeding to subsequent repeat-dose studies in a patient population. | E5: Protocol Example (28Sep2023) 1 | F5: Provide the study type in concise, inline format (e.g., first-in-human, Phase 1) to maintain paragraph continuity. | G5: first-in-human, Phase 1 | H5: 0 | I5: #VALUE! | J5: 0 | K5: 0
A6: <lay terminology for SAD portion of study> | B6: 0 | C6: Paragraph | D6: All screening tests establishing eligibility will be performed following informed consent and within 35 days prior to study intervention administration. Participants will reside at the CRU from Day 2 to Day 5 and Day 28 to Day 33 and will receive SC 150 mg ABC-123 (6 participants) or placebo (2 participants) every other week for 3 doses. The actual dose and regimen selected for this part of the study will be based on the safety, tolerability, and PK of ABC-123 as determined during the ongoing SAD component of the study. To account for anticipated accumulation, the dose selected for the repeat-dose cohort will not exceed 50% of a dose that has previously been shown to be safe and well tolerated in the single-dose cohort. Sentinel dosing is not required during this part of the study. Participants must not have been enrolled in the SAD component. | E6: Protocol Example (28Sep2023) 1 | F6: Provide a concise lay term for the SAD portion of the study, matching the flow for an inline reference. | G6: the single-dose part of the study | H6: 0 | I6: #VALUE! | J6: 0 | K6: 0
A7: <lay terminology for repeat-dose portion of study> | B7: 0 | C7: Paragraph | D7: The SAD portion of this study is a standard design for first-in-human testing with a monoclonal antibody. In addition, a 4-week repeated dose cohort will allow confirmation of the safety, tolerability, and repeat-dose PK and immunogenicity in the target population prior to proceeding to subsequent repeat-dose studies in a patient population. | E7: Protocol Example (28Sep2023) 1 | F7: 0 | G7: 0 | H7: 0 | I7: #VALUE! | J7: 0 | K7: 0
A8: <lay terminology for dosing regimen/duration> | B8: 0 | C8: Paragraph | D8: Following Check-out from the CRU, all participants will return for Follow-up study visits up to 6 weeks post dosing in the first 3 cohorts and 10 weeks post dosing in the remaining cohorts as shown in the Schedule of Assessments | E8: Protocol Example (28Sep2023) 1 | F8: Rewrite the dosing regimen and duration in clear lay terms suitable for an informed consent document. | G8: every other week for 3 doses over up to 6 weeks | H8: 0 | I8: #VALUE! | J8: 0 | K8: 0
A9: <brief lay description of disease> | B9: 0 | C9: Paragraph | D9: ABC-123 is intended for use in patients with boneitis, a disease that causes bones to change shape or disappear. | E9: Protocol Example (28Sep2023) 1 | F9: Provide a brief, clear lay description of boneitis to fit seamlessly within the sentence. | G9: a disease that causes bones to change shape or disappear | H9: 0 | I9: #VALUE! | J9: 0.79 | K9: 0
A10: <lay terminology for SAD portion of study> | B10: 0 | C10: Paragraph | D10: All screening tests establishing eligibility will be performed following informed consent and within 35 days prior to study intervention administration. Participants will reside at the CRU from Day 2 to Day 5 and Day 28 to Day 33 and will receive SC 150 mg ABC-123 (6 participants) or placebo (2 participants) every other week for 3 doses. The actual dose and regimen selected for this part of the study will be based on the safety, tolerability, and PK of ABC-123 as determined during the ongoing SAD component of the study. To account for anticipated accumulation, the dose selected for the repeat-dose cohort will not exceed 50% of a dose that has previously been shown to be safe and well tolerated in the single-dose cohort. Sentinel dosing is not required during this part of the study. Participants must not have been enrolled in the SAD component. | E10: Protocol Example (28Sep2023) 1 | F10: Provide a concise lay term for the SAD portion of the study, matching the flow for an inline reference. | G10: the single-dose part of the study | H10: 0 | I10: #VALUE! | J10: 0 | K10: 0
A11: <lay terminology summarizing design and enrollment plan for Cohort 1 with sentinel participants> | B11: 0 | C11: Paragraph | D11: All screening tests establishing eligibility will be performed following informed consent and within 35 days prior to study intervention administration. Each participant will be enrolled in 1 dose cohort only; participants will reside at the Clinical Research Unit (CRU) from Day 2 to Day 8. In each cohort, participants will receive a subcutaneous (SC) dose of ABC-123 (6 participants) or placebo (2 participants) on Day 1. To assure safety and tolerability of the starting dose, 2 sentinel participants will be dosed first in Cohort 1 (1 active drug and 1 placebo to maintain study blinding); the remaining Cohort 1 participants may be dosed at least 48 hours later, after initial safety of the sentinel participants is confirmed by the Phase 1 Unit Principal Investigator in consultation with the Sponsor. | E11: Protocol Example (28Sep2023) 1 | F11: Summarize the design and enrollment plan for Cohort 1, explaining sentinel dosing in lay language. | G11: The first group (Cohort 1) will include 8 participants, with 2 participants (called sentinels) receiving the study drug or placebo first to monitor safety. If no safety concerns are found after 48 hours, the remaining participants in the group will receive their doses. | H11: 0 | I11: #VALUE! | J11: 0 | K11: 0
A12: <lay terminology for repeat-dose portion of study> | B12: 0 | C12: Paragraph | D12: The SAD portion of this study is a standard design for first-in-human testing with a monoclonal antibody. In addition, a 4-week repeated dose cohort will allow confirmation of the safety, tolerability, and repeat-dose PK and immunogenicity in the target population prior to proceeding to subsequent repeat-dose studies in a patient population. | E12: Protocol Example (28Sep2023) 1 | F12: 0 | G12: 0 | H12: 0 | I12: #VALUE! | J12: 0 | K12: 0
A13: <lay terminology for dosing regimen/duration> | B13: 0 | C13: Paragraph | D13: Following Check-out from the CRU, all participants will return for Follow-up study visits up to 6 weeks post dosing in the first 3 cohorts and 10 weeks post dosing in the remaining cohorts as shown in the Schedule of Assessments | E13: Protocol Example (28Sep2023) 1 | F13: Rewrite the dosing regimen and duration in clear lay terms suitable for an informed consent document. | G13: every other week for 3 doses over up to 6 weeks | H13: 0 | I13: #VALUE! | J13: 0 | K13: 0
A14: <lay terminology for choice of dose for repeat-dose portion of study based on data from SAD portion of study> | B14: 0 | C14: Paragraph | D14: The repeat-dose portion of the study is a double-blind, randomized, placebo-controlled design in 1 cohort of participants with boneitis. All screening tests establishing eligibility will be performed following informed consent and within 35 days prior to study intervention administration. Participants will reside at the CRU from Day 2 to Day 5 and Day 28 to Day 33 and will receive SC 150 mg ABC-123 (6 participants) or placebo (2 participants) every other week for 3 doses. The actual dose and regimen selected for this part of the study will be based on the safety, tolerability, and PK of ABC-123 as determined during the ongoing SAD component of the study. To account for anticipated accumulation, the dose selected for the repeat-dose cohort will not exceed 50% of a dose that has previously been shown to be safe and well tolerated in the single-dose cohort. Sentinel dosing is not required during this part of the study. Participants must not have been enrolled in the SAD component. | E14: Protocol Example (28Sep2023) 1 | F14: Provide a lay summary explaining that the repeat-dose regimen is chosen based on safety, tolerability, and PK data from the SAD portion. | G14: was selected based on safety, tolerability, and PK data from the single ascending dose (SAD) portion of the study | H14: 0 | I14: #VALUE! | J14: 0 | K14: 0
A15: <lay terminology for SAD portion of study> | B15: 0 | C15: Paragraph | D15: All screening tests establishing eligibility will be performed following informed consent and within 35 days prior to study intervention administration. Participants will reside at the CRU from Day 2 to Day 5 and Day 28 to Day 33 and will receive SC 150 mg ABC-123 (6 participants) or placebo (2 participants) every other week for 3 doses. The actual dose and regimen selected for this part of the study will be based on the safety, tolerability, and PK of ABC-123 as determined during the ongoing SAD component of the study. To account for anticipated accumulation, the dose selected for the repeat-dose cohort will not exceed 50% of a dose that has previously been shown to be safe and well tolerated in the single-dose cohort. Sentinel dosing is not required during this part of the study. Participants must not have been enrolled in the SAD component. | E15: Protocol Example (28Sep2023) 1 | F15: Provide a concise lay term for the SAD portion of the study, matching the flow for an inline reference. | G15: the single-dose part of the study | H15: 0 | I15: #VALUE! | J15: 0 | K15: 0
A16: <lay terminology for SAD portion of study> | B16: 0 | C16: Paragraph | D16: All screening tests establishing eligibility will be performed following informed consent and within 35 days prior to study intervention administration. Participants will reside at the CRU from Day 2 to Day 5 and Day 28 to Day 33 and will receive SC 150 mg ABC-123 (6 participants) or placebo (2 participants) every other week for 3 doses. The actual dose and regimen selected for this part of the study will be based on the safety, tolerability, and PK of ABC-123 as determined during the ongoing SAD component of the study. To account for anticipated accumulation, the dose selected for the repeat-dose cohort will not exceed 50% of a dose that has previously been shown to be safe and well tolerated in the single-dose cohort. Sentinel dosing is not required during this part of the study. Participants must not have been enrolled in the SAD component. | E16: Protocol Example (28Sep2023) 1 | F16: Provide a concise lay term for the SAD portion of the study, matching the flow for an inline reference. | G16: the single-dose part of the study | H16: 0 | I16: #VALUE! | J16: 0 | K16: 0
A17: <lay summary of duration on study including details/time for screening, screeningthe clinic, follow-up periods> | B17: 0 | C17: Paragraph | D17: The SAD portion of the study is double-blind, randomized, placebo-controlled, single ascending dose design in up to 6 cohorts of healthy participants. All screening tests establishing eligibility will be performed following informed consent and within 35 days prior to study intervention administration. Each participant will be enrolled in 1 dose cohort only; participants will reside at the Clinical Research Unit (CRU) from Day 2 to Day 8. In each cohort, participants will receive a subcutaneous (SC) dose of ABC-123 (6 participants) or placebo (2 participants) on Day 1. To assure safety and tolerability of the starting dose, 2 sentinel participants will be dosed first in Cohort 1 (1 active drug and 1 placebo to maintain study blinding); the remaining Cohort 1 participants may be dosed at least 48 hours later, after initial safety of the sentinel participants is confirmed by the Phase 1 Unit Principal Investigator in consultation with the Sponsor. Following Check-out from the CRU, all participants will return for Follow-up study visits up to 6 weeks post dosing in the first 3 cohorts and 10 weeks post dosing in the remaining cohorts as shown in the Schedule of Assessments (SoA; Section 1.3). Blood samples for PK and blood and urine samples for biomarkers are planned to be collected prior to dosing and at specific post-dose time points per the SoA. Timing of the blood sample collection for PK may change based on availability of new data from completed study cohorts. Safety measurements, including 12-lead ECG; vital sign monitoring including blood pressure, pulse rate, respiratory rate, and body temperature; clinical laboratory tests (chemistry, hematology, lipid profile, cytokine assessments); physical examinations; mental health assessment; and other metrics, will be obtained at specific time points per the SoA. Adverse events and concomitant medication use will be monitored throughout the study. The study Investigator and Medical Monitor will monitor the safety of participants in a blinded fashion throughout the study on an ongoing basis to determine whether to continue dosing, whether to escalate dose, and whether to initiate dosing in various cohorts. The allocation of participants to various cohorts may be adjusted based on the ongoing data review. Dose escalation to the next cohort (ie, dose level) will not take place until the Sponsor, in conjunction with the Principal Investigator, has determined that adequate safety, tolerability, and PK (if available) from the previous cohort have been demonstrated to permit proceeding to the next cohort. | E17: Protocol Example (28Sep2023) 1 | F17: Write a lay summary of the study schedule for these cohorts, including screening period, dosing regimen, and total study duration. | G17: up to 5 weeks for screening, followed by repeat dosing every other week for 3 doses, and up to 15 weeks total from Screening to Follow-up | H17: 0 | I17: #VALUE! | J17: 0 | K17: 0
A18: <lay summary of duration on study including details/time for screening, time in the clinic, follow-up periods> | B18: 0 | C18: Paragraph | D18: The SAD portion of the study is double-blind, randomized, placebo-controlled, single ascending dose design in up to 6 cohorts of healthy participants. All screening tests establishing eligibility will be performed following informed consent and within 35 days prior to study intervention administration. Each participant will be enrolled in 1 dose cohort only; participants will reside at the Clinical Research Unit (CRU) from Day 2 to Day 8. In each cohort, participants will receive a subcutaneous (SC) dose of ABC-123 (6 participants) or placebo (2 participants) on Day 1. To assure safety and tolerability of the starting dose, 2 sentinel participants will be dosed first in Cohort 1 (1 active drug and 1 placebo to maintain study blinding); the remaining Cohort 1 participants may be dosed at least 48 hours later, after initial safety of the sentinel participants is confirmed by the Phase 1 Unit Principal Investigator in consultation with the Sponsor. Following Check-out from the CRU, all participants will return for Follow-up study visits up to 6 weeks post dosing in the first 3 cohorts and 10 weeks post dosing in the remaining cohorts as shown in the Schedule of Assessments (SoA; Section 1.3). Blood samples for PK and blood and urine samples for biomarkers are planned to be collected prior to dosing and at specific post-dose time points per the SoA. Timing of the blood sample collection for PK may change based on availability of new data from completed study cohorts. Safety measurements, including 12-lead ECG; vital sign monitoring including blood pressure, pulse rate, respiratory rate, and body temperature; clinical laboratory tests (chemistry, hematology, lipid profile, cytokine assessments); physical examinations; mental health assessment; and other metrics, will be obtained at specific time points per the SoA. Adverse events and concomitant medication use will be monitored throughout the study. The study Investigator and Medical Monitor will monitor the safety of participants in a blinded fashion throughout the study on an ongoing basis to determine whether to continue dosing, whether to escalate dose, and whether to initiate dosing in various cohorts. The allocation of participants to various cohorts may be adjusted based on the ongoing data review. Dose escalation to the next cohort (ie, dose level) will not take place until the Sponsor, in conjunction with the Principal Investigator, has determined that adequate safety, tolerability, and PK (if available) from the previous cohort have been demonstrated to permit proceeding to the next cohort. | E18: Protocol Example (28Sep2023) 1 | F18: Write a lay summary of the study schedule for these cohorts, including screening period, dosing regimen, and total study duration. | G18: up to 5 weeks for screening, followed by repeat dosing every other week for 3 doses, and up to 15 weeks total from Screening to Follow-up | H18: 0 | I18: #VALUE! | J18: 0 | K18: 0
A19: <lay terminology for repeat-dose portion of study> | B19: 0 | C19: Paragraph | D19: The SAD portion of this study is a standard design for first-in-human testing with a monoclonal antibody. In addition, a 4-week repeated dose cohort will allow confirmation of the safety, tolerability, and repeat-dose PK and immunogenicity in the target population prior to proceeding to subsequent repeat-dose studies in a patient population. | E19: Protocol Example (28Sep2023) 1 | F19: 0 | G19: 0 | H19: 0 | I19: #VALUE! | J19: 0 | K19: 0
A20: <lay terminology for repeat-dose portion of study> | B20: 0 | C20: Paragraph | D20: The SAD portion of this study is a standard design for first-in-human testing with a monoclonal antibody. In addition, a 4-week repeated dose cohort will allow confirmation of the safety, tolerability, and repeat-dose PK and immunogenicity in the target population prior to proceeding to subsequent repeat-dose studies in a patient population. | E20: Protocol Example (28Sep2023) 1 | F20: 0 | G20: 0 | H20: 0 | I20: #VALUE! | J20: 0 | K20: 0
A21: <lay summary of duration on study including details/ time for screening, time in the clinic, follow-up periods> | B21: 0 | C21: Paragraph | D21: The SAD portion of the study is double-blind, randomized, placebo-controlled, single ascending dose design in up to 6 cohorts of healthy participants. All screening tests establishing eligibility will be performed following informed consent and within 35 days prior to study intervention administration. Each participant will be enrolled in 1 dose cohort only; participants will reside at the Clinical Research Unit (CRU) from Day 2 to Day 8. In each cohort, participants will receive a subcutaneous (SC) dose of ABC-123 (6 participants) or placebo (2 participants) on Day 1. To assure safety and tolerability of the starting dose, 2 sentinel participants will be dosed first in Cohort 1 (1 active drug and 1 placebo to maintain study blinding); the remaining Cohort 1 participants may be dosed at least 48 hours later, after initial safety of the sentinel participants is confirmed by the Phase 1 Unit Principal Investigator in consultation with the Sponsor. Following Check-out from the CRU, all participants will return for Follow-up study visits up to 6 weeks post dosing in the first 3 cohorts and 10 weeks post dosing in the remaining cohorts as shown in the Schedule of Assessments (SoA; Section 1.3). Blood samples for PK and blood and urine samples for biomarkers are planned to be collected prior to dosing and at specific post-dose time points per the SoA. Timing of the blood sample collection for PK may change based on availability of new data from completed study cohorts. Safety measurements, including 12-lead ECG; vital sign monitoring including blood pressure, pulse rate, respiratory rate, and body temperature; clinical laboratory tests (chemistry, hematology, lipid profile, cytokine assessments); physical examinations; mental health assessment; and other metrics, will be obtained at specific time points per the SoA. Adverse events and concomitant medication use will be monitored throughout the study. The study Investigator and Medical Monitor will monitor the safety of participants in a blinded fashion throughout the study on an ongoing basis to determine whether to continue dosing, whether to escalate dose, and whether to initiate dosing in various cohorts. The allocation of participants to various cohorts may be adjusted based on the ongoing data review. Dose escalation to the next cohort (ie, dose level) will not take place until the Sponsor, in conjunction with the Principal Investigator, has determined that adequate safety, tolerability, and PK (if available) from the previous cohort have been demonstrated to permit proceeding to the next cohort. | E21: Protocol Example (28Sep2023) 1 | F21: Summarize the total study duration, specifying the time for screening, dosing, and follow-up in a concise lay format. | G21: up to 15 weeks, including up to 5 weeks for Screening, dosing every other week for 3 doses, and a Follow-up period | H21: 0 | I21: #VALUE! | J21: 0 | K21: 0
A22: <lay terminology for SAD portion of study> | B22: 0 | C22: Paragraph | D22: All screening tests establishing eligibility will be performed following informed consent and within 35 days prior to study intervention administration. Participants will reside at the CRU from Day 2 to Day 5 and Day 28 to Day 33 and will receive SC 150 mg ABC-123 (6 participants) or placebo (2 participants) every other week for 3 doses. The actual dose and regimen selected for this part of the study will be based on the safety, tolerability, and PK of ABC-123 as determined during the ongoing SAD component of the study. To account for anticipated accumulation, the dose selected for the repeat-dose cohort will not exceed 50% of a dose that has previously been shown to be safe and well tolerated in the single-dose cohort. Sentinel dosing is not required during this part of the study. Participants must not have been enrolled in the SAD component. | E22: Protocol Example (28Sep2023) 1 | F22: Provide a concise lay term for the SAD portion of the study, matching the flow for an inline reference. | G22: the single-dose part of the study | H22: 0 | I22: #VALUE! | J22: 0 | K22: 0
A23: <Bullet list of lay terminology of all assessments required during Check-in/Day1> | B23: 0 | C23: Paragraph | D23: Participants should avoid strenuous activity within 24 hours prior to Check-in and subsequent return visits. Participants may engage in light recreational activities during the study (eg, watching television, reading). Study participants in the repeat-dose cohort may continue their usual exercise/activity regimen but should not increase intensity during the study. | E23: Protocol Example (28Sep2023) 1 | F23: List all assessments required during Check-in/Day 1 using lay terminology as a concise bullet or inline list. | G23: Blood pressure, pulse rate, respiratory rate, body temperature, blood tests, heart monitoring (ECG), physical examination, and mental health assessment. | H23: 0 | I23: #VALUE! | J23: 0 | K23: 0
